<sdf version='1.5'>
  <world name='default'>
    <gui fullscreen='0'>
      <camera name='user_camera'>
        <pose frame=''>268.733 -151.872 10.334 0 0.937796 1.236</pose>
        <view_controller>orbit</view_controller>
        <projection_type>perspective</projection_type>
      </camera>
    </gui>
    <light name='sun' type='directional'>
      <cast_shadows>1</cast_shadows>
      <pose frame=''>0 0 10 0 -0 0</pose>
      <diffuse>0.8 0.8 0.8 1</diffuse>
      <specular>0.1 0.1 0.1 1</specular>
      <attenuation>
        <range>1000</range>
        <constant>0.9</constant>
        <linear>0.01</linear>
        <quadratic>0.001</quadratic>
      </attenuation>
      <direction>-0.5 0.5 -1</direction>
    </light>
    <model name='curved_road'>
      <static>1</static>
      <link name='link'>
        <collision name='collision'>
          <geometry>
            <mesh>
              <uri>models/newcurve/curve8k.dae</uri>
              <scale>1 1 1</scale>
            </mesh>
          </geometry>
          <max_contacts>10</max_contacts>
          <surface>
            <contact>
              <ode/>
            </contact>
            <bounce/>
            <friction>
              <torsional>
                <ode/>
              </torsional>
              <ode/>
            </friction>
          </surface>
        </collision>
        <visual name='visual'>
          <cast_shadows>0</cast_shadows>
          <geometry>
            <mesh>
              <uri>models/newcurve/curve8k.dae</uri>
              <scale>1 1 1</scale>
            </mesh>
          </geometry>
          <material>
            <script>
              <uri>models/newcurve/materials/scripts</uri>
              <uri>models/newcurve/materials/textures</uri>
              <name>newcurve</name>
            </script>
          </material>
        </visual>
        <self_collide>0</self_collide>
        <kinematic>0</kinematic>
        <gravity>1</gravity>
      </link>
      <pose frame=''>91.25 -2.5 -0.05 0 0 -1.575</pose>
    </model>
    <model name='car'>
      <link name='chassis'>
        <pose frame=''>0 0 0.35 0 -0 0</pose>
        <inertial>
          <mass>100</mass>
          <inertia>
            <ixx>1</ixx>
            <ixy>0</ixy>
            <ixz>0</ixz>
            <iyy>1</iyy>
            <iyz>0</iyz>
            <izz>1</izz>
          </inertia>
        </inertial>
        <collision name='chassis_collision'>
          <geometry>
            <box>
              <size>2 0.8 0.2</size>
            </box>
          </geometry>
          <max_contacts>10</max_contacts>
          <surface>
            <contact>
              <ode/>
            </contact>
            <bounce/>
            <friction>
              <torsional>
                <ode/>
              </torsional>
              <ode/>
            </friction>
          </surface>
        </collision>
        <visual name='chassis_visual'>
          <pose frame=''>0.1 0 -0.2 0 -0 1.57079</pose>
          <geometry>
            <mesh>
              <uri>models/sdcCar/cooper-test.dae</uri>
              <scale>1 1 1</scale>
            </mesh>
          </geometry>
        </visual>
        <self_collide>0</self_collide>
        <kinematic>0</kinematic>
        <gravity>1</gravity>
      </link>
      <link name='front_left_wheel'>
        <inertial>
          <mass>10</mass>
          <inertia>
            <ixx>1</ixx>
            <ixy>0</ixy>
            <ixz>0</ixz>
            <iyy>1</iyy>
            <iyz>0</iyz>
            <izz>1</izz>
          </inertia>
        </inertial>
        <pose frame=''>0.8 0.5 0.3 0 1.57079 1.57079</pose>
        <collision name='front_left_wheel_collision'>
          <geometry>
            <cylinder>
              <radius>0.21</radius>
              <length>0.1</length>
            </cylinder>
          </geometry>
          <max_contacts>10</max_contacts>
          <surface>
            <contact>
              <ode/>
            </contact>
            <bounce/>
            <friction>
              <torsional>
                <ode/>
              </torsional>
              <ode/>
            </friction>
          </surface>
        </collision>
        <visual name='front_left_wheel_visual'>
          <geometry>
            <mesh>
              <uri>models/sdcCar/wheel.stl</uri>
              <scale>1 1 1</scale>
            </mesh>
          </geometry>
          <material>
            <script>
              <uri>file://media/materials/scripts/gazebo.material</uri>
              <name>Gazebo/Black</name>
            </script>
          </material>
        </visual>
        <self_collide>0</self_collide>
        <kinematic>0</kinematic>
        <gravity>1</gravity>
      </link>
      <link name='front_right_wheel'>
        <pose frame=''>0.8 -0.5 0.3 0 1.57079 -1.57079</pose>
        <inertial>
          <mass>10</mass>
          <inertia>
            <ixx>1</ixx>
            <ixy>0</ixy>
            <ixz>0</ixz>
            <iyy>1</iyy>
            <iyz>0</iyz>
            <izz>1</izz>
          </inertia>
        </inertial>
        <collision name='front_right_wheel_collision'>
          <geometry>
            <cylinder>
              <radius>0.21</radius>
              <length>0.1</length>
            </cylinder>
          </geometry>
          <max_contacts>10</max_contacts>
          <surface>
            <contact>
              <ode/>
            </contact>
            <bounce/>
            <friction>
              <torsional>
                <ode/>
              </torsional>
              <ode/>
            </friction>
          </surface>
        </collision>
        <visual name='front_right_wheel_visual'>
          <geometry>
            <mesh>
              <uri>models/sdcCar/wheel.stl</uri>
              <scale>1 1 1</scale>
            </mesh>
          </geometry>
          <material>
            <script>
              <uri>file://media/materials/scripts/gazebo.material</uri>
              <name>Gazebo/Black</name>
            </script>
          </material>
        </visual>
        <self_collide>0</self_collide>
        <kinematic>0</kinematic>
        <gravity>1</gravity>
      </link>
      <link name='back_right_wheel'>
        <pose frame=''>-0.87 -0.5 0.3 0 1.57079 -1.57079</pose>
        <inertial>
          <mass>10</mass>
          <inertia>
            <ixx>1</ixx>
            <ixy>0</ixy>
            <ixz>0</ixz>
            <iyy>1</iyy>
            <iyz>0</iyz>
            <izz>1</izz>
          </inertia>
        </inertial>
        <collision name='back_right_wheel_collision'>
          <geometry>
            <cylinder>
              <radius>0.21</radius>
              <length>0.1</length>
            </cylinder>
          </geometry>
          <max_contacts>10</max_contacts>
          <surface>
            <contact>
              <ode/>
            </contact>
            <bounce/>
            <friction>
              <torsional>
                <ode/>
              </torsional>
              <ode/>
            </friction>
          </surface>
        </collision>
        <visual name='back_right_wheel_visual'>
          <geometry>
            <mesh>
              <uri>models/sdcCar/wheel.stl</uri>
              <scale>1 1 1</scale>
            </mesh>
          </geometry>
          <material>
            <script>
              <uri>file://media/materials/scripts/gazebo.material</uri>
              <name>Gazebo/Black</name>
            </script>
          </material>
        </visual>
        <self_collide>0</self_collide>
        <kinematic>0</kinematic>
        <gravity>1</gravity>
      </link>
      <link name='back_left_wheel'>
        <pose frame=''>-0.87 0.5 0.3 0 1.57079 1.57079</pose>
        <inertial>
          <mass>10</mass>
          <inertia>
            <ixx>1</ixx>
            <ixy>0</ixy>
            <ixz>0</ixz>
            <iyy>1</iyy>
            <iyz>0</iyz>
            <izz>1</izz>
          </inertia>
        </inertial>
        <collision name='back_left_wheel_collision'>
          <geometry>
            <cylinder>
              <radius>0.21</radius>
              <length>0.1</length>
            </cylinder>
          </geometry>
          <max_contacts>10</max_contacts>
          <surface>
            <contact>
              <ode/>
            </contact>
            <bounce/>
            <friction>
              <torsional>
                <ode/>
              </torsional>
              <ode/>
            </friction>
          </surface>
        </collision>
        <visual name='back_left_wheel_visual'>
          <geometry>
            <mesh>
              <uri>models/sdcCar/wheel.stl</uri>
              <scale>1 1 1</scale>
            </mesh>
          </geometry>
          <material>
            <script>
              <uri>file://media/materials/scripts/gazebo.material</uri>
              <name>Gazebo/Black</name>
            </script>
          </material>
        </visual>
        <self_collide>0</self_collide>
        <kinematic>0</kinematic>
        <gravity>1</gravity>
      </link>
      <joint name='front_left_joint' type='revolute2'>
        <parent>chassis</parent>
        <child>front_left_wheel</child>
        <axis>
          <xyz>0 0 1</xyz>
          <limit>
            <lower>0.012495</lower>
            <upper>0.012495</upper>
          </limit>
          <use_parent_model_frame>1</use_parent_model_frame>
          <dynamics>
            <spring_reference>0</spring_reference>
            <spring_stiffness>0</spring_stiffness>
          </dynamics>
        </axis>
        <axis2>
          <xyz>0 1 0</xyz>
          <use_parent_model_frame>1</use_parent_model_frame>
          <dynamics>
            <spring_reference>0</spring_reference>
            <spring_stiffness>0</spring_stiffness>
          </dynamics>
        </axis2>
        <physics>
          <ode>
            <limit>
              <cfm>0</cfm>
              <erp>0.9</erp>
            </limit>
            <suspension>
              <cfm>0.01</cfm>
              <erp>0.15</erp>
            </suspension>
          </ode>
        </physics>
      </joint>
      <joint name='front_right_joint' type='revolute2'>
        <parent>chassis</parent>
        <child>front_right_wheel</child>
        <axis>
          <xyz>0 0 1</xyz>
          <limit>
            <lower>0.012495</lower>
            <upper>0.012495</upper>
          </limit>
          <use_parent_model_frame>1</use_parent_model_frame>
          <dynamics>
            <spring_reference>0</spring_reference>
            <spring_stiffness>0</spring_stiffness>
          </dynamics>
        </axis>
        <axis2>
          <xyz>0 1 0</xyz>
          <use_parent_model_frame>1</use_parent_model_frame>
          <dynamics>
            <spring_reference>0</spring_reference>
            <spring_stiffness>0</spring_stiffness>
          </dynamics>
        </axis2>
        <physics>
          <ode>
            <limit>
              <cfm>0</cfm>
              <erp>0.9</erp>
            </limit>
            <suspension>
              <cfm>0.01</cfm>
              <erp>0.15</erp>
            </suspension>
          </ode>
        </physics>
      </joint>
      <joint name='back_right_joint' type='revolute2'>
        <parent>chassis</parent>
        <child>back_right_wheel</child>
        <axis>
          <xyz>0 0 1</xyz>
          <limit>
            <lower>0</lower>
            <upper>0</upper>
          </limit>
          <use_parent_model_frame>1</use_parent_model_frame>
          <dynamics>
            <spring_reference>0</spring_reference>
            <spring_stiffness>0</spring_stiffness>
          </dynamics>
        </axis>
        <axis2>
          <xyz>0 1 0</xyz>
          <use_parent_model_frame>1</use_parent_model_frame>
          <dynamics>
            <spring_reference>0</spring_reference>
            <spring_stiffness>0</spring_stiffness>
          </dynamics>
        </axis2>
        <physics>
          <ode>
            <limit>
              <cfm>0</cfm>
              <erp>0.9</erp>
            </limit>
            <suspension>
              <cfm>0.01</cfm>
              <erp>0.15</erp>
            </suspension>
          </ode>
        </physics>
      </joint>
      <joint name='back_left_joint' type='revolute2'>
        <parent>chassis</parent>
        <child>back_left_wheel</child>
        <axis>
          <xyz>0 0 1</xyz>
          <limit>
            <lower>0</lower>
            <upper>0</upper>
          </limit>
          <use_parent_model_frame>1</use_parent_model_frame>
          <dynamics>
            <spring_reference>0</spring_reference>
            <spring_stiffness>0</spring_stiffness>
          </dynamics>
        </axis>
        <axis2>
          <xyz>0 1 0</xyz>
          <use_parent_model_frame>1</use_parent_model_frame>
          <dynamics>
            <spring_reference>0</spring_reference>
            <spring_stiffness>0</spring_stiffness>
          </dynamics>
        </axis2>
        <physics>
          <ode>
            <limit>
              <cfm>0</cfm>
              <erp>0.9</erp>
            </limit>
            <suspension>
              <cfm>0.01</cfm>
              <erp>0.15</erp>
            </suspension>
          </ode>
        </physics>
      </joint>
      <link name='front_lidar'>
        <pose frame=''>1 0 0.4 0 -0 0</pose>
        <visual name='front_lidar_visual'>
          <geometry>
            <mesh>
              <uri>model://hokuyo/meshes/hokuyo.dae</uri>
              <scale>1 1 1</scale>
            </mesh>
          </geometry>
        </visual>
        <collision name='front_lidar_collision-base'>
          <pose frame=''>0 0 -0.0145 0 -0 0</pose>
          <geometry>
            <box>
              <size>0.05 0.05 0.041</size>
            </box>
          </geometry>
          <max_contacts>10</max_contacts>
          <surface>
            <contact>
              <ode/>
            </contact>
            <bounce/>
            <friction>
              <torsional>
                <ode/>
              </torsional>
              <ode/>
            </friction>
          </surface>
        </collision>
        <collision name='front_lidar_collision-top'>
          <pose frame=''>0 0 0.0205 0 -0 0</pose>
          <geometry>
            <cylinder>
              <radius>0.021</radius>
              <length>0.029</length>
            </cylinder>
          </geometry>
          <max_contacts>10</max_contacts>
          <surface>
            <contact>
              <ode/>
            </contact>
            <bounce/>
            <friction>
              <torsional>
                <ode/>
              </torsional>
              <ode/>
            </friction>
          </surface>
        </collision>
        <sensor name='front_lidar' type='ray'>
          <pose frame=''>0.01 0 0.0175 0 -0 0</pose>
          <ray>
            <scan>
              <horizontal>
                <samples>640</samples>
                <resolution>1</resolution>
                <min_angle>-1.39626</min_angle>
                <max_angle>1.39626</max_angle>
              </horizontal>
              <vertical>
                <samples>1</samples>
                <min_angle>0</min_angle>
                <max_angle>0</max_angle>
              </vertical>
            </scan>
            <range>
              <min>0.08</min>
              <max>20</max>
              <resolution>0.01</resolution>
            </range>
          </ray>
          <plugin name='sdcFrontLidarSensor' filename='build/libsdcFrontLidarSensor.so'/>
          <always_on>1</always_on>
          <update_rate>30</update_rate>
          <visualize>1</visualize>
        </sensor>
        <self_collide>0</self_collide>
        <inertial>
          <inertia>
            <ixx>1</ixx>
            <ixy>0</ixy>
            <ixz>0</ixz>
            <iyy>1</iyy>
            <iyz>0</iyz>
            <izz>1</izz>
          </inertia>
          <mass>1</mass>
        </inertial>
        <kinematic>0</kinematic>
        <gravity>1</gravity>
      </link>
      <joint name='front_lidar_joint' type='revolute'>
        <child>front_lidar</child>
        <parent>chassis</parent>
        <axis>
          <xyz>0 0 1</xyz>
          <limit>
            <upper>0</upper>
            <lower>0</lower>
          </limit>
          <use_parent_model_frame>1</use_parent_model_frame>
          <dynamics>
            <spring_reference>0</spring_reference>
            <spring_stiffness>0</spring_stiffness>
          </dynamics>
        </axis>
      </joint>
      <link name='back_lidar'>
        <pose frame=''>-1.2 0 0.4 0 -0 0</pose>
        <visual name='back_lidar_visual'>
          <geometry>
            <mesh>
              <uri>model://hokuyo/meshes/hokuyo.dae</uri>
              <scale>1 1 1</scale>
            </mesh>
          </geometry>
        </visual>
        <collision name='back_lidar_collision-base'>
          <pose frame=''>0 0 -0.0145 0 -0 0</pose>
          <geometry>
            <box>
              <size>0.05 0.05 0.041</size>
            </box>
          </geometry>
          <max_contacts>10</max_contacts>
          <surface>
            <contact>
              <ode/>
            </contact>
            <bounce/>
            <friction>
              <torsional>
                <ode/>
              </torsional>
              <ode/>
            </friction>
          </surface>
        </collision>
        <collision name='back_lidar_collision-top'>
          <pose frame=''>0 0 0.0205 0 -0 0</pose>
          <geometry>
            <cylinder>
              <radius>0.021</radius>
              <length>0.029</length>
            </cylinder>
          </geometry>
          <max_contacts>10</max_contacts>
          <surface>
            <contact>
              <ode/>
            </contact>
            <bounce/>
            <friction>
              <torsional>
                <ode/>
              </torsional>
              <ode/>
            </friction>
          </surface>
        </collision>
        <sensor name='back_lidar' type='ray'>
          <pose frame=''>0.01 0 0.0175 3.14159 -0.004307 3.14159</pose>
          <ray>
            <scan>
              <horizontal>
                <samples>120</samples>
                <resolution>1</resolution>
                <min_angle>-1.5709</min_angle>
                <max_angle>1.5709</max_angle>
              </horizontal>
              <vertical>
                <samples>1</samples>
                <min_angle>0</min_angle>
                <max_angle>0</max_angle>
              </vertical>
            </scan>
            <range>
              <min>0.08</min>
              <max>10</max>
              <resolution>0.01</resolution>
            </range>
          </ray>
          <plugin name='sdcBackLidarSensor' filename='build/libsdcBackLidarSensor.so'/>
          <always_on>1</always_on>
          <update_rate>30</update_rate>
          <visualize>0</visualize>
        </sensor>
        <self_collide>0</self_collide>
        <inertial>
          <inertia>
            <ixx>1</ixx>
            <ixy>0</ixy>
            <ixz>0</ixz>
            <iyy>1</iyy>
            <iyz>0</iyz>
            <izz>1</izz>
          </inertia>
          <mass>1</mass>
        </inertial>
        <kinematic>0</kinematic>
        <gravity>1</gravity>
      </link>
      <joint name='back_lidar_joint' type='revolute'>
        <child>back_lidar</child>
        <parent>chassis</parent>
        <axis>
          <xyz>0 0 1</xyz>
          <limit>
            <upper>0</upper>
            <lower>0</lower>
          </limit>
          <use_parent_model_frame>1</use_parent_model_frame>
          <dynamics>
            <spring_reference>0</spring_reference>
            <spring_stiffness>0</spring_stiffness>
          </dynamics>
        </axis>
      </joint>
      <link name='top_laser'>
        <pose frame=''>0 0 1.1 0 -0 0</pose>
        <visual name='top_laser_visual'>
          <geometry>
            <mesh>
              <uri>model://hokuyo/meshes/hokuyo.dae</uri>
              <scale>1 1 1</scale>
            </mesh>
          </geometry>
        </visual>
        <collision name='top_laser_collision-base'>
          <pose frame=''>0 0 -0.0145 0 -0 0</pose>
          <geometry>
            <box>
              <size>0.05 0.05 0.041</size>
            </box>
          </geometry>
          <max_contacts>10</max_contacts>
          <surface>
            <contact>
              <ode/>
            </contact>
            <bounce/>
            <friction>
              <torsional>
                <ode/>
              </torsional>
              <ode/>
            </friction>
          </surface>
        </collision>
        <collision name='top_laser_collision-top'>
          <pose frame=''>0 0 0.0205 0 -0 0</pose>
          <geometry>
            <cylinder>
              <radius>0.021</radius>
              <length>0.029</length>
            </cylinder>
          </geometry>
          <max_contacts>10</max_contacts>
          <surface>
            <contact>
              <ode/>
            </contact>
            <bounce/>
            <friction>
              <torsional>
                <ode/>
              </torsional>
              <ode/>
            </friction>
          </surface>
        </collision>
        <sensor name='top_left_laser' type='ray'>
          <pose frame=''>0.01 0 0.0175 0 0.18 1.5708</pose>
          <ray>
            <scan>
              <horizontal>
                <samples>160</samples>
                <resolution>1</resolution>
                <min_angle>-0.7854</min_angle>
                <max_angle>0.7854</max_angle>
              </horizontal>
              <vertical>
                <samples>1</samples>
                <min_angle>0</min_angle>
                <max_angle>0</max_angle>
              </vertical>
            </scan>
            <range>
              <min>0.08</min>
              <max>20</max>
              <resolution>0.01</resolution>
            </range>
          </ray>
          <plugin name='sdcTopLidarSensor' filename='build/libsdcTopLidarSensor.so'/>
          <always_on>1</always_on>
          <update_rate>30</update_rate>
          <visualize>0</visualize>
        </sensor>
        <sensor name='top_forward_laser' type='ray'>
          <pose frame=''>0.01 0 0.0175 0 0.18 0</pose>
          <ray>
            <scan>
              <horizontal>
                <samples>160</samples>
                <resolution>1</resolution>
                <min_angle>-0.7854</min_angle>
                <max_angle>0.7854</max_angle>
              </horizontal>
              <vertical>
                <samples>1</samples>
                <min_angle>0</min_angle>
                <max_angle>0</max_angle>
              </vertical>
            </scan>
            <range>
              <min>0.08</min>
              <max>20</max>
              <resolution>0.01</resolution>
            </range>
          </ray>
          <plugin name='sdcTopLidarSensor' filename='build/libsdcTopLidarSensor.so'/>
          <always_on>1</always_on>
          <update_rate>30</update_rate>
          <visualize>0</visualize>
        </sensor>
        <sensor name='top_backward_laser' type='ray'>
          <pose frame=''>0.01 0 0.0175 -0 0.18 3.14159</pose>
          <ray>
            <scan>
              <horizontal>
                <samples>160</samples>
                <resolution>1</resolution>
                <min_angle>-0.7854</min_angle>
                <max_angle>0.7854</max_angle>
              </horizontal>
              <vertical>
                <samples>1</samples>
                <min_angle>0</min_angle>
                <max_angle>0</max_angle>
              </vertical>
            </scan>
            <range>
              <min>0.08</min>
              <max>20</max>
              <resolution>0.01</resolution>
            </range>
          </ray>
          <plugin name='sdcTopLidarSensor' filename='build/libsdcTopLidarSensor.so'/>
          <always_on>1</always_on>
          <update_rate>30</update_rate>
          <visualize>0</visualize>
        </sensor>
        <sensor name='top_right_laser' type='ray'>
          <pose frame=''>0.01 0 0.0175 0 0.18 -1.5708</pose>
          <ray>
            <scan>
              <horizontal>
                <samples>160</samples>
                <resolution>1</resolution>
                <min_angle>-0.7854</min_angle>
                <max_angle>0.7854</max_angle>
              </horizontal>
              <vertical>
                <samples>1</samples>
                <min_angle>0</min_angle>
                <max_angle>0</max_angle>
              </vertical>
            </scan>
            <range>
              <min>0.08</min>
              <max>20</max>
              <resolution>0.01</resolution>
            </range>
          </ray>
          <plugin name='sdcTopLidarSensor' filename='build/libsdcTopLidarSensor.so'/>
          <always_on>1</always_on>
          <update_rate>30</update_rate>
          <visualize>0</visualize>
        </sensor>
        <self_collide>0</self_collide>
        <inertial>
          <inertia>
            <ixx>1</ixx>
            <ixy>0</ixy>
            <ixz>0</ixz>
            <iyy>1</iyy>
            <iyz>0</iyz>
            <izz>1</izz>
          </inertia>
          <mass>1</mass>
        </inertial>
        <kinematic>0</kinematic>
        <gravity>1</gravity>
      </link>
      <joint name='top_laser_joint' type='revolute'>
        <child>top_laser</child>
        <parent>chassis</parent>
        <axis>
          <xyz>0 0 1</xyz>
          <limit>
            <upper>0</upper>
            <lower>0</lower>
          </limit>
          <use_parent_model_frame>1</use_parent_model_frame>
          <dynamics>
            <spring_reference>0</spring_reference>
            <spring_stiffness>0</spring_stiffness>
          </dynamics>
        </axis>
      </joint>
      <link name='side_right_sensors'>
        <pose frame=''>0 -0.55 0.4 0 -0 0</pose>
        <visual name='side_right_sensors_visual'>
          <geometry>
            <mesh>
              <uri>model://hokuyo/meshes/hokuyo.dae</uri>
              <scale>1 1 1</scale>
            </mesh>
          </geometry>
        </visual>
        <collision name='side_right_sensors_collision-base'>
          <pose frame=''>0 0 -0.0145 0 -0 0</pose>
          <geometry>
            <box>
              <size>0.05 0.05 0.041</size>
            </box>
          </geometry>
          <max_contacts>10</max_contacts>
          <surface>
            <contact>
              <ode/>
            </contact>
            <bounce/>
            <friction>
              <torsional>
                <ode/>
              </torsional>
              <ode/>
            </friction>
          </surface>
        </collision>
        <collision name='side_right_sensors_collision-top'>
          <pose frame=''>0 0 0.0205 0 -0 0</pose>
          <geometry>
            <cylinder>
              <radius>0.021</radius>
              <length>0.029</length>
            </cylinder>
          </geometry>
          <max_contacts>10</max_contacts>
          <surface>
            <contact>
              <ode/>
            </contact>
            <bounce/>
            <friction>
              <torsional>
                <ode/>
              </torsional>
              <ode/>
            </friction>
          </surface>
        </collision>
        <sensor name='side_right_front_laser' type='ray'>
          <pose frame=''>0.4 -0.02 0 0 0 -1.5708</pose>
          <ray>
            <scan>
              <horizontal>
                <samples>160</samples>
                <resolution>1</resolution>
                <min_angle>-1.3</min_angle>
                <max_angle>1.3</max_angle>
              </horizontal>
              <vertical>
                <samples>1</samples>
                <min_angle>0</min_angle>
                <max_angle>0</max_angle>
              </vertical>
            </scan>
            <range>
              <min>0.08</min>
              <max>1</max>
              <resolution>0.01</resolution>
            </range>
          </ray>
          <plugin name='sdcSideLidarSensor' filename='build/libsdcSideLidarSensor.so'/>
          <always_on>1</always_on>
          <update_rate>30</update_rate>
          <visualize>0</visualize>
        </sensor>
        <sensor name='side_right_back_laser' type='ray'>
          <pose frame=''>-0.6 -0.02 0 0 0 -1.5708</pose>
          <ray>
            <scan>
              <horizontal>
                <samples>160</samples>
                <resolution>1</resolution>
                <min_angle>-1.3</min_angle>
                <max_angle>1.3</max_angle>
              </horizontal>
              <vertical>
                <samples>1</samples>
                <min_angle>0</min_angle>
                <max_angle>0</max_angle>
              </vertical>
            </scan>
            <range>
              <min>0.08</min>
              <max>1</max>
              <resolution>0.01</resolution>
            </range>
          </ray>
          <plugin name='sdcSideLidarSensor' filename='build/libsdcSideLidarSensor.so'/>
          <always_on>1</always_on>
          <update_rate>30</update_rate>
          <visualize>0</visualize>
        </sensor>
        <self_collide>0</self_collide>
        <inertial>
          <inertia>
            <ixx>1</ixx>
            <ixy>0</ixy>
            <ixz>0</ixz>
            <iyy>1</iyy>
            <iyz>0</iyz>
            <izz>1</izz>
          </inertia>
          <mass>1</mass>
        </inertial>
        <kinematic>0</kinematic>
        <gravity>1</gravity>
      </link>
      <joint name='side_right_sensor_joint' type='revolute'>
        <child>side_right_sensors</child>
        <parent>chassis</parent>
        <axis>
          <xyz>0 0 1</xyz>
          <limit>
            <upper>0</upper>
            <lower>0</lower>
          </limit>
          <use_parent_model_frame>1</use_parent_model_frame>
          <dynamics>
            <spring_reference>0</spring_reference>
            <spring_stiffness>0</spring_stiffness>
          </dynamics>
        </axis>
      </joint>
      <link name='side_left_sensors'>
        <pose frame=''>0 0.55 0.4 0 -0 0</pose>
        <visual name='side_left_sensors_visual'>
          <geometry>
            <mesh>
              <uri>model://hokuyo/meshes/hokuyo.dae</uri>
              <scale>1 1 1</scale>
            </mesh>
          </geometry>
        </visual>
        <collision name='side_left_sensors_collision-base'>
          <pose frame=''>0 0 -0.0145 0 -0 0</pose>
          <geometry>
            <box>
              <size>0.05 0.05 0.041</size>
            </box>
          </geometry>
          <max_contacts>10</max_contacts>
          <surface>
            <contact>
              <ode/>
            </contact>
            <bounce/>
            <friction>
              <torsional>
                <ode/>
              </torsional>
              <ode/>
            </friction>
          </surface>
        </collision>
        <collision name='side_left_sensors_collision-top'>
          <pose frame=''>0 0 0.0205 0 -0 0</pose>
          <geometry>
            <cylinder>
              <radius>0.021</radius>
              <length>0.029</length>
            </cylinder>
          </geometry>
          <max_contacts>10</max_contacts>
          <surface>
            <contact>
              <ode/>
            </contact>
            <bounce/>
            <friction>
              <torsional>
                <ode/>
              </torsional>
              <ode/>
            </friction>
          </surface>
        </collision>
        <sensor name='side_left_front_laser' type='ray'>
          <pose frame=''>0.4 0.02 0 0 -0 1.5708</pose>
          <ray>
            <scan>
              <horizontal>
                <samples>160</samples>
                <resolution>1</resolution>
                <min_angle>-1.3</min_angle>
                <max_angle>1.3</max_angle>
              </horizontal>
              <vertical>
                <samples>1</samples>
                <min_angle>0</min_angle>
                <max_angle>0</max_angle>
              </vertical>
            </scan>
            <range>
              <min>0.08</min>
              <max>1</max>
              <resolution>0.01</resolution>
            </range>
          </ray>
          <plugin name='sdcSideLidarSensor' filename='build/libsdcSideLidarSensor.so'/>
          <always_on>1</always_on>
          <update_rate>30</update_rate>
          <visualize>0</visualize>
        </sensor>
        <sensor name='side_left_back_laser' type='ray'>
          <pose frame=''>-0.6 0.02 0 0 -0 1.5708</pose>
          <ray>
            <scan>
              <horizontal>
                <samples>160</samples>
                <resolution>1</resolution>
                <min_angle>-1.3</min_angle>
                <max_angle>1.3</max_angle>
              </horizontal>
              <vertical>
                <samples>1</samples>
                <min_angle>0</min_angle>
                <max_angle>0</max_angle>
              </vertical>
            </scan>
            <range>
              <min>0.08</min>
              <max>1</max>
              <resolution>0.01</resolution>
            </range>
          </ray>
          <plugin name='sdcSideLidarSensor' filename='build/libsdcSideLidarSensor.so'/>
          <always_on>1</always_on>
          <update_rate>30</update_rate>
          <visualize>0</visualize>
        </sensor>
        <self_collide>0</self_collide>
        <inertial>
          <inertia>
            <ixx>1</ixx>
            <ixy>0</ixy>
            <ixz>0</ixz>
            <iyy>1</iyy>
            <iyz>0</iyz>
            <izz>1</izz>
          </inertia>
          <mass>1</mass>
        </inertial>
        <kinematic>0</kinematic>
        <gravity>1</gravity>
      </link>
      <joint name='side_left_sensor_joint' type='revolute'>
        <child>side_left_sensors</child>
        <parent>chassis</parent>
        <axis>
          <xyz>0 0 1</xyz>
          <limit>
            <upper>0</upper>
            <lower>0</lower>
          </limit>
          <use_parent_model_frame>1</use_parent_model_frame>
          <dynamics>
            <spring_reference>0</spring_reference>
            <spring_stiffness>0</spring_stiffness>
          </dynamics>
        </axis>
      </joint>
      <link name='camera::link'>
        <pose frame=''>0.65 0 0.85 0 0.008 0</pose>
        <self_collide>0</self_collide>
        <kinematic>0</kinematic>
        <sensor name='camera' type='multicamera'>
          <always_on>1</always_on>
          <update_rate>24</update_rate>
          <visualize>0</visualize>
          <topic>comps_car_camera</topic>
          <camera name='left'>
            <pose frame=''>0 0 0 0 -0 0</pose>
            <horizontal_fov>1.047</horizontal_fov>
            <image>
              <width>640</width>
              <height>480</height>
            </image>
            <clip>
              <near>0.1</near>
              <far>150</far>
            </clip>
            <save enabled='0'>
              <path>/Users/selfcar/Desktop/Self-Driving-Comps/comps_camera_recordings/</path>
            </save>
          </camera>
          <plugin name='sdcCameraSensor' filename='build/libsdcCameraSensor.so'/>
        </sensor>
        <visual name='visual'>
          <geometry>
            <box>
              <size>0.1 0.1 0.1</size>
            </box>
          </geometry>
          <material>
            <shader type='pixel'/>
          </material>
          <pose frame=''>0 0 0 0 -0 0</pose>
          <cast_shadows>1</cast_shadows>
          <transparency>0</transparency>
        </visual>
        <inertial>
          <inertia>
            <ixx>1</ixx>
            <ixy>0</ixy>
            <ixz>0</ixz>
            <iyy>1</iyy>
            <iyz>0</iyz>
            <izz>1</izz>
          </inertia>
          <mass>1</mass>
        </inertial>
        <gravity>1</gravity>
      </link>
      <joint name='camera' type='revolute'>
        <parent>chassis</parent>
        <child>camera::link</child>
        <axis>
          <xyz>0 0 1</xyz>
          <use_parent_model_frame>0</use_parent_model_frame>
          <limit>
            <lower>0</lower>
            <upper>0</upper>
            <effort>-1</effort>
            <velocity>-1</velocity>
          </limit>
          <dynamics>
            <spring_reference>0</spring_reference>
            <spring_stiffness>0</spring_stiffness>
            <damping>0</damping>
            <friction>0</friction>
          </dynamics>
          <use_parent_model_frame>1</use_parent_model_frame>
        </axis>
        <physics>
          <ode>
            <limit>
              <cfm>0</cfm>
              <erp>0.2</erp>
            </limit>
            <suspension>
              <cfm>0</cfm>
              <erp>0.2</erp>
            </suspension>
          </ode>
        </physics>
      </joint>
      <link name='gps'>
        <pose frame=''>0 0 1 0 -0 0</pose>
        <visual name='visual'>
          <geometry>
            <mesh>
              <uri>model://hokuyo/meshes/hokuyo.dae</uri>
              <scale>1 1 1</scale>
            </mesh>
          </geometry>
        </visual>
        <collision name='gps_collision-base'>
          <pose frame=''>0 0 -0.0145 0 -0 0</pose>
          <geometry>
            <box>
              <size>0.05 0.05 0.041</size>
            </box>
          </geometry>
          <max_contacts>10</max_contacts>
          <surface>
            <contact>
              <ode/>
            </contact>
            <bounce/>
            <friction>
              <torsional>
                <ode/>
              </torsional>
              <ode/>
            </friction>
          </surface>
        </collision>
        <collision name='gps_collision-top'>
          <pose frame=''>0 0 0.0205 0 -0 0</pose>
          <geometry>
            <cylinder>
              <radius>0.021</radius>
              <length>0.029</length>
            </cylinder>
          </geometry>
          <max_contacts>10</max_contacts>
          <surface>
            <contact>
              <ode/>
            </contact>
            <bounce/>
            <friction>
              <torsional>
                <ode/>
              </torsional>
              <ode/>
            </friction>
          </surface>
        </collision>
        <sensor name='gps' type='gps'>
          <pose frame=''>0 0 0 0 -0 0</pose>
          <always_on>1</always_on>
          <update_rate>30</update_rate>
        </sensor>
        <self_collide>0</self_collide>
        <inertial>
          <inertia>
            <ixx>1</ixx>
            <ixy>0</ixy>
            <ixz>0</ixz>
            <iyy>1</iyy>
            <iyz>0</iyz>
            <izz>1</izz>
          </inertia>
          <mass>1</mass>
        </inertial>
        <kinematic>0</kinematic>
        <gravity>1</gravity>
      </link>
      <joint name='gps_joint' type='revolute'>
        <child>gps</child>
        <parent>chassis</parent>
        <axis>
          <xyz>0 0 1</xyz>
          <limit>
            <upper>0</upper>
            <lower>0</lower>
          </limit>
          <use_parent_model_frame>1</use_parent_model_frame>
          <dynamics>
            <spring_reference>0</spring_reference>
            <spring_stiffness>0</spring_stiffness>
          </dynamics>
        </axis>
      </joint>
      <plugin name='sdcCar' filename='build/libsdcCar.so'>
        <front_left>front_left_joint</front_left>
        <front_right>front_right_joint</front_right>
        <back_left>back_left_joint</back_left>
        <back_right>back_right_joint</back_right>
        <chassis>chassis</chassis>
        <camera>camera::link</camera>
        <frontLidar>front_lidar</frontLidar>
        <wheel_radius>0.21</wheel_radius>
        <front_power>10</front_power>
        <rear_power>10</rear_power>
        <tire_angle_range>0.5</tire_angle_range>
        <max_speed>10</max_speed>
        <aero_load>1.0</aero_load>
      </plugin>
      <plugin name='sdcGpsSensor' filename='build/libsdcGpsSensor.so'>
        <gps>gps</gps>
      </plugin>
      <pose frame=''>-12 -0.5 0 0 -0 0</pose>
    </model>
    <model name='ground_plane'>
      <static>1</static>
      <link name='link'>
        <pose frame=''>50 100 0 0 -0 0</pose>
        <collision name='collision'>
          <geometry>
            <plane>
              <normal>0 0 1</normal>
              <size>100 20</size>
            </plane>
          </geometry>
          <max_contacts>10</max_contacts>
          <surface>
            <contact>
              <ode/>
            </contact>
            <bounce/>
            <friction>
              <torsional>
                <ode/>
              </torsional>
              <ode/>
            </friction>
          </surface>
        </collision>
        <visual name='visual'>
          <cast_shadows>0</cast_shadows>
          <geometry>
            <plane>
              <normal>0 0 1</normal>
              <size>100 20</size>
            </plane>
          </geometry>
          <material>
            <script>
              <uri>__default__</uri>
              <name>__default__</name>
            </script>
          </material>
        </visual>
        <self_collide>0</self_collide>
        <kinematic>0</kinematic>
        <gravity>1</gravity>
      </link>
    </model>
    <model name='road_2_0_1'>
      <pose frame=''>25 1.02 -0.05 0 -0 0</pose>
      <static>1</static>
      <link name='link'>
        <collision name='collision'>
          <geometry>
            <box>
              <size>75 6.54 0.0001</size>
            </box>
          </geometry>
          <max_contacts>10</max_contacts>
          <surface>
            <contact>
              <ode/>
            </contact>
            <bounce/>
            <friction>
              <torsional>
                <ode/>
              </torsional>
              <ode/>
            </friction>
          </surface>
        </collision>
        <visual name='visual'>
          <cast_shadows>0</cast_shadows>
          <geometry>
            <box>
              <size>75 6.54 0.0001</size>
            </box>
          </geometry>
          <material>
            <script>
              <uri>models/newstraight/materials/scripts</uri>
              <uri>models/newstraight/materials/textures</uri>
              <name>newstraight</name>
            </script>
          </material>
        </visual>
        <self_collide>0</self_collide>
        <kinematic>0</kinematic>
        <gravity>1</gravity>
      </link>
    </model>
    <model name='road_2_0_2'>
      <pose frame=''>139.5 -47.4 -0.05 0 0 -0.78</pose>
      <static>1</static>
      <link name='link'>
        <collision name='collision'>
          <geometry>
            <box>
              <size>75 6.54 0.0001</size>
            </box>
          </geometry>
          <max_contacts>10</max_contacts>
          <surface>
            <contact>
              <ode/>
            </contact>
            <bounce/>
            <friction>
              <torsional>
                <ode/>
              </torsional>
              <ode/>
            </friction>
          </surface>
        </collision>
        <visual name='visual'>
          <cast_shadows>0</cast_shadows>
          <geometry>
            <box>
              <size>75 6.54 0.0001</size>
            </box>
          </geometry>
          <material>
            <script>
              <uri>models/newstraight/materials/scripts</uri>
              <uri>models/newstraight/materials/textures</uri>
              <name>newstraight</name>
            </script>
          </material>
        </visual>
        <self_collide>0</self_collide>
        <kinematic>0</kinematic>
        <gravity>1</gravity>
      </link>
    </model>
    <physics name='default_physics' default='0' type='ode'>
      <max_step_size>0.001</max_step_size>
      <real_time_factor>1</real_time_factor>
      <real_time_update_rate>1000</real_time_update_rate>
      <gravity>0 0 -9.8</gravity>
      <magnetic_field>6e-06 2.3e-05 -4.2e-05</magnetic_field>
    </physics>
    <scene>
      <ambient>0.4 0.4 0.4 1</ambient>
      <background>0.7 0.7 0.7 1</background>
      <shadows>1</shadows>
    </scene>
    <spherical_coordinates>
      <surface_model>EARTH_WGS84</surface_model>
      <latitude_deg>0</latitude_deg>
      <longitude_deg>0</longitude_deg>
      <elevation>0</elevation>
      <heading_deg>0</heading_deg>
    </spherical_coordinates>
    <model name='road_2_0_2_clone'>
      <pose frame=''>191.652 -96.019 -0.05 0 0 -0.78</pose>
      <static>1</static>
      <link name='link'>
        <collision name='collision'>
          <geometry>
            <box>
              <size>75 6.54 0.0001</size>
            </box>
          </geometry>
          <max_contacts>10</max_contacts>
          <surface>
            <contact>
              <ode/>
            </contact>
            <bounce/>
            <friction>
              <torsional>
                <ode/>
              </torsional>
              <ode/>
            </friction>
          </surface>
        </collision>
        <visual name='visual'>
          <cast_shadows>0</cast_shadows>
          <geometry>
            <box>
              <size>75 6.54 0.0001</size>
            </box>
          </geometry>
          <material>
            <script>
              <uri>models/newstraight/materials/scripts</uri>
              <uri>models/newstraight/materials/textures</uri>
              <name>newstraight</name>
            </script>
          </material>
        </visual>
        <self_collide>0</self_collide>
        <kinematic>0</kinematic>
        <gravity>1</gravity>
      </link>
    </model>
    <model name='curved_road_clone'>
      <static>1</static>
      <link name='link'>
        <collision name='collision'>
          <geometry>
            <mesh>
              <uri>models/newcurve/curve8k.dae</uri>
              <scale>1 1 1</scale>
            </mesh>
          </geometry>
          <max_contacts>10</max_contacts>
          <surface>
            <contact>
              <ode/>
            </contact>
            <bounce/>
            <friction>
              <torsional>
                <ode/>
              </torsional>
              <ode/>
            </friction>
          </surface>
        </collision>
        <visual name='visual'>
          <cast_shadows>0</cast_shadows>
          <geometry>
            <mesh>
              <uri>models/newcurve/curve8k.dae</uri>
              <scale>1 1 1</scale>
            </mesh>
          </geometry>
          <material>
            <script>
              <uri>models/newcurve/materials/scripts</uri>
              <uri>models/newcurve/materials/textures</uri>
              <name>newcurve</name>
            </script>
          </material>
        </visual>
        <self_collide>0</self_collide>
        <kinematic>0</kinematic>
        <gravity>1</gravity>
      </link>
      <pose frame=''>151.942 -44.8313 -0.05 0 0 -1.575</pose>
    </model>
    <model name='road_2_0_2_clone_clone'>
      <pose frame=''>309.611 -152.455 -0.05 0 0 -0.78</pose>
      <static>1</static>
      <link name='link'>
        <collision name='collision'>
          <geometry>
            <box>
              <size>308.643 6.54 0.0001</size>
            </box>
          </geometry>
          <max_contacts>10</max_contacts>
          <surface>
            <contact>
              <ode/>
            </contact>
            <bounce/>
            <friction>
              <torsional>
                <ode/>
              </torsional>
              <ode/>
            </friction>
          </surface>
        </collision>
        <visual name='visual'>
          <cast_shadows>0</cast_shadows>
          <geometry>
            <box>
              <size>308.643 6.54 0.0001</size>
            </box>
          </geometry>
          <material>
            <script>
              <uri>models/newstraight/materials/scripts</uri>
              <uri>models/newstraight/materials/textures</uri>
              <name>newstraight</name>
            </script>
          </material>
        </visual>
        <self_collide>0</self_collide>
        <kinematic>0</kinematic>
        <gravity>1</gravity>
      </link>
    </model>
    <state world_name='default'>
      <sim_time>0 0</sim_time>
      <real_time>0 0</real_time>
      <wall_time>1486603487 600403000</wall_time>
      <iterations>0</iterations>
      <model name='car'>
        <pose frame=''>-12 -0.500037 -1e-05 2e-06 -9e-06 0.000733</pose>
        <link name='back_left_wheel'>
          <pose frame=''>-12.8701 -0.000227 0.29999 0.93783 1.57078 2.50872</pose>
          <velocity>-0.061281 -0.22674 -0.009822 0.001047 0.01 0.102979</velocity>
          <acceleration>-61.2808 -226.74 -9.82205 -2.09507 -0.575222 -0.693105</acceleration>
          <wrench>-612.808 -2267.4 -98.2205 0 -0 0</wrench>
        </link>
        <link name='back_lidar'>
          <pose frame=''>-13.2 -0.500694 0.399986 -1.1e-05 -1e-06 0.000497</pose>
          <velocity>0.001374 -0.693897 -0.013612 -0.01098 -0.001073 0.49729</velocity>
          <acceleration>1.37435 -693.897 -13.6116 1.5863 -1.07263 0.918022</acceleration>
          <wrench>1.37435 -693.897 -13.6116 0 -0 0</wrench>
        </link>
        <link name='back_right_wheel'>
          <pose frame=''>-12.8699 -1.00019 0.29999 -0.606443 1.57078 -2.17699</pose>
          <velocity>0.112492 -0.187421 -0.009809 -0.008043 0.01 0.247107</velocity>
          <acceleration>112.492 -187.421 -9.80925 1.38134 -0.575222 -1.0784</acceleration>
          <wrench>1124.92 -1874.21 -98.0925 0 -0 0</wrench>
        </link>
        <link name='camera::link'>
          <pose frame=''>-11.35 -0.499576 0.849996 -2e-06 0.007992 0.000699</pose>
          <velocity>-0.002821 0.423694 -0.003983 -0.002253 -0.007942 0.698994</velocity>
          <acceleration>-2.82073 423.694 -3.98299 0.88831 -1.48282 -1.58119</acceleration>
          <wrench>-2.82073 423.694 -3.98299 0 -0 0</wrench>
        </link>
        <link name='chassis'>
          <pose frame=''>-12 -0.500038 0.34999 2e-06 -9e-06 0.000733</pose>
          <velocity>0.003737 -0.03771 -0.009841 0.001598 -0.009308 0.732594</velocity>
          <acceleration>3.73724 -37.7099 -9.84105 -1.54353 -0.117002 0.602855</acceleration>
          <wrench>373.724 -3770.99 -984.105 0 -0 0</wrench>
        </link>
        <link name='front_left_wheel'>
          <pose frame=''>-11.2004 0.000501 0.29999 0.786417 1.57078 2.34669</pose>
          <velocity>-0.356693 0.5011 -0.009692 0.00375 0.01 2.05344</velocity>
          <acceleration>-356.693 501.1 -9.69243 0.608518 -0.575222 1.97995</acceleration>
          <wrench>-3566.93 5011 -96.9243 0 -0 0</wrench>
        </link>
        <link name='front_lidar'>
          <pose frame=''>-11 -0.499593 0.399989 -1e-05 3e-06 0.000401</pose>
          <velocity>0.001566 0.406887 -0.010648 -0.010006 0.002867 0.401039</velocity>
          <acceleration>1.56638 406.887 -10.6478 -0.581653 0.274771 2.05705</acceleration>
          <wrench>1.56638 406.887 -10.6478 0 -0 0</wrench>
        </link>
        <link name='front_right_wheel'>
          <pose frame=''>-11.1997 -0.999707 0.29999 -1.12402 1.57079 -2.70547</pose>
          <velocity>0.270441 0.292647 -0.009721 0.001626 0.01 1.90255</velocity>
          <acceleration>270.441 292.647 -9.72061 -1.5155 -0.575222 1.89162</acceleration>
          <wrench>2704.41 2926.47 -97.206 0 -0 0</wrench>
        </link>
        <link name='gps'>
          <pose frame=''>-12 -0.500041 0.99999 -5e-06 -9e-06 0.000724</pose>
          <velocity>-0.004285 -0.040898 -0.009835 -0.004824 -0.008653 0.723467</velocity>
          <acceleration>-4.28524 -40.8979 -9.83501 -1.68288 -0.771794 -2.24058</acceleration>
          <wrench>-4.28524 -40.8979 -9.83501 0 -0 0</wrench>
        </link>
        <link name='side_left_sensors'>
          <pose frame=''>-12.0004 0.049958 0.399988 -5e-06 -6e-06 0.00067</pose>
          <velocity>-0.378512 -0.041737 -0.011685 -0.005358 -0.006092 0.669934</velocity>
          <acceleration>-378.512 -41.7369 -11.6855 0.924869 0.191098 -2.36693</acceleration>
          <wrench>-378.512 -41.7369 -11.6855 0 -0 0</wrench>
        </link>
        <link name='side_right_sensors'>
          <pose frame=''>-11.9996 -1.05004 0.399994 -8e-06 -6e-06 0.00063</pose>
          <velocity>0.362372 -0.041634 -0.006443 -0.007749 -0.005598 0.629294</velocity>
          <acceleration>362.372 -41.6344 -6.44283 -1.46612 0.685163 0.975397</acceleration>
          <wrench>362.372 -41.6344 -6.44283 0 -0 0</wrench>
        </link>
        <link name='top_laser'>
          <pose frame=''>-12 -0.500037 1.09999 -7e-06 -5e-06 0.000594</pose>
          <velocity>-0.003012 -0.03728 -0.009846 -0.007007 -0.005332 0.593891</velocity>
          <acceleration>-3.01231 -37.28 -9.84557 -0.724245 0.95154 -3.0115</acceleration>
          <wrench>-3.01231 -37.28 -9.84557 0 -0 0</wrench>
        </link>
      </model>
      <model name='curved_road'>
        <pose frame=''>91.1197 -5.22028 -0.13 0 0 -1.575</pose>
        <link name='link'>
          <pose frame=''>91.1197 -5.22028 -0.13 0 0 -1.575</pose>
          <velocity>0 0 0 0 -0 0</velocity>
          <acceleration>0 0 0 0 -0 0</acceleration>
          <wrench>0 0 0 0 -0 0</wrench>
        </link>
      </model>
      <model name='curved_road_clone'>
        <pose frame=''>243.27 -138.224 -0.13 0 -0 1.56957</pose>
        <link name='link'>
          <pose frame=''>243.27 -138.224 -0.13 0 -0 1.56957</pose>
          <velocity>0 0 0 0 -0 0</velocity>
          <acceleration>0 0 0 0 -0 0</acceleration>
          <wrench>0 0 0 0 -0 0</wrench>
        </link>
      </model>
      <model name='ground_plane'>
        <pose frame=''>0 0 0 0 -0 0</pose>
        <link name='link'>
          <pose frame=''>50 100 0 0 -0 0</pose>
          <velocity>0 0 0 0 -0 0</velocity>
          <acceleration>0 0 0 0 -0 0</acceleration>
          <wrench>0 0 0 0 -0 0</wrench>
        </link>
      </model>
      <model name='road_2_0_1'>
        <pose frame=''>25 1.02 -0.05 0 -0 0</pose>
        <link name='link'>
          <pose frame=''>25 1.02 -0.05 0 -0 0</pose>
          <velocity>0 0 0 0 -0 0</velocity>
          <acceleration>0 0 0 0 -0 0</acceleration>
          <wrench>0 0 0 0 -0 0</wrench>
        </link>
      </model>
      <model name='road_2_0_2'>
        <pose frame=''>140.495 -45.3521 -0.05 0 0 -0.78</pose>
        <link name='link'>
          <pose frame=''>140.495 -45.3521 -0.05 0 0 -0.78</pose>
          <velocity>0 0 0 0 -0 0</velocity>
          <acceleration>0 0 0 0 -0 0</acceleration>
          <wrench>0 0 0 0 -0 0</wrench>
        </link>
      </model>
      <model name='road_2_0_2_clone'>
        <pose frame=''>193.77 -98.066 -0.05 0 0 -0.78</pose>
        <link name='link'>
          <pose frame=''>193.77 -98.066 -0.05 0 0 -0.78</pose>
          <velocity>0 0 0 0 -0 0</velocity>
          <acceleration>0 0 0 0 -0 0</acceleration>
          <wrench>0 0 0 0 -0 0</wrench>
        </link>
      </model>
      <model name='road_2_0_2_clone_clone'>
        <pose frame=''>426.333 -144.096 -0.05 0 -0 0.001754</pose>
        <link name='link'>
          <pose frame=''>426.333 -144.096 -0.05 0 -0 0.001754</pose>
          <velocity>0 0 0 0 -0 0</velocity>
          <acceleration>0 0 0 0 -0 0</acceleration>
          <wrench>0 0 0 0 -0 0</wrench>
        </link>
      </model>
    </state>
    <audio>
      <device>default</device>
    </audio>
  </world>
</sdf>
