<sdf version='1.5'>
  <world name='default'>
    <gui fullscreen='0'>
      <camera name='user_camera'>
        <pose frame=''>308.797 -78.8683 89.1101 0 0.885796 -1.74801</pose>
        <view_controller>orbit</view_controller>
        <projection_type>perspective</projection_type>
      </camera>
    </gui>
    <light name='sun' type='directional'>
      <cast_shadows>1</cast_shadows>
      <pose frame=''>0 0 10 0 -0 0</pose>
      <diffuse>0.8 0.8 0.8 1</diffuse>
      <specular>0.1 0.1 0.1 1</specular>
      <attenuation>
        <range>1000</range>
        <constant>0.9</constant>
        <linear>0.01</linear>
        <quadratic>0.001</quadratic>
      </attenuation>
      <direction>-0.5 0.5 -1</direction>
    </light>
    <model name='curved_road'>
      <static>1</static>
      <link name='link'>
        <collision name='collision'>
          <geometry>
            <mesh>
              <uri>models/newcurve/curve8k.dae</uri>
              <scale>1 1 1</scale>
            </mesh>
          </geometry>
          <max_contacts>10</max_contacts>
          <surface>
            <contact>
              <ode/>
            </contact>
            <bounce/>
            <friction>
              <torsional>
                <ode/>
              </torsional>
              <ode/>
            </friction>
          </surface>
        </collision>
        <visual name='visual'>
          <cast_shadows>0</cast_shadows>
          <geometry>
            <mesh>
              <uri>models/newcurve/curve8k.dae</uri>
              <scale>1 1 1</scale>
            </mesh>
          </geometry>
          <material>
            <script>
              <uri>models/newcurve/materials/scripts</uri>
              <uri>models/newcurve/materials/textures</uri>
              <name>newcurve</name>
            </script>
          </material>
        </visual>
        <self_collide>0</self_collide>
        <kinematic>0</kinematic>
        <gravity>1</gravity>
      </link>
      <pose frame=''>91.25 -2.5 -0.13 0 0 -1.575</pose>
    </model>
    <model name='car'>
      <link name='chassis'>
        <pose frame=''>0 0 0.35 0 -0 0</pose>
        <inertial>
          <mass>100</mass>
          <inertia>
            <ixx>1</ixx>
            <ixy>0</ixy>
            <ixz>0</ixz>
            <iyy>1</iyy>
            <iyz>0</iyz>
            <izz>1</izz>
          </inertia>
        </inertial>
        <collision name='chassis_collision'>
          <geometry>
            <box>
              <size>2 0.8 0.2</size>
            </box>
          </geometry>
          <max_contacts>10</max_contacts>
          <surface>
            <contact>
              <ode/>
            </contact>
            <bounce/>
            <friction>
              <torsional>
                <ode/>
              </torsional>
              <ode/>
            </friction>
          </surface>
        </collision>
        <visual name='chassis_visual'>
          <pose frame=''>0.1 0 -0.2 0 -0 1.57079</pose>
          <geometry>
            <mesh>
              <uri>models/sdcCar/cooper-test.dae</uri>
              <scale>1 1 1</scale>
            </mesh>
          </geometry>
        </visual>
        <self_collide>0</self_collide>
        <kinematic>0</kinematic>
        <gravity>1</gravity>
      </link>
      <link name='front_left_wheel'>
        <inertial>
          <mass>10</mass>
          <inertia>
            <ixx>1</ixx>
            <ixy>0</ixy>
            <ixz>0</ixz>
            <iyy>1</iyy>
            <iyz>0</iyz>
            <izz>1</izz>
          </inertia>
        </inertial>
        <pose frame=''>0.8 0.5 0.3 0 1.57079 1.57079</pose>
        <collision name='front_left_wheel_collision'>
          <geometry>
            <cylinder>
              <radius>0.21</radius>
              <length>0.1</length>
            </cylinder>
          </geometry>
          <max_contacts>10</max_contacts>
          <surface>
            <contact>
              <ode/>
            </contact>
            <bounce/>
            <friction>
              <torsional>
                <ode/>
              </torsional>
              <ode/>
            </friction>
          </surface>
        </collision>
        <visual name='front_left_wheel_visual'>
          <geometry>
            <mesh>
              <uri>models/sdcCar/wheel.stl</uri>
              <scale>1 1 1</scale>
            </mesh>
          </geometry>
          <material>
            <script>
              <uri>file://media/materials/scripts/gazebo.material</uri>
              <name>Gazebo/Black</name>
            </script>
          </material>
        </visual>
        <self_collide>0</self_collide>
        <kinematic>0</kinematic>
        <gravity>1</gravity>
      </link>
      <link name='front_right_wheel'>
        <pose frame=''>0.8 -0.5 0.3 0 1.57079 -1.57079</pose>
        <inertial>
          <mass>10</mass>
          <inertia>
            <ixx>1</ixx>
            <ixy>0</ixy>
            <ixz>0</ixz>
            <iyy>1</iyy>
            <iyz>0</iyz>
            <izz>1</izz>
          </inertia>
        </inertial>
        <collision name='front_right_wheel_collision'>
          <geometry>
            <cylinder>
              <radius>0.21</radius>
              <length>0.1</length>
            </cylinder>
          </geometry>
          <max_contacts>10</max_contacts>
          <surface>
            <contact>
              <ode/>
            </contact>
            <bounce/>
            <friction>
              <torsional>
                <ode/>
              </torsional>
              <ode/>
            </friction>
          </surface>
        </collision>
        <visual name='front_right_wheel_visual'>
          <geometry>
            <mesh>
              <uri>models/sdcCar/wheel.stl</uri>
              <scale>1 1 1</scale>
            </mesh>
          </geometry>
          <material>
            <script>
              <uri>file://media/materials/scripts/gazebo.material</uri>
              <name>Gazebo/Black</name>
            </script>
          </material>
        </visual>
        <self_collide>0</self_collide>
        <kinematic>0</kinematic>
        <gravity>1</gravity>
      </link>
      <link name='back_right_wheel'>
        <pose frame=''>-0.87 -0.5 0.3 0 1.57079 -1.57079</pose>
        <inertial>
          <mass>10</mass>
          <inertia>
            <ixx>1</ixx>
            <ixy>0</ixy>
            <ixz>0</ixz>
            <iyy>1</iyy>
            <iyz>0</iyz>
            <izz>1</izz>
          </inertia>
        </inertial>
        <collision name='back_right_wheel_collision'>
          <geometry>
            <cylinder>
              <radius>0.21</radius>
              <length>0.1</length>
            </cylinder>
          </geometry>
          <max_contacts>10</max_contacts>
          <surface>
            <contact>
              <ode/>
            </contact>
            <bounce/>
            <friction>
              <torsional>
                <ode/>
              </torsional>
              <ode/>
            </friction>
          </surface>
        </collision>
        <visual name='back_right_wheel_visual'>
          <geometry>
            <mesh>
              <uri>models/sdcCar/wheel.stl</uri>
              <scale>1 1 1</scale>
            </mesh>
          </geometry>
          <material>
            <script>
              <uri>file://media/materials/scripts/gazebo.material</uri>
              <name>Gazebo/Black</name>
            </script>
          </material>
        </visual>
        <self_collide>0</self_collide>
        <kinematic>0</kinematic>
        <gravity>1</gravity>
      </link>
      <link name='back_left_wheel'>
        <pose frame=''>-0.87 0.5 0.3 0 1.57079 1.57079</pose>
        <inertial>
          <mass>10</mass>
          <inertia>
            <ixx>1</ixx>
            <ixy>0</ixy>
            <ixz>0</ixz>
            <iyy>1</iyy>
            <iyz>0</iyz>
            <izz>1</izz>
          </inertia>
        </inertial>
        <collision name='back_left_wheel_collision'>
          <geometry>
            <cylinder>
              <radius>0.21</radius>
              <length>0.1</length>
            </cylinder>
          </geometry>
          <max_contacts>10</max_contacts>
          <surface>
            <contact>
              <ode/>
            </contact>
            <bounce/>
            <friction>
              <torsional>
                <ode/>
              </torsional>
              <ode/>
            </friction>
          </surface>
        </collision>
        <visual name='back_left_wheel_visual'>
          <geometry>
            <mesh>
              <uri>models/sdcCar/wheel.stl</uri>
              <scale>1 1 1</scale>
            </mesh>
          </geometry>
          <material>
            <script>
              <uri>file://media/materials/scripts/gazebo.material</uri>
              <name>Gazebo/Black</name>
            </script>
          </material>
        </visual>
        <self_collide>0</self_collide>
        <kinematic>0</kinematic>
        <gravity>1</gravity>
      </link>
      <joint name='front_left_joint' type='revolute2'>
        <parent>chassis</parent>
        <child>front_left_wheel</child>
        <axis>
          <xyz>0 0 1</xyz>
          <limit>
            <lower>0</lower>
            <upper>0</upper>
          </limit>
          <use_parent_model_frame>1</use_parent_model_frame>
          <dynamics>
            <spring_reference>0</spring_reference>
            <spring_stiffness>0</spring_stiffness>
          </dynamics>
        </axis>
        <axis2>
          <xyz>0 1 0</xyz>
          <use_parent_model_frame>1</use_parent_model_frame>
          <dynamics>
            <spring_reference>0</spring_reference>
            <spring_stiffness>0</spring_stiffness>
          </dynamics>
        </axis2>
        <physics>
          <ode>
            <limit>
              <cfm>0</cfm>
              <erp>0.9</erp>
            </limit>
            <suspension>
              <cfm>0.01</cfm>
              <erp>0.15</erp>
            </suspension>
          </ode>
        </physics>
      </joint>
      <joint name='front_right_joint' type='revolute2'>
        <parent>chassis</parent>
        <child>front_right_wheel</child>
        <axis>
          <xyz>0 0 1</xyz>
          <limit>
            <lower>0</lower>
            <upper>0</upper>
          </limit>
          <use_parent_model_frame>1</use_parent_model_frame>
          <dynamics>
            <spring_reference>0</spring_reference>
            <spring_stiffness>0</spring_stiffness>
          </dynamics>
        </axis>
        <axis2>
          <xyz>0 1 0</xyz>
          <use_parent_model_frame>1</use_parent_model_frame>
          <dynamics>
            <spring_reference>0</spring_reference>
            <spring_stiffness>0</spring_stiffness>
          </dynamics>
        </axis2>
        <physics>
          <ode>
            <limit>
              <cfm>0</cfm>
              <erp>0.9</erp>
            </limit>
            <suspension>
              <cfm>0.01</cfm>
              <erp>0.15</erp>
            </suspension>
          </ode>
        </physics>
      </joint>
      <joint name='back_right_joint' type='revolute2'>
        <parent>chassis</parent>
        <child>back_right_wheel</child>
        <axis>
          <xyz>0 0 1</xyz>
          <limit>
            <lower>0</lower>
            <upper>0</upper>
          </limit>
          <use_parent_model_frame>1</use_parent_model_frame>
          <dynamics>
            <spring_reference>0</spring_reference>
            <spring_stiffness>0</spring_stiffness>
          </dynamics>
        </axis>
        <axis2>
          <xyz>0 1 0</xyz>
          <use_parent_model_frame>1</use_parent_model_frame>
          <dynamics>
            <spring_reference>0</spring_reference>
            <spring_stiffness>0</spring_stiffness>
          </dynamics>
        </axis2>
        <physics>
          <ode>
            <limit>
              <cfm>0</cfm>
              <erp>0.9</erp>
            </limit>
            <suspension>
              <cfm>0.01</cfm>
              <erp>0.15</erp>
            </suspension>
          </ode>
        </physics>
      </joint>
      <joint name='back_left_joint' type='revolute2'>
        <parent>chassis</parent>
        <child>back_left_wheel</child>
        <axis>
          <xyz>0 0 1</xyz>
          <limit>
            <lower>0</lower>
            <upper>0</upper>
          </limit>
          <use_parent_model_frame>1</use_parent_model_frame>
          <dynamics>
            <spring_reference>0</spring_reference>
            <spring_stiffness>0</spring_stiffness>
          </dynamics>
        </axis>
        <axis2>
          <xyz>0 1 0</xyz>
          <use_parent_model_frame>1</use_parent_model_frame>
          <dynamics>
            <spring_reference>0</spring_reference>
            <spring_stiffness>0</spring_stiffness>
          </dynamics>
        </axis2>
        <physics>
          <ode>
            <limit>
              <cfm>0</cfm>
              <erp>0.9</erp>
            </limit>
            <suspension>
              <cfm>0.01</cfm>
              <erp>0.15</erp>
            </suspension>
          </ode>
        </physics>
      </joint>
      <link name='front_lidar'>
        <pose frame=''>1 0 0.4 0 -0 0</pose>
        <visual name='front_lidar_visual'>
          <geometry>
            <mesh>
              <uri>model://hokuyo/meshes/hokuyo.dae</uri>
              <scale>1 1 1</scale>
            </mesh>
          </geometry>
        </visual>
        <collision name='front_lidar_collision-base'>
          <pose frame=''>0 0 -0.0145 0 -0 0</pose>
          <geometry>
            <box>
              <size>0.05 0.05 0.041</size>
            </box>
          </geometry>
          <max_contacts>10</max_contacts>
          <surface>
            <contact>
              <ode/>
            </contact>
            <bounce/>
            <friction>
              <torsional>
                <ode/>
              </torsional>
              <ode/>
            </friction>
          </surface>
        </collision>
        <collision name='front_lidar_collision-top'>
          <pose frame=''>0 0 0.0205 0 -0 0</pose>
          <geometry>
            <cylinder>
              <radius>0.021</radius>
              <length>0.029</length>
            </cylinder>
          </geometry>
          <max_contacts>10</max_contacts>
          <surface>
            <contact>
              <ode/>
            </contact>
            <bounce/>
            <friction>
              <torsional>
                <ode/>
              </torsional>
              <ode/>
            </friction>
          </surface>
        </collision>
        <sensor name='front_lidar' type='ray'>
          <pose frame=''>0.01 0 0.0175 0 -0 0</pose>
          <ray>
            <scan>
              <horizontal>
                <samples>640</samples>
                <resolution>1</resolution>
                <min_angle>-1.39626</min_angle>
                <max_angle>1.39626</max_angle>
              </horizontal>
              <vertical>
                <samples>1</samples>
                <min_angle>0</min_angle>
                <max_angle>0</max_angle>
              </vertical>
            </scan>
            <range>
              <min>0.08</min>
              <max>20</max>
              <resolution>0.01</resolution>
            </range>
          </ray>
          <plugin name='sdcFrontLidarSensor' filename='build/libsdcFrontLidarSensor.so'/>
          <always_on>1</always_on>
          <update_rate>30</update_rate>
          <visualize>1</visualize>
        </sensor>
        <self_collide>0</self_collide>
        <inertial>
          <inertia>
            <ixx>1</ixx>
            <ixy>0</ixy>
            <ixz>0</ixz>
            <iyy>1</iyy>
            <iyz>0</iyz>
            <izz>1</izz>
          </inertia>
          <mass>1</mass>
        </inertial>
        <kinematic>0</kinematic>
        <gravity>1</gravity>
      </link>
      <joint name='front_lidar_joint' type='revolute'>
        <child>front_lidar</child>
        <parent>chassis</parent>
        <axis>
          <xyz>0 0 1</xyz>
          <limit>
            <upper>0</upper>
            <lower>0</lower>
          </limit>
          <use_parent_model_frame>1</use_parent_model_frame>
          <dynamics>
            <spring_reference>0</spring_reference>
            <spring_stiffness>0</spring_stiffness>
          </dynamics>
        </axis>
      </joint>
      <link name='back_lidar'>
        <pose frame=''>-1.2 0 0.4 0 -0 0</pose>
        <visual name='back_lidar_visual'>
          <geometry>
            <mesh>
              <uri>model://hokuyo/meshes/hokuyo.dae</uri>
              <scale>1 1 1</scale>
            </mesh>
          </geometry>
        </visual>
        <collision name='back_lidar_collision-base'>
          <pose frame=''>0 0 -0.0145 0 -0 0</pose>
          <geometry>
            <box>
              <size>0.05 0.05 0.041</size>
            </box>
          </geometry>
          <max_contacts>10</max_contacts>
          <surface>
            <contact>
              <ode/>
            </contact>
            <bounce/>
            <friction>
              <torsional>
                <ode/>
              </torsional>
              <ode/>
            </friction>
          </surface>
        </collision>
        <collision name='back_lidar_collision-top'>
          <pose frame=''>0 0 0.0205 0 -0 0</pose>
          <geometry>
            <cylinder>
              <radius>0.021</radius>
              <length>0.029</length>
            </cylinder>
          </geometry>
          <max_contacts>10</max_contacts>
          <surface>
            <contact>
              <ode/>
            </contact>
            <bounce/>
            <friction>
              <torsional>
                <ode/>
              </torsional>
              <ode/>
            </friction>
          </surface>
        </collision>
        <sensor name='back_lidar' type='ray'>
          <pose frame=''>0.01 0 0.0175 3.14159 -0.004307 3.14159</pose>
          <ray>
            <scan>
              <horizontal>
                <samples>120</samples>
                <resolution>1</resolution>
                <min_angle>-1.5709</min_angle>
                <max_angle>1.5709</max_angle>
              </horizontal>
              <vertical>
                <samples>1</samples>
                <min_angle>0</min_angle>
                <max_angle>0</max_angle>
              </vertical>
            </scan>
            <range>
              <min>0.08</min>
              <max>10</max>
              <resolution>0.01</resolution>
            </range>
          </ray>
          <plugin name='sdcBackLidarSensor' filename='build/libsdcBackLidarSensor.so'/>
          <always_on>1</always_on>
          <update_rate>30</update_rate>
          <visualize>0</visualize>
        </sensor>
        <self_collide>0</self_collide>
        <inertial>
          <inertia>
            <ixx>1</ixx>
            <ixy>0</ixy>
            <ixz>0</ixz>
            <iyy>1</iyy>
            <iyz>0</iyz>
            <izz>1</izz>
          </inertia>
          <mass>1</mass>
        </inertial>
        <kinematic>0</kinematic>
        <gravity>1</gravity>
      </link>
      <joint name='back_lidar_joint' type='revolute'>
        <child>back_lidar</child>
        <parent>chassis</parent>
        <axis>
          <xyz>0 0 1</xyz>
          <limit>
            <upper>0</upper>
            <lower>0</lower>
          </limit>
          <use_parent_model_frame>1</use_parent_model_frame>
          <dynamics>
            <spring_reference>0</spring_reference>
            <spring_stiffness>0</spring_stiffness>
          </dynamics>
        </axis>
      </joint>
      <link name='top_laser'>
        <pose frame=''>0 0 1.1 0 -0 0</pose>
        <visual name='top_laser_visual'>
          <geometry>
            <mesh>
              <uri>model://hokuyo/meshes/hokuyo.dae</uri>
              <scale>1 1 1</scale>
            </mesh>
          </geometry>
        </visual>
        <collision name='top_laser_collision-base'>
          <pose frame=''>0 0 -0.0145 0 -0 0</pose>
          <geometry>
            <box>
              <size>0.05 0.05 0.041</size>
            </box>
          </geometry>
          <max_contacts>10</max_contacts>
          <surface>
            <contact>
              <ode/>
            </contact>
            <bounce/>
            <friction>
              <torsional>
                <ode/>
              </torsional>
              <ode/>
            </friction>
          </surface>
        </collision>
        <collision name='top_laser_collision-top'>
          <pose frame=''>0 0 0.0205 0 -0 0</pose>
          <geometry>
            <cylinder>
              <radius>0.021</radius>
              <length>0.029</length>
            </cylinder>
          </geometry>
          <max_contacts>10</max_contacts>
          <surface>
            <contact>
              <ode/>
            </contact>
            <bounce/>
            <friction>
              <torsional>
                <ode/>
              </torsional>
              <ode/>
            </friction>
          </surface>
        </collision>
        <sensor name='top_left_laser' type='ray'>
          <pose frame=''>0.01 0 0.0175 0 0.18 1.5708</pose>
          <ray>
            <scan>
              <horizontal>
                <samples>160</samples>
                <resolution>1</resolution>
                <min_angle>-0.7854</min_angle>
                <max_angle>0.7854</max_angle>
              </horizontal>
              <vertical>
                <samples>1</samples>
                <min_angle>0</min_angle>
                <max_angle>0</max_angle>
              </vertical>
            </scan>
            <range>
              <min>0.08</min>
              <max>20</max>
              <resolution>0.01</resolution>
            </range>
          </ray>
          <plugin name='sdcTopLidarSensor' filename='build/libsdcTopLidarSensor.so'/>
          <always_on>1</always_on>
          <update_rate>30</update_rate>
          <visualize>0</visualize>
        </sensor>
        <sensor name='top_forward_laser' type='ray'>
          <pose frame=''>0.01 0 0.0175 0 0.18 0</pose>
          <ray>
            <scan>
              <horizontal>
                <samples>160</samples>
                <resolution>1</resolution>
                <min_angle>-0.7854</min_angle>
                <max_angle>0.7854</max_angle>
              </horizontal>
              <vertical>
                <samples>1</samples>
                <min_angle>0</min_angle>
                <max_angle>0</max_angle>
              </vertical>
            </scan>
            <range>
              <min>0.08</min>
              <max>20</max>
              <resolution>0.01</resolution>
            </range>
          </ray>
          <plugin name='sdcTopLidarSensor' filename='build/libsdcTopLidarSensor.so'/>
          <always_on>1</always_on>
          <update_rate>30</update_rate>
          <visualize>0</visualize>
        </sensor>
        <sensor name='top_backward_laser' type='ray'>
          <pose frame=''>0.01 0 0.0175 -0 0.18 3.14159</pose>
          <ray>
            <scan>
              <horizontal>
                <samples>160</samples>
                <resolution>1</resolution>
                <min_angle>-0.7854</min_angle>
                <max_angle>0.7854</max_angle>
              </horizontal>
              <vertical>
                <samples>1</samples>
                <min_angle>0</min_angle>
                <max_angle>0</max_angle>
              </vertical>
            </scan>
            <range>
              <min>0.08</min>
              <max>20</max>
              <resolution>0.01</resolution>
            </range>
          </ray>
          <plugin name='sdcTopLidarSensor' filename='build/libsdcTopLidarSensor.so'/>
          <always_on>1</always_on>
          <update_rate>30</update_rate>
          <visualize>0</visualize>
        </sensor>
        <sensor name='top_right_laser' type='ray'>
          <pose frame=''>0.01 0 0.0175 0 0.18 -1.5708</pose>
          <ray>
            <scan>
              <horizontal>
                <samples>160</samples>
                <resolution>1</resolution>
                <min_angle>-0.7854</min_angle>
                <max_angle>0.7854</max_angle>
              </horizontal>
              <vertical>
                <samples>1</samples>
                <min_angle>0</min_angle>
                <max_angle>0</max_angle>
              </vertical>
            </scan>
            <range>
              <min>0.08</min>
              <max>20</max>
              <resolution>0.01</resolution>
            </range>
          </ray>
          <plugin name='sdcTopLidarSensor' filename='build/libsdcTopLidarSensor.so'/>
          <always_on>1</always_on>
          <update_rate>30</update_rate>
          <visualize>0</visualize>
        </sensor>
        <self_collide>0</self_collide>
        <inertial>
          <inertia>
            <ixx>1</ixx>
            <ixy>0</ixy>
            <ixz>0</ixz>
            <iyy>1</iyy>
            <iyz>0</iyz>
            <izz>1</izz>
          </inertia>
          <mass>1</mass>
        </inertial>
        <kinematic>0</kinematic>
        <gravity>1</gravity>
      </link>
      <joint name='top_laser_joint' type='revolute'>
        <child>top_laser</child>
        <parent>chassis</parent>
        <axis>
          <xyz>0 0 1</xyz>
          <limit>
            <upper>0</upper>
            <lower>0</lower>
          </limit>
          <use_parent_model_frame>1</use_parent_model_frame>
          <dynamics>
            <spring_reference>0</spring_reference>
            <spring_stiffness>0</spring_stiffness>
          </dynamics>
        </axis>
      </joint>
      <link name='side_right_sensors'>
        <pose frame=''>0 -0.55 0.4 0 -0 0</pose>
        <visual name='side_right_sensors_visual'>
          <geometry>
            <mesh>
              <uri>model://hokuyo/meshes/hokuyo.dae</uri>
              <scale>1 1 1</scale>
            </mesh>
          </geometry>
        </visual>
        <collision name='side_right_sensors_collision-base'>
          <pose frame=''>0 0 -0.0145 0 -0 0</pose>
          <geometry>
            <box>
              <size>0.05 0.05 0.041</size>
            </box>
          </geometry>
          <max_contacts>10</max_contacts>
          <surface>
            <contact>
              <ode/>
            </contact>
            <bounce/>
            <friction>
              <torsional>
                <ode/>
              </torsional>
              <ode/>
            </friction>
          </surface>
        </collision>
        <collision name='side_right_sensors_collision-top'>
          <pose frame=''>0 0 0.0205 0 -0 0</pose>
          <geometry>
            <cylinder>
              <radius>0.021</radius>
              <length>0.029</length>
            </cylinder>
          </geometry>
          <max_contacts>10</max_contacts>
          <surface>
            <contact>
              <ode/>
            </contact>
            <bounce/>
            <friction>
              <torsional>
                <ode/>
              </torsional>
              <ode/>
            </friction>
          </surface>
        </collision>
        <sensor name='side_right_front_laser' type='ray'>
          <pose frame=''>0.4 -0.02 0 0 0 -1.5708</pose>
          <ray>
            <scan>
              <horizontal>
                <samples>160</samples>
                <resolution>1</resolution>
                <min_angle>-1.3</min_angle>
                <max_angle>1.3</max_angle>
              </horizontal>
              <vertical>
                <samples>1</samples>
                <min_angle>0</min_angle>
                <max_angle>0</max_angle>
              </vertical>
            </scan>
            <range>
              <min>0.08</min>
              <max>1</max>
              <resolution>0.01</resolution>
            </range>
          </ray>
          <plugin name='sdcSideLidarSensor' filename='build/libsdcSideLidarSensor.so'/>
          <always_on>1</always_on>
          <update_rate>30</update_rate>
          <visualize>0</visualize>
        </sensor>
        <sensor name='side_right_back_laser' type='ray'>
          <pose frame=''>-0.6 -0.02 0 0 0 -1.5708</pose>
          <ray>
            <scan>
              <horizontal>
                <samples>160</samples>
                <resolution>1</resolution>
                <min_angle>-1.3</min_angle>
                <max_angle>1.3</max_angle>
              </horizontal>
              <vertical>
                <samples>1</samples>
                <min_angle>0</min_angle>
                <max_angle>0</max_angle>
              </vertical>
            </scan>
            <range>
              <min>0.08</min>
              <max>1</max>
              <resolution>0.01</resolution>
            </range>
          </ray>
          <plugin name='sdcSideLidarSensor' filename='build/libsdcSideLidarSensor.so'/>
          <always_on>1</always_on>
          <update_rate>30</update_rate>
          <visualize>0</visualize>
        </sensor>
        <self_collide>0</self_collide>
        <inertial>
          <inertia>
            <ixx>1</ixx>
            <ixy>0</ixy>
            <ixz>0</ixz>
            <iyy>1</iyy>
            <iyz>0</iyz>
            <izz>1</izz>
          </inertia>
          <mass>1</mass>
        </inertial>
        <kinematic>0</kinematic>
        <gravity>1</gravity>
      </link>
      <joint name='side_right_sensor_joint' type='revolute'>
        <child>side_right_sensors</child>
        <parent>chassis</parent>
        <axis>
          <xyz>0 0 1</xyz>
          <limit>
            <upper>0</upper>
            <lower>0</lower>
          </limit>
          <use_parent_model_frame>1</use_parent_model_frame>
          <dynamics>
            <spring_reference>0</spring_reference>
            <spring_stiffness>0</spring_stiffness>
          </dynamics>
        </axis>
      </joint>
      <link name='side_left_sensors'>
        <pose frame=''>0 0.55 0.4 0 -0 0</pose>
        <visual name='side_left_sensors_visual'>
          <geometry>
            <mesh>
              <uri>model://hokuyo/meshes/hokuyo.dae</uri>
              <scale>1 1 1</scale>
            </mesh>
          </geometry>
        </visual>
        <collision name='side_left_sensors_collision-base'>
          <pose frame=''>0 0 -0.0145 0 -0 0</pose>
          <geometry>
            <box>
              <size>0.05 0.05 0.041</size>
            </box>
          </geometry>
          <max_contacts>10</max_contacts>
          <surface>
            <contact>
              <ode/>
            </contact>
            <bounce/>
            <friction>
              <torsional>
                <ode/>
              </torsional>
              <ode/>
            </friction>
          </surface>
        </collision>
        <collision name='side_left_sensors_collision-top'>
          <pose frame=''>0 0 0.0205 0 -0 0</pose>
          <geometry>
            <cylinder>
              <radius>0.021</radius>
              <length>0.029</length>
            </cylinder>
          </geometry>
          <max_contacts>10</max_contacts>
          <surface>
            <contact>
              <ode/>
            </contact>
            <bounce/>
            <friction>
              <torsional>
                <ode/>
              </torsional>
              <ode/>
            </friction>
          </surface>
        </collision>
        <sensor name='side_left_front_laser' type='ray'>
          <pose frame=''>0.4 0.02 0 0 -0 1.5708</pose>
          <ray>
            <scan>
              <horizontal>
                <samples>160</samples>
                <resolution>1</resolution>
                <min_angle>-1.3</min_angle>
                <max_angle>1.3</max_angle>
              </horizontal>
              <vertical>
                <samples>1</samples>
                <min_angle>0</min_angle>
                <max_angle>0</max_angle>
              </vertical>
            </scan>
            <range>
              <min>0.08</min>
              <max>1</max>
              <resolution>0.01</resolution>
            </range>
          </ray>
          <plugin name='sdcSideLidarSensor' filename='build/libsdcSideLidarSensor.so'/>
          <always_on>1</always_on>
          <update_rate>30</update_rate>
          <visualize>0</visualize>
        </sensor>
        <sensor name='side_left_back_laser' type='ray'>
          <pose frame=''>-0.6 0.02 0 0 -0 1.5708</pose>
          <ray>
            <scan>
              <horizontal>
                <samples>160</samples>
                <resolution>1</resolution>
                <min_angle>-1.3</min_angle>
                <max_angle>1.3</max_angle>
              </horizontal>
              <vertical>
                <samples>1</samples>
                <min_angle>0</min_angle>
                <max_angle>0</max_angle>
              </vertical>
            </scan>
            <range>
              <min>0.08</min>
              <max>1</max>
              <resolution>0.01</resolution>
            </range>
          </ray>
          <plugin name='sdcSideLidarSensor' filename='build/libsdcSideLidarSensor.so'/>
          <always_on>1</always_on>
          <update_rate>30</update_rate>
          <visualize>0</visualize>
        </sensor>
        <self_collide>0</self_collide>
        <inertial>
          <inertia>
            <ixx>1</ixx>
            <ixy>0</ixy>
            <ixz>0</ixz>
            <iyy>1</iyy>
            <iyz>0</iyz>
            <izz>1</izz>
          </inertia>
          <mass>1</mass>
        </inertial>
        <kinematic>0</kinematic>
        <gravity>1</gravity>
      </link>
      <joint name='side_left_sensor_joint' type='revolute'>
        <child>side_left_sensors</child>
        <parent>chassis</parent>
        <axis>
          <xyz>0 0 1</xyz>
          <limit>
            <upper>0</upper>
            <lower>0</lower>
          </limit>
          <use_parent_model_frame>1</use_parent_model_frame>
          <dynamics>
            <spring_reference>0</spring_reference>
            <spring_stiffness>0</spring_stiffness>
          </dynamics>
        </axis>
      </joint>
      <link name='camera::link'>
        <pose frame=''>0.65 0 0.85 0 0.008 0</pose>
        <self_collide>0</self_collide>
        <kinematic>0</kinematic>
        <sensor name='camera' type='multicamera'>
          <always_on>1</always_on>
          <update_rate>24</update_rate>
          <visualize>0</visualize>
          <topic>comps_car_camera</topic>
          <camera name='left'>
            <pose frame=''>0 0 0 0 -0 0</pose>
            <horizontal_fov>1.047</horizontal_fov>
            <image>
              <width>640</width>
              <height>480</height>
            </image>
            <clip>
              <near>0.1</near>
              <far>150</far>
            </clip>
            <save enabled='0'>
              <path>/Users/selfcar/Desktop/Self-Driving-Comps/comps_camera_recordings/</path>
            </save>
          </camera>
          <plugin name='sdcCameraSensor' filename='build/libsdcCameraSensor.so'/>
        </sensor>
        <visual name='visual'>
          <geometry>
            <box>
              <size>0.1 0.1 0.1</size>
            </box>
          </geometry>
          <material>
            <shader type='pixel'/>
          </material>
          <pose frame=''>0 0 0 0 -0 0</pose>
          <cast_shadows>1</cast_shadows>
          <transparency>0</transparency>
        </visual>
        <inertial>
          <inertia>
            <ixx>1</ixx>
            <ixy>0</ixy>
            <ixz>0</ixz>
            <iyy>1</iyy>
            <iyz>0</iyz>
            <izz>1</izz>
          </inertia>
          <mass>1</mass>
        </inertial>
        <gravity>1</gravity>
      </link>
      <joint name='camera' type='revolute'>
        <parent>chassis</parent>
        <child>camera::link</child>
        <axis>
          <xyz>0 0 1</xyz>
          <use_parent_model_frame>0</use_parent_model_frame>
          <limit>
            <lower>0</lower>
            <upper>0</upper>
            <effort>-1</effort>
            <velocity>-1</velocity>
          </limit>
          <dynamics>
            <spring_reference>0</spring_reference>
            <spring_stiffness>0</spring_stiffness>
            <damping>0</damping>
            <friction>0</friction>
          </dynamics>
          <use_parent_model_frame>1</use_parent_model_frame>
        </axis>
        <physics>
          <ode>
            <limit>
              <cfm>0</cfm>
              <erp>0.2</erp>
            </limit>
            <suspension>
              <cfm>0</cfm>
              <erp>0.2</erp>
            </suspension>
          </ode>
        </physics>
      </joint>
      <link name='gps'>
        <pose frame=''>0 0 1 0 -0 0</pose>
        <visual name='visual'>
          <geometry>
            <mesh>
              <uri>model://hokuyo/meshes/hokuyo.dae</uri>
              <scale>1 1 1</scale>
            </mesh>
          </geometry>
        </visual>
        <collision name='gps_collision-base'>
          <pose frame=''>0 0 -0.0145 0 -0 0</pose>
          <geometry>
            <box>
              <size>0.05 0.05 0.041</size>
            </box>
          </geometry>
          <max_contacts>10</max_contacts>
          <surface>
            <contact>
              <ode/>
            </contact>
            <bounce/>
            <friction>
              <torsional>
                <ode/>
              </torsional>
              <ode/>
            </friction>
          </surface>
        </collision>
        <collision name='gps_collision-top'>
          <pose frame=''>0 0 0.0205 0 -0 0</pose>
          <geometry>
            <cylinder>
              <radius>0.021</radius>
              <length>0.029</length>
            </cylinder>
          </geometry>
          <max_contacts>10</max_contacts>
          <surface>
            <contact>
              <ode/>
            </contact>
            <bounce/>
            <friction>
              <torsional>
                <ode/>
              </torsional>
              <ode/>
            </friction>
          </surface>
        </collision>
        <sensor name='gps' type='gps'>
          <pose frame=''>0 0 0 0 -0 0</pose>
          <always_on>1</always_on>
          <update_rate>30</update_rate>
        </sensor>
        <self_collide>0</self_collide>
        <inertial>
          <inertia>
            <ixx>1</ixx>
            <ixy>0</ixy>
            <ixz>0</ixz>
            <iyy>1</iyy>
            <iyz>0</iyz>
            <izz>1</izz>
          </inertia>
          <mass>1</mass>
        </inertial>
        <kinematic>0</kinematic>
        <gravity>1</gravity>
      </link>
      <joint name='gps_joint' type='revolute'>
        <child>gps</child>
        <parent>chassis</parent>
        <axis>
          <xyz>0 0 1</xyz>
          <limit>
            <upper>0</upper>
            <lower>0</lower>
          </limit>
          <use_parent_model_frame>1</use_parent_model_frame>
          <dynamics>
            <spring_reference>0</spring_reference>
            <spring_stiffness>0</spring_stiffness>
          </dynamics>
        </axis>
      </joint>
      <plugin name='sdcCar' filename='build/libsdcCar.so'>
        <front_left>front_left_joint</front_left>
        <front_right>front_right_joint</front_right>
        <back_left>back_left_joint</back_left>
        <back_right>back_right_joint</back_right>
        <chassis>chassis</chassis>
        <camera>camera::link</camera>
        <frontLidar>front_lidar</frontLidar>
        <wheel_radius>0.21</wheel_radius>
        <front_power>10</front_power>
        <rear_power>10</rear_power>
        <tire_angle_range>0.5</tire_angle_range>
        <max_speed>10</max_speed>
        <aero_load>1.0</aero_load>
      </plugin>
      <plugin name='sdcGpsSensor' filename='build/libsdcGpsSensor.so'>
        <gps>gps</gps>
      </plugin>
      <pose frame=''>-12 -0.5 0 0 -0 0</pose>
    </model>
    <model name='ground_plane'>
      <static>1</static>
      <link name='link'>
        <pose frame=''>50 100 0 0 -0 0</pose>
        <collision name='collision'>
          <geometry>
            <plane>
              <normal>0 0 1</normal>
              <size>100 20</size>
            </plane>
          </geometry>
          <max_contacts>10</max_contacts>
          <surface>
            <contact>
              <ode/>
            </contact>
            <bounce/>
            <friction>
              <torsional>
                <ode/>
              </torsional>
              <ode/>
            </friction>
          </surface>
        </collision>
        <visual name='visual'>
          <cast_shadows>0</cast_shadows>
          <geometry>
            <plane>
              <normal>0 0 1</normal>
              <size>100 20</size>
            </plane>
          </geometry>
          <material>
            <script>
              <uri>__default__</uri>
              <name>__default__</name>
            </script>
          </material>
        </visual>
        <self_collide>0</self_collide>
        <kinematic>0</kinematic>
        <gravity>1</gravity>
      </link>
    </model>
    <model name='road_2_0_1'>
      <pose frame=''>25 1.02 -0.05 0 -0 0</pose>
      <static>1</static>
      <link name='link'>
        <collision name='collision'>
          <geometry>
            <box>
              <size>75 6.54 0.0001</size>
            </box>
          </geometry>
          <max_contacts>10</max_contacts>
          <surface>
            <contact>
              <ode/>
            </contact>
            <bounce/>
            <friction>
              <torsional>
                <ode/>
              </torsional>
              <ode/>
            </friction>
          </surface>
        </collision>
        <visual name='visual'>
          <cast_shadows>0</cast_shadows>
          <geometry>
            <box>
              <size>75 6.54 0.0001</size>
            </box>
          </geometry>
          <material>
            <script>
              <uri>models/newstraight/materials/scripts</uri>
              <uri>models/newstraight/materials/textures</uri>
              <name>newstraight</name>
            </script>
          </material>
        </visual>
        <self_collide>0</self_collide>
        <kinematic>0</kinematic>
        <gravity>1</gravity>
      </link>
    </model>
    <model name='road_2_0_2'>
      <pose frame=''>139.5 -47.4 -0.05 0 0 -0.78</pose>
      <static>1</static>
      <link name='link'>
        <collision name='collision'>
          <geometry>
            <box>
              <size>75 6.54 0.0001</size>
            </box>
          </geometry>
          <max_contacts>10</max_contacts>
          <surface>
            <contact>
              <ode/>
            </contact>
            <bounce/>
            <friction>
              <torsional>
                <ode/>
              </torsional>
              <ode/>
            </friction>
          </surface>
        </collision>
        <visual name='visual'>
          <cast_shadows>0</cast_shadows>
          <geometry>
            <box>
              <size>75 6.54 0.0001</size>
            </box>
          </geometry>
          <material>
            <script>
              <uri>models/newstraight/materials/scripts</uri>
              <uri>models/newstraight/materials/textures</uri>
              <name>newstraight</name>
            </script>
          </material>
        </visual>
        <self_collide>0</self_collide>
        <kinematic>0</kinematic>
        <gravity>1</gravity>
      </link>
    </model>
    <physics name='default_physics' default='0' type='ode'>
      <max_step_size>0.001</max_step_size>
      <real_time_factor>1</real_time_factor>
      <real_time_update_rate>1000</real_time_update_rate>
      <gravity>0 0 -9.8</gravity>
      <magnetic_field>6e-06 2.3e-05 -4.2e-05</magnetic_field>
    </physics>
    <scene>
      <ambient>0.4 0.4 0.4 1</ambient>
      <background>0.7 0.7 0.7 1</background>
      <shadows>1</shadows>
    </scene>
    <spherical_coordinates>
      <surface_model>EARTH_WGS84</surface_model>
      <latitude_deg>0</latitude_deg>
      <longitude_deg>0</longitude_deg>
      <elevation>0</elevation>
      <heading_deg>0</heading_deg>
    </spherical_coordinates>
    <model name='road_2_0_2_clone'>
      <pose frame=''>191.652 -96.019 -0.05 0 0 -0.78</pose>
      <static>1</static>
      <link name='link'>
        <collision name='collision'>
          <geometry>
            <box>
              <size>75 6.54 0.0001</size>
            </box>
          </geometry>
          <max_contacts>10</max_contacts>
          <surface>
            <contact>
              <ode/>
            </contact>
            <bounce/>
            <friction>
              <torsional>
                <ode/>
              </torsional>
              <ode/>
            </friction>
          </surface>
        </collision>
        <visual name='visual'>
          <cast_shadows>0</cast_shadows>
          <geometry>
            <box>
              <size>75 6.54 0.0001</size>
            </box>
          </geometry>
          <material>
            <script>
              <uri>models/newstraight/materials/scripts</uri>
              <uri>models/newstraight/materials/textures</uri>
              <name>newstraight</name>
            </script>
          </material>
        </visual>
        <self_collide>0</self_collide>
        <kinematic>0</kinematic>
        <gravity>1</gravity>
      </link>
    </model>
    <model name='curved_road_clone'>
      <static>1</static>
      <link name='link'>
        <collision name='collision'>
          <geometry>
            <mesh>
              <uri>models/newcurve/curve8k.dae</uri>
              <scale>1 1 1</scale>
            </mesh>
          </geometry>
          <max_contacts>10</max_contacts>
          <surface>
            <contact>
              <ode/>
            </contact>
            <bounce/>
            <friction>
              <torsional>
                <ode/>
              </torsional>
              <ode/>
            </friction>
          </surface>
        </collision>
        <visual name='visual'>
          <cast_shadows>0</cast_shadows>
          <geometry>
            <mesh>
              <uri>models/newcurve/curve8k.dae</uri>
              <scale>1 1 1</scale>
            </mesh>
          </geometry>
          <material>
            <script>
              <uri>models/newcurve/materials/scripts</uri>
              <uri>models/newcurve/materials/textures</uri>
              <name>newcurve</name>
            </script>
          </material>
        </visual>
        <self_collide>0</self_collide>
        <kinematic>0</kinematic>
        <gravity>1</gravity>
      </link>
      <pose frame=''>151.942 -44.8313 -0.13 0 0 -1.575</pose>
    </model>
    <model name='road_2_0_2_clone_clone'>
      <pose frame=''>309.611 -152.455 -0.05 0 0 -0.78</pose>
      <static>1</static>
      <link name='link'>
        <collision name='collision'>
          <geometry>
            <box>
              <size>74.9999 6.54 0.0001</size>
            </box>
          </geometry>
          <max_contacts>10</max_contacts>
          <surface>
            <contact>
              <ode/>
            </contact>
            <bounce/>
            <friction>
              <torsional>
                <ode/>
              </torsional>
              <ode/>
            </friction>
          </surface>
        </collision>
        <visual name='visual'>
          <cast_shadows>0</cast_shadows>
          <geometry>
            <box>
              <size>74.9999 6.54 0.0001</size>
            </box>
          </geometry>
          <material>
            <script>
              <uri>models/newstraight/materials/scripts</uri>
              <uri>models/newstraight/materials/textures</uri>
              <name>newstraight</name>
            </script>
          </material>
        </visual>
        <self_collide>0</self_collide>
        <kinematic>0</kinematic>
        <gravity>1</gravity>
      </link>
    </model>
    <state world_name='default'>
      <sim_time>0 0</sim_time>
      <real_time>0 0</real_time>
      <wall_time>1486689215 487904000</wall_time>
      <iterations>0</iterations>
      <model name='car'>
        <pose frame=''>-12 -0.5 -1e-05 0 -3e-06 0</pose>
        <link name='back_left_wheel'>
          <pose frame=''>-12.87 0 0.29999 1.00853 1.57079 2.57932</pose>
          <velocity>0.00016 -1.5e-05 -0.009828 2e-06 0.01 6e-06</velocity>
          <acceleration>0.159904 -0.015301 -9.82788 -3.13911 -0.575222 -3.13603</acceleration>
          <wrench>1.59904 -0.153012 -98.2788 0 -0 0</wrench>
        </link>
        <link name='back_lidar'>
          <pose frame=''>-13.2 -0.5 0.399986 0 -3e-06 0</pose>
          <velocity>-0.000156 -2.8e-05 -0.013664 1e-06 -0.003218 2.8e-05</velocity>
          <acceleration>-0.15606 -0.028442 -13.664 -3.14014 0.076058 -3.11402</acceleration>
          <wrench>-0.15606 -0.028442 -13.664 0 -0 0</wrench>
        </link>
        <link name='back_right_wheel'>
          <pose frame=''>-12.87 -1 0.29999 -1.0049 1.57078 -2.57569</pose>
          <velocity>0.000154 1.2e-05 -0.009828 3e-06 0.01 -2.5e-05</velocity>
          <acceleration>0.154003 0.012055 -9.8279 -3.13838 -0.575222 3.11614</acceleration>
          <wrench>1.54003 0.120553 -98.279 0 -0 0</wrench>
        </link>
        <link name='camera::link'>
          <pose frame=''>-11.35 -0.5 0.849992 0 0.007997 0</pose>
          <velocity>-0.001597 1.1e-05 -0.007735 -0 -0.003191 1.6e-05</velocity>
          <acceleration>-1.59669 0.010865 -7.73466 -3.14159 0.049257 -3.12605</acceleration>
          <wrench>-1.59669 0.010865 -7.73466 0 -0 0</wrench>
        </link>
        <link name='chassis'>
          <pose frame=''>-12 -0.5 0.34999 0 -3e-06 0</pose>
          <velocity>4e-06 2e-06 -0.009813 2e-06 -0.00322 1e-05</velocity>
          <acceleration>0.003804 0.002179 -9.81308 -3.13914 0.078513 -3.13182</acceleration>
          <wrench>0.380439 0.217943 -981.308 0 -0 0</wrench>
        </link>
        <link name='front_left_wheel'>
          <pose frame=''>-11.2 0 0.29999 1.0071 1.57078 2.57789</pose>
          <velocity>0.000163 -3e-06 -0.009775 3e-06 0.01 8e-06</velocity>
          <acceleration>0.162943 -0.002789 -9.77459 -3.1387 -0.575222 -3.13318</acceleration>
          <wrench>1.62943 -0.02789 -97.746 0 -0 0</wrench>
        </link>
        <link name='front_lidar'>
          <pose frame=''>-11 -0.5 0.399993 0 -3e-06 0</pose>
          <velocity>-0.000157 3e-05 -0.006591 1e-06 -0.003222 3e-05</velocity>
          <acceleration>-0.157078 0.030429 -6.59085 -3.1401 0.080892 -3.11187</acceleration>
          <wrench>-0.157078 0.030429 -6.59085 0 -0 0</wrench>
        </link>
        <link name='front_right_wheel'>
          <pose frame=''>-11.2 -1 0.29999 -1.0052 1.57078 -2.57599</pose>
          <velocity>0.000154 -1.8e-05 -0.009775 3e-06 0.01 -1.8e-05</velocity>
          <acceleration>0.15446 -0.017596 -9.77463 -3.13868 -0.575222 3.12324</acceleration>
          <wrench>1.5446 -0.175962 -97.7463 0 -0 0</wrench>
        </link>
        <link name='gps'>
          <pose frame=''>-12 -0.5 0.99999 0 -3e-06 0</pose>
          <velocity>-0.002085 1e-06 -0.009813 1e-06 -0.003205 1.3e-05</velocity>
          <acceleration>-2.08523 0.000685 -9.81298 -3.14066 0.063901 -3.12812</acceleration>
          <wrench>-2.08523 0.000685 -9.81298 0 -0 0</wrench>
        </link>
        <link name='side_left_sensors'>
          <pose frame=''>-12 0.05 0.39999 0 -3e-06 0</pose>
          <velocity>-0.000164 2e-06 -0.009813 -0 -0.003187 1.7e-05</velocity>
          <acceleration>-0.164354 0.001761 -9.81308 3.14148 0.045196 -3.12428</acceleration>
          <wrench>-0.164354 0.001761 -9.81308 0 -0 0</wrench>
        </link>
        <link name='side_right_sensors'>
          <pose frame=''>-12 -1.05 0.39999 0 -3e-06 0</pose>
          <velocity>-0.000145 2e-06 -0.009813 0 -0.003187 2e-05</velocity>
          <acceleration>-0.145415 0.001756 -9.81297 -3.14158 0.045902 -3.12201</acceleration>
          <wrench>-0.145415 0.001756 -9.81297 0 -0 0</wrench>
        </link>
        <link name='top_laser'>
          <pose frame=''>-12 -0.5 1.09999 0 -3e-06 0</pose>
          <velocity>-0.002389 1e-06 -0.009813 1e-06 -0.003197 2.2e-05</velocity>
          <acceleration>-2.38871 0.001313 -9.81304 -3.14058 0.055566 -3.12003</acceleration>
          <wrench>-2.38871 0.001313 -9.81304 0 -0 0</wrench>
        </link>
      </model>
      <model name='curved_road'>
        <pose frame=''>91.1223 -5.1822 -0.13 0 0 -1.575</pose>
        <link name='link'>
          <pose frame=''>91.1223 -5.1822 -0.13 0 0 -1.575</pose>
          <velocity>0 0 0 0 -0 0</velocity>
          <acceleration>0 0 0 0 -0 0</acceleration>
          <wrench>0 0 0 0 -0 0</wrench>
        </link>
      </model>
      <model name='curved_road_clone'>
        <pose frame=''>243.27 -138.224 -0.13 0 -0 1.56957</pose>
        <link name='link'>
          <pose frame=''>243.27 -138.224 -0.13 0 -0 1.56957</pose>
          <velocity>0 0 0 0 -0 0</velocity>
          <acceleration>0 0 0 0 -0 0</acceleration>
          <wrench>0 0 0 0 -0 0</wrench>
        </link>
      </model>
      <model name='ground_plane'>
        <pose frame=''>0 0 0 0 -0 0</pose>
        <link name='link'>
          <pose frame=''>50 100 0 0 -0 0</pose>
          <velocity>0 0 0 0 -0 0</velocity>
          <acceleration>0 0 0 0 -0 0</acceleration>
          <wrench>0 0 0 0 -0 0</wrench>
        </link>
      </model>
      <model name='road_2_0_1'>
        <pose frame=''>25 1.02 -0.05 0 -0 0</pose>
        <link name='link'>
          <pose frame=''>25 1.02 -0.05 0 -0 0</pose>
          <velocity>0 0 0 0 -0 0</velocity>
          <acceleration>0 0 0 0 -0 0</acceleration>
          <wrench>0 0 0 0 -0 0</wrench>
        </link>
      </model>
      <model name='road_2_0_2'>
        <pose frame=''>140.495 -45.3521 -0.05 0 0 -0.78</pose>
        <link name='link'>
          <pose frame=''>140.495 -45.3521 -0.05 0 0 -0.78</pose>
          <velocity>0 0 0 0 -0 0</velocity>
          <acceleration>0 0 0 0 -0 0</acceleration>
          <wrench>0 0 0 0 -0 0</wrench>
        </link>
      </model>
      <model name='road_2_0_2_clone'>
        <pose frame=''>193.77 -98.066 -0.05 0 0 -0.78</pose>
        <link name='link'>
          <pose frame=''>193.77 -98.066 -0.05 0 0 -0.78</pose>
          <velocity>0 0 0 0 -0 0</velocity>
          <acceleration>0 0 0 0 -0 0</acceleration>
          <wrench>0 0 0 0 -0 0</wrench>
        </link>
      </model>
      <model name='road_2_0_2_clone_clone'>
        <pose frame=''>420.906 -143.789 -0.05 0 -0 0.004053</pose>
        <link name='link'>
          <pose frame=''>420.906 -143.789 -0.05 0 -0 0.004053</pose>
          <velocity>0 0 0 0 -0 0</velocity>
          <acceleration>0 0 0 0 -0 0</acceleration>
          <wrench>0 0 0 0 -0 0</wrench>
        </link>
      </model>
      <model name='road_2_0_2_clone_clone_0'>
        <pose frame=''>309.524 -144.438 -0.05 0 0 -0.001554</pose>
        <link name='link'>
          <pose frame=''>309.524 -144.438 -0.05 0 0 -0.001554</pose>
          <velocity>0 0 0 0 -0 0</velocity>
          <acceleration>0 0 0 0 -0 0</acceleration>
          <wrench>0 0 0 0 -0 0</wrench>
        </link>
      </model>
    </state>
    <audio>
      <device>default</device>
    </audio>
    <model name='road_2_0_2_clone_clone_0'>
      <pose frame=''>299 -139 -0.05 0 0 -0.78</pose>
      <static>1</static>
      <link name='link'>
        <collision name='collision'>
          <geometry>
            <box>
              <size>75 6.54 0.0001</size>
            </box>
          </geometry>
          <max_contacts>10</max_contacts>
          <surface>
            <contact>
              <ode/>
            </contact>
            <bounce/>
            <friction>
              <torsional>
                <ode/>
              </torsional>
              <ode/>
            </friction>
          </surface>
        </collision>
        <visual name='visual'>
          <cast_shadows>0</cast_shadows>
          <geometry>
            <box>
              <size>75 6.54 0.0001</size>
            </box>
          </geometry>
          <material>
            <script>
              <uri>models/newstraight/materials/scripts</uri>
              <uri>models/newstraight/materials/textures</uri>
              <name>newstraight</name>
            </script>
          </material>
        </visual>
        <self_collide>0</self_collide>
        <kinematic>0</kinematic>
        <gravity>1</gravity>
      </link>
    </model>
  </world>
</sdf>
