<sdf version='1.5'>
  <world name='default'>
    <gui fullscreen='0'>
      <camera name='user_camera'>
        <pose frame=''>-27.7424 -32.7472 16.6592 0 0.3 0.78</pose>
        <view_controller>orbit</view_controller>
        <projection_type>perspective</projection_type>
      </camera>
    </gui>
    <light name='sun' type='directional'>
      <cast_shadows>1</cast_shadows>
      <pose frame=''>0 0 10 0 -0 0</pose>
      <diffuse>0.8 0.8 0.8 1</diffuse>
      <specular>0.2 0.2 0.2 1</specular>
      <attenuation>
        <range>1000</range>
        <constant>0.9</constant>
        <linear>0.01</linear>
        <quadratic>0.001</quadratic>
      </attenuation>
      <direction>-0.5 0.1 -0.9</direction>
    </light>
    <model name='car'>
      <link name='chassis'>
        <pose frame=''>0 0 0.35 0 -0 0</pose>
        <inertial>
          <mass>100</mass>
          <inertia>
            <ixx>1</ixx>
            <ixy>0</ixy>
            <ixz>0</ixz>
            <iyy>1</iyy>
            <iyz>0</iyz>
            <izz>1</izz>
          </inertia>
        </inertial>
        <collision name='chassis_collision'>
          <geometry>
            <box>
              <size>2 0.8 0.2</size>
            </box>
          </geometry>
          <max_contacts>10</max_contacts>
          <surface>
            <contact>
              <ode/>
            </contact>
            <bounce/>
            <friction>
              <ode/>
            </friction>
          </surface>
        </collision>
        <visual name='chassis_visual'>
          <pose frame=''>0.1 0 -0.2 0 -0 1.57079</pose>
          <geometry>
            <mesh>
              <uri>models/sdcCar/cooper-test.dae</uri>
            </mesh>
          </geometry>
        </visual>
        <self_collide>0</self_collide>
        <kinematic>0</kinematic>
        <gravity>1</gravity>
      </link>
      <link name='front_left_wheel'>
        <inertial>
          <mass>10</mass>
          <inertia>
            <ixx>1</ixx>
            <ixy>0</ixy>
            <ixz>0</ixz>
            <iyy>1</iyy>
            <iyz>0</iyz>
            <izz>1</izz>
          </inertia>
        </inertial>
        <pose frame=''>0.8 0.5 0.3 0 1.57079 1.57079</pose>
        <collision name='front_left_wheel_collision'>
          <geometry>
            <cylinder>
              <radius>0.21</radius>
              <length>0.1</length>
            </cylinder>
          </geometry>
          <max_contacts>10</max_contacts>
          <surface>
            <contact>
              <ode/>
            </contact>
            <bounce/>
            <friction>
              <ode/>
            </friction>
          </surface>
        </collision>
        <visual name='front_left_wheel_visual'>
          <geometry>
            <mesh>
              <uri>models/sdcCar/wheel.stl</uri>
            </mesh>
          </geometry>
          <material>
            <script>
              <uri>file://media/materials/scripts/gazebo.material</uri>
              <name>Gazebo/Black</name>
            </script>
          </material>
        </visual>
        <self_collide>0</self_collide>
        <kinematic>0</kinematic>
        <gravity>1</gravity>
      </link>
      <link name='front_right_wheel'>
        <pose frame=''>0.8 -0.5 0.3 0 1.57079 -1.57079</pose>
        <inertial>
          <mass>10</mass>
          <inertia>
            <ixx>1</ixx>
            <ixy>0</ixy>
            <ixz>0</ixz>
            <iyy>1</iyy>
            <iyz>0</iyz>
            <izz>1</izz>
          </inertia>
        </inertial>
        <collision name='front_right_wheel_collision'>
          <geometry>
            <cylinder>
              <radius>0.21</radius>
              <length>0.1</length>
            </cylinder>
          </geometry>
          <max_contacts>10</max_contacts>
          <surface>
            <contact>
              <ode/>
            </contact>
            <bounce/>
            <friction>
              <ode/>
            </friction>
          </surface>
        </collision>
        <visual name='front_right_wheel_visual'>
          <geometry>
            <mesh>
              <uri>models/sdcCar/wheel.stl</uri>
            </mesh>
          </geometry>
          <material>
            <script>
              <uri>file://media/materials/scripts/gazebo.material</uri>
              <name>Gazebo/Black</name>
            </script>
          </material>
        </visual>
        <self_collide>0</self_collide>
        <kinematic>0</kinematic>
        <gravity>1</gravity>
      </link>
      <link name='back_right_wheel'>
        <pose frame=''>-0.87 -0.5 0.3 0 1.57079 -1.57079</pose>
        <inertial>
          <mass>10</mass>
          <inertia>
            <ixx>1</ixx>
            <ixy>0</ixy>
            <ixz>0</ixz>
            <iyy>1</iyy>
            <iyz>0</iyz>
            <izz>1</izz>
          </inertia>
        </inertial>
        <collision name='back_right_wheel_collision'>
          <geometry>
            <cylinder>
              <radius>0.21</radius>
              <length>0.1</length>
            </cylinder>
          </geometry>
          <max_contacts>10</max_contacts>
          <surface>
            <contact>
              <ode/>
            </contact>
            <bounce/>
            <friction>
              <ode/>
            </friction>
          </surface>
        </collision>
        <visual name='back_right_wheel_visual'>
          <geometry>
            <mesh>
              <uri>models/sdcCar/wheel.stl</uri>
            </mesh>
          </geometry>
          <material>
            <script>
              <uri>file://media/materials/scripts/gazebo.material</uri>
              <name>Gazebo/Black</name>
            </script>
          </material>
        </visual>
        <self_collide>0</self_collide>
        <kinematic>0</kinematic>
        <gravity>1</gravity>
      </link>
      <link name='back_left_wheel'>
        <pose frame=''>-0.87 0.5 0.3 0 1.57079 1.57079</pose>
        <inertial>
          <mass>10</mass>
          <inertia>
            <ixx>1</ixx>
            <ixy>0</ixy>
            <ixz>0</ixz>
            <iyy>1</iyy>
            <iyz>0</iyz>
            <izz>1</izz>
          </inertia>
        </inertial>
        <collision name='back_left_wheel_collision'>
          <geometry>
            <cylinder>
              <radius>0.21</radius>
              <length>0.1</length>
            </cylinder>
          </geometry>
          <max_contacts>10</max_contacts>
          <surface>
            <contact>
              <ode/>
            </contact>
            <bounce/>
            <friction>
              <ode/>
            </friction>
          </surface>
        </collision>
        <visual name='back_left_wheel_visual'>
          <geometry>
            <mesh>
              <uri>models/sdcCar/wheel.stl</uri>
            </mesh>
          </geometry>
          <material>
            <script>
              <uri>file://media/materials/scripts/gazebo.material</uri>
              <name>Gazebo/Black</name>
            </script>
          </material>
        </visual>
        <self_collide>0</self_collide>
        <kinematic>0</kinematic>
        <gravity>1</gravity>
      </link>
      <joint name='front_left_joint' type='revolute2'>
        <parent>chassis</parent>
        <child>front_left_wheel</child>
        <axis>
          <xyz>0 0 1</xyz>
          <limit>
            <lower>0</lower>
            <upper>0</upper>
          </limit>
          <use_parent_model_frame>1</use_parent_model_frame>
          <dynamics>
            <spring_reference>0</spring_reference>
            <spring_stiffness>0</spring_stiffness>
          </dynamics>
        </axis>
        <axis2>
          <xyz>0 1 0</xyz>
          <use_parent_model_frame>1</use_parent_model_frame>
          <dynamics>
            <spring_reference>0</spring_reference>
            <spring_stiffness>0</spring_stiffness>
          </dynamics>
        </axis2>
        <physics>
          <ode>
            <limit>
              <cfm>0</cfm>
              <erp>0.9</erp>
            </limit>
            <suspension>
              <cfm>0.01</cfm>
              <erp>0.15</erp>
            </suspension>
          </ode>
        </physics>
      </joint>
      <joint name='front_right_joint' type='revolute2'>
        <parent>chassis</parent>
        <child>front_right_wheel</child>
        <axis>
          <xyz>0 0 1</xyz>
          <limit>
            <lower>0</lower>
            <upper>0</upper>
          </limit>
          <use_parent_model_frame>1</use_parent_model_frame>
          <dynamics>
            <spring_reference>0</spring_reference>
            <spring_stiffness>0</spring_stiffness>
          </dynamics>
        </axis>
        <axis2>
          <xyz>0 1 0</xyz>
          <use_parent_model_frame>1</use_parent_model_frame>
          <dynamics>
            <spring_reference>0</spring_reference>
            <spring_stiffness>0</spring_stiffness>
          </dynamics>
        </axis2>
        <physics>
          <ode>
            <limit>
              <cfm>0</cfm>
              <erp>0.9</erp>
            </limit>
            <suspension>
              <cfm>0.01</cfm>
              <erp>0.15</erp>
            </suspension>
          </ode>
        </physics>
      </joint>
      <joint name='back_right_joint' type='revolute2'>
        <parent>chassis</parent>
        <child>back_right_wheel</child>
        <axis>
          <xyz>0 0 1</xyz>
          <limit>
            <lower>0</lower>
            <upper>0</upper>
          </limit>
          <use_parent_model_frame>1</use_parent_model_frame>
          <dynamics>
            <spring_reference>0</spring_reference>
            <spring_stiffness>0</spring_stiffness>
          </dynamics>
        </axis>
        <axis2>
          <xyz>0 1 0</xyz>
          <use_parent_model_frame>1</use_parent_model_frame>
          <dynamics>
            <spring_reference>0</spring_reference>
            <spring_stiffness>0</spring_stiffness>
          </dynamics>
        </axis2>
        <physics>
          <ode>
            <limit>
              <cfm>0</cfm>
              <erp>0.9</erp>
            </limit>
            <suspension>
              <cfm>0.01</cfm>
              <erp>0.15</erp>
            </suspension>
          </ode>
        </physics>
      </joint>
      <joint name='back_left_joint' type='revolute2'>
        <parent>chassis</parent>
        <child>back_left_wheel</child>
        <axis>
          <xyz>0 0 1</xyz>
          <limit>
            <lower>0</lower>
            <upper>0</upper>
          </limit>
          <use_parent_model_frame>1</use_parent_model_frame>
          <dynamics>
            <spring_reference>0</spring_reference>
            <spring_stiffness>0</spring_stiffness>
          </dynamics>
        </axis>
        <axis2>
          <xyz>0 1 0</xyz>
          <use_parent_model_frame>1</use_parent_model_frame>
          <dynamics>
            <spring_reference>0</spring_reference>
            <spring_stiffness>0</spring_stiffness>
          </dynamics>
        </axis2>
        <physics>
          <ode>
            <limit>
              <cfm>0</cfm>
              <erp>0.9</erp>
            </limit>
            <suspension>
              <cfm>0.01</cfm>
              <erp>0.15</erp>
            </suspension>
          </ode>
        </physics>
      </joint>
      <link name='front_lidar'>
        <pose frame=''>1 0 0.4 0 -0 0</pose>
        <visual name='front_lidar_visual'>
          <geometry>
            <mesh>
              <uri>model://hokuyo/meshes/hokuyo.dae</uri>
            </mesh>
          </geometry>
        </visual>
        <collision name='front_lidar_collision-base'>
          <pose frame=''>0 0 -0.0145 0 -0 0</pose>
          <geometry>
            <box>
              <size>0.05 0.05 0.041</size>
            </box>
          </geometry>
          <max_contacts>10</max_contacts>
          <surface>
            <contact>
              <ode/>
            </contact>
            <bounce/>
            <friction>
              <ode/>
            </friction>
          </surface>
        </collision>
        <collision name='front_lidar_collision-top'>
          <pose frame=''>0 0 0.0205 0 -0 0</pose>
          <geometry>
            <cylinder>
              <radius>0.021</radius>
              <length>0.029</length>
            </cylinder>
          </geometry>
          <max_contacts>10</max_contacts>
          <surface>
            <contact>
              <ode/>
            </contact>
            <bounce/>
            <friction>
              <ode/>
            </friction>
          </surface>
        </collision>
        <sensor name='front_lidar' type='ray'>
          <pose frame=''>0.01 0 0.0175 0 -0 0</pose>
          <ray>
            <scan>
              <horizontal>
                <samples>640</samples>
                <resolution>1</resolution>
                <min_angle>-1</min_angle>
                <max_angle>1</max_angle>
              </horizontal>
            </scan>
            <range>
              <min>0.08</min>
              <max>200</max>
              <resolution>0.01</resolution>
            </range>
          </ray>
          <plugin name='sdcFrontLidarSensor' filename='build/libsdcFrontLidarSensor.so'/>
          <always_on>1</always_on>
          <update_rate>30</update_rate>
          <visualize>1</visualize>
        </sensor>
        <self_collide>0</self_collide>
        <inertial>
          <inertia>
            <ixx>1</ixx>
            <ixy>0</ixy>
            <ixz>0</ixz>
            <iyy>1</iyy>
            <iyz>0</iyz>
            <izz>1</izz>
          </inertia>
          <mass>1</mass>
        </inertial>
        <kinematic>0</kinematic>
        <gravity>1</gravity>
      </link>
      <joint name='front_lidar_joint' type='revolute'>
        <child>front_lidar</child>
        <parent>chassis</parent>
        <axis>
          <xyz>0 0 1</xyz>
          <limit>
            <upper>0</upper>
            <lower>0</lower>
          </limit>
          <use_parent_model_frame>1</use_parent_model_frame>
          <dynamics>
            <spring_reference>0</spring_reference>
            <spring_stiffness>0</spring_stiffness>
          </dynamics>
        </axis>
      </joint>
      <link name='back_lidar'>
        <pose frame=''>-1.2 0 0.4 0 -0 0</pose>
        <visual name='back_lidar_visual'>
          <geometry>
            <mesh>
              <uri>model://hokuyo/meshes/hokuyo.dae</uri>
            </mesh>
          </geometry>
        </visual>
        <collision name='back_lidar_collision-base'>
          <pose frame=''>0 0 -0.0145 0 -0 0</pose>
          <geometry>
            <box>
              <size>0.05 0.05 0.041</size>
            </box>
          </geometry>
          <max_contacts>10</max_contacts>
          <surface>
            <contact>
              <ode/>
            </contact>
            <bounce/>
            <friction>
              <ode/>
            </friction>
          </surface>
        </collision>
        <collision name='back_lidar_collision-top'>
          <pose frame=''>0 0 0.0205 0 -0 0</pose>
          <geometry>
            <cylinder>
              <radius>0.021</radius>
              <length>0.029</length>
            </cylinder>
          </geometry>
          <max_contacts>10</max_contacts>
          <surface>
            <contact>
              <ode/>
            </contact>
            <bounce/>
            <friction>
              <ode/>
            </friction>
          </surface>
        </collision>
        <sensor name='back_lidar' type='ray'>
          <pose frame=''>0.01 0 0.0175 3.14159 -0.004307 3.14159</pose>
          <ray>
            <scan>
              <horizontal>
                <samples>120</samples>
                <resolution>1</resolution>
                <min_angle>-1.5709</min_angle>
                <max_angle>1.5709</max_angle>
              </horizontal>
            </scan>
            <range>
              <min>0.08</min>
              <max>10</max>
              <resolution>0.01</resolution>
            </range>
          </ray>
          <plugin name='sdcBackLidarSensor' filename='build/libsdcBackLidarSensor.so'/>
          <always_on>1</always_on>
          <update_rate>30</update_rate>
          <visualize>0</visualize>
        </sensor>
        <self_collide>0</self_collide>
        <inertial>
          <inertia>
            <ixx>1</ixx>
            <ixy>0</ixy>
            <ixz>0</ixz>
            <iyy>1</iyy>
            <iyz>0</iyz>
            <izz>1</izz>
          </inertia>
          <mass>1</mass>
        </inertial>
        <kinematic>0</kinematic>
        <gravity>1</gravity>
      </link>
      <joint name='back_lidar_joint' type='revolute'>
        <child>back_lidar</child>
        <parent>chassis</parent>
        <axis>
          <xyz>0 0 1</xyz>
          <limit>
            <upper>0</upper>
            <lower>0</lower>
          </limit>
          <use_parent_model_frame>1</use_parent_model_frame>
          <dynamics>
            <spring_reference>0</spring_reference>
            <spring_stiffness>0</spring_stiffness>
          </dynamics>
        </axis>
      </joint>
      <link name='top_laser'>
        <pose frame=''>0 0 1.1 0 -0 0</pose>
        <visual name='top_laser_visual'>
          <geometry>
            <mesh>
              <uri>model://hokuyo/meshes/hokuyo.dae</uri>
            </mesh>
          </geometry>
        </visual>
        <collision name='top_laser_collision-base'>
          <pose frame=''>0 0 -0.0145 0 -0 0</pose>
          <geometry>
            <box>
              <size>0.05 0.05 0.041</size>
            </box>
          </geometry>
          <max_contacts>10</max_contacts>
          <surface>
            <contact>
              <ode/>
            </contact>
            <bounce/>
            <friction>
              <ode/>
            </friction>
          </surface>
        </collision>
        <collision name='top_laser_collision-top'>
          <pose frame=''>0 0 0.0205 0 -0 0</pose>
          <geometry>
            <cylinder>
              <radius>0.021</radius>
              <length>0.029</length>
            </cylinder>
          </geometry>
          <max_contacts>10</max_contacts>
          <surface>
            <contact>
              <ode/>
            </contact>
            <bounce/>
            <friction>
              <ode/>
            </friction>
          </surface>
        </collision>
        <sensor name='top_left_laser' type='ray'>
          <pose frame=''>0.01 0 0.0175 0 0.18 1.5708</pose>
          <ray>
            <scan>
              <horizontal>
                <samples>160</samples>
                <resolution>1</resolution>
                <min_angle>-0.7854</min_angle>
                <max_angle>0.7854</max_angle>
              </horizontal>
            </scan>
            <range>
              <min>0.08</min>
              <max>20</max>
              <resolution>0.01</resolution>
            </range>
          </ray>
          <plugin name='sdcTopLidarSensor' filename='build/libsdcTopLidarSensor.so'/>
          <always_on>1</always_on>
          <update_rate>30</update_rate>
          <visualize>0</visualize>
        </sensor>
        <sensor name='top_forward_laser' type='ray'>
          <pose frame=''>0.01 0 0.0175 0 0.18 0</pose>
          <ray>
            <scan>
              <horizontal>
                <samples>160</samples>
                <resolution>1</resolution>
                <min_angle>-0.7854</min_angle>
                <max_angle>0.7854</max_angle>
              </horizontal>
            </scan>
            <range>
              <min>0.08</min>
              <max>20</max>
              <resolution>0.01</resolution>
            </range>
          </ray>
          <plugin name='sdcTopLidarSensor' filename='build/libsdcTopLidarSensor.so'/>
          <always_on>1</always_on>
          <update_rate>30</update_rate>
          <visualize>0</visualize>
        </sensor>
        <sensor name='top_backward_laser' type='ray'>
          <pose frame=''>0.01 0 0.0175 -0 0.18 3.14159</pose>
          <ray>
            <scan>
              <horizontal>
                <samples>160</samples>
                <resolution>1</resolution>
                <min_angle>-0.7854</min_angle>
                <max_angle>0.7854</max_angle>
              </horizontal>
            </scan>
            <range>
              <min>0.08</min>
              <max>20</max>
              <resolution>0.01</resolution>
            </range>
          </ray>
          <plugin name='sdcTopLidarSensor' filename='build/libsdcTopLidarSensor.so'/>
          <always_on>1</always_on>
          <update_rate>30</update_rate>
          <visualize>0</visualize>
        </sensor>
        <sensor name='top_right_laser' type='ray'>
          <pose frame=''>0.01 0 0.0175 0 0.18 -1.5708</pose>
          <ray>
            <scan>
              <horizontal>
                <samples>160</samples>
                <resolution>1</resolution>
                <min_angle>-0.7854</min_angle>
                <max_angle>0.7854</max_angle>
              </horizontal>
            </scan>
            <range>
              <min>0.08</min>
              <max>20</max>
              <resolution>0.01</resolution>
            </range>
          </ray>
          <plugin name='sdcTopLidarSensor' filename='build/libsdcTopLidarSensor.so'/>
          <always_on>1</always_on>
          <update_rate>30</update_rate>
          <visualize>0</visualize>
        </sensor>
        <self_collide>0</self_collide>
        <inertial>
          <inertia>
            <ixx>1</ixx>
            <ixy>0</ixy>
            <ixz>0</ixz>
            <iyy>1</iyy>
            <iyz>0</iyz>
            <izz>1</izz>
          </inertia>
          <mass>1</mass>
        </inertial>
        <kinematic>0</kinematic>
        <gravity>1</gravity>
      </link>
      <joint name='top_laser_joint' type='revolute'>
        <child>top_laser</child>
        <parent>chassis</parent>
        <axis>
          <xyz>0 0 1</xyz>
          <limit>
            <upper>0</upper>
            <lower>0</lower>
          </limit>
          <use_parent_model_frame>1</use_parent_model_frame>
          <dynamics>
            <spring_reference>0</spring_reference>
            <spring_stiffness>0</spring_stiffness>
          </dynamics>
        </axis>
      </joint>
      <link name='side_right_sensors'>
        <pose frame=''>0 -0.55 0.4 0 -0 0</pose>
        <visual name='side_right_sensors_visual'>
          <geometry>
            <mesh>
              <uri>model://hokuyo/meshes/hokuyo.dae</uri>
            </mesh>
          </geometry>
        </visual>
        <collision name='side_right_sensors_collision-base'>
          <pose frame=''>0 0 -0.0145 0 -0 0</pose>
          <geometry>
            <box>
              <size>0.05 0.05 0.041</size>
            </box>
          </geometry>
          <max_contacts>10</max_contacts>
          <surface>
            <contact>
              <ode/>
            </contact>
            <bounce/>
            <friction>
              <ode/>
            </friction>
          </surface>
        </collision>
        <collision name='side_right_sensors_collision-top'>
          <pose frame=''>0 0 0.0205 0 -0 0</pose>
          <geometry>
            <cylinder>
              <radius>0.021</radius>
              <length>0.029</length>
            </cylinder>
          </geometry>
          <max_contacts>10</max_contacts>
          <surface>
            <contact>
              <ode/>
            </contact>
            <bounce/>
            <friction>
              <ode/>
            </friction>
          </surface>
        </collision>
        <sensor name='side_right_front_laser' type='ray'>
          <pose frame=''>0.4 -0.02 0 0 0 -1.5708</pose>
          <ray>
            <scan>
              <horizontal>
                <samples>160</samples>
                <resolution>1</resolution>
                <min_angle>-1.3</min_angle>
                <max_angle>1.3</max_angle>
              </horizontal>
            </scan>
            <range>
              <min>0.08</min>
              <max>11</max>
              <resolution>0.01</resolution>
            </range>
          </ray>
          <plugin name='sdcSideLidarSensor' filename='build/libsdcSideLidarSensor.so'/>
          <always_on>1</always_on>
          <update_rate>30</update_rate>
          <visualize>1</visualize>
        </sensor>
        <sensor name='side_right_back_laser' type='ray'>
          <pose frame=''>-0.6 -0.02 0 0 0 -1.5708</pose>
          <ray>
            <scan>
              <horizontal>
                <samples>160</samples>
                <resolution>1</resolution>
                <min_angle>-1.3</min_angle>
                <max_angle>1.3</max_angle>
              </horizontal>
            </scan>
            <range>
              <min>0.08</min>
              <max>1</max>
              <resolution>0.01</resolution>
            </range>
          </ray>
          <plugin name='sdcSideLidarSensor' filename='build/libsdcSideLidarSensor.so'/>
          <always_on>1</always_on>
          <update_rate>30</update_rate>
          <visualize>0</visualize>
        </sensor>
        <self_collide>0</self_collide>
        <inertial>
          <inertia>
            <ixx>1</ixx>
            <ixy>0</ixy>
            <ixz>0</ixz>
            <iyy>1</iyy>
            <iyz>0</iyz>
            <izz>1</izz>
          </inertia>
          <mass>1</mass>
        </inertial>
        <kinematic>0</kinematic>
        <gravity>1</gravity>
      </link>
      <joint name='side_right_sensor_joint' type='revolute'>
        <child>side_right_sensors</child>
        <parent>chassis</parent>
        <axis>
          <xyz>0 0 1</xyz>
          <limit>
            <upper>0</upper>
            <lower>0</lower>
          </limit>
          <use_parent_model_frame>1</use_parent_model_frame>
          <dynamics>
            <spring_reference>0</spring_reference>
            <spring_stiffness>0</spring_stiffness>
          </dynamics>
        </axis>
      </joint>
      <link name='side_left_sensors'>
        <pose frame=''>0 0.55 0.4 0 -0 0</pose>
        <visual name='side_left_sensors_visual'>
          <geometry>
            <mesh>
              <uri>model://hokuyo/meshes/hokuyo.dae</uri>
            </mesh>
          </geometry>
        </visual>
        <collision name='side_left_sensors_collision-base'>
          <pose frame=''>0 0 -0.0145 0 -0 0</pose>
          <geometry>
            <box>
              <size>0.05 0.05 0.041</size>
            </box>
          </geometry>
          <max_contacts>10</max_contacts>
          <surface>
            <contact>
              <ode/>
            </contact>
            <bounce/>
            <friction>
              <ode/>
            </friction>
          </surface>
        </collision>
        <collision name='side_left_sensors_collision-top'>
          <pose frame=''>0 0 0.0205 0 -0 0</pose>
          <geometry>
            <cylinder>
              <radius>0.021</radius>
              <length>0.029</length>
            </cylinder>
          </geometry>
          <max_contacts>10</max_contacts>
          <surface>
            <contact>
              <ode/>
            </contact>
            <bounce/>
            <friction>
              <ode/>
            </friction>
          </surface>
        </collision>
        <sensor name='side_left_front_laser' type='ray'>
          <pose frame=''>0.4 0.02 0 0 -0 1.5708</pose>
          <ray>
            <scan>
              <horizontal>
                <samples>160</samples>
                <resolution>1</resolution>
                <min_angle>-1.3</min_angle>
                <max_angle>1.3</max_angle>
              </horizontal>
            </scan>
            <range>
              <min>0.08</min>
              <max>11</max>
              <resolution>0.01</resolution>
            </range>
          </ray>
          <plugin name='sdcSideLidarSensor' filename='build/libsdcSideLidarSensor.so'/>
          <always_on>1</always_on>
          <update_rate>30</update_rate>
          <visualize>1</visualize>
        </sensor>
        <sensor name='side_left_back_laser' type='ray'>
          <pose frame=''>-0.6 0.02 0 0 -0 1.5708</pose>
          <ray>
            <scan>
              <horizontal>
                <samples>160</samples>
                <resolution>1</resolution>
                <min_angle>-1.3</min_angle>
                <max_angle>1.3</max_angle>
              </horizontal>
            </scan>
            <range>
              <min>0.08</min>
              <max>1</max>
              <resolution>0.01</resolution>
            </range>
          </ray>
          <plugin name='sdcSideLidarSensor' filename='build/libsdcSideLidarSensor.so'/>
          <always_on>1</always_on>
          <update_rate>30</update_rate>
          <visualize>0</visualize>
        </sensor>
        <self_collide>0</self_collide>
        <inertial>
          <inertia>
            <ixx>1</ixx>
            <ixy>0</ixy>
            <ixz>0</ixz>
            <iyy>1</iyy>
            <iyz>0</iyz>
            <izz>1</izz>
          </inertia>
          <mass>1</mass>
        </inertial>
        <kinematic>0</kinematic>
        <gravity>1</gravity>
      </link>
      <joint name='side_left_sensor_joint' type='revolute'>
        <child>side_left_sensors</child>
        <parent>chassis</parent>
        <axis>
          <xyz>0 0 1</xyz>
          <limit>
            <upper>0</upper>
            <lower>0</lower>
          </limit>
          <use_parent_model_frame>1</use_parent_model_frame>
          <dynamics>
            <spring_reference>0</spring_reference>
            <spring_stiffness>0</spring_stiffness>
          </dynamics>
        </axis>
      </joint>
      <link name='camera::link'>
        <pose frame=''>0.65 0 0.85 0 0.008 0</pose>
        <self_collide>0</self_collide>
        <kinematic>0</kinematic>
        <sensor name='camera' type='multicamera'>
          <always_on>1</always_on>
          <update_rate>24</update_rate>
          <visualize>0</visualize>
          <topic>comps_car_camera</topic>
          <camera name='left'>
            <pose frame=''>0 0 0 0 -0 0</pose>
            <horizontal_fov>1.047</horizontal_fov>
            <image>
              <width>640</width>
              <height>480</height>
            </image>
            <clip>
              <near>0.1</near>
              <far>150</far>
            </clip>
            <save enabled='0'>
              <path>/Users/selfcar/Desktop/Self-Driving-Comps/comps_camera_recordings/</path>
            </save>
          </camera>
          <plugin name='sdcCameraSensor' filename='build/libsdcCameraSensor.so'/>
        </sensor>
        <visual name='visual'>
          <geometry>
            <box>
              <size>0.1 0.1 0.1</size>
            </box>
          </geometry>
          <material>
            <shader type='pixel'/>
          </material>
          <pose frame=''>0 0 0 0 -0 0</pose>
          <cast_shadows>1</cast_shadows>
          <transparency>0</transparency>
        </visual>
        <inertial>
          <inertia>
            <ixx>1</ixx>
            <ixy>0</ixy>
            <ixz>0</ixz>
            <iyy>1</iyy>
            <iyz>0</iyz>
            <izz>1</izz>
          </inertia>
          <mass>1</mass>
        </inertial>
        <gravity>1</gravity>
      </link>
      <joint name='camera' type='revolute'>
        <parent>chassis</parent>
        <child>camera::link</child>
        <axis>
          <xyz>0 0 1</xyz>
          <use_parent_model_frame>0</use_parent_model_frame>
          <limit>
            <lower>0</lower>
            <upper>0</upper>
            <effort>-1</effort>
            <velocity>-1</velocity>
          </limit>
          <dynamics>
            <spring_reference>0</spring_reference>
            <spring_stiffness>0</spring_stiffness>
            <damping>0</damping>
            <friction>0</friction>
          </dynamics>
          <use_parent_model_frame>1</use_parent_model_frame>
        </axis>
        <physics>
          <ode>
            <limit>
              <cfm>0</cfm>
              <erp>0.2</erp>
            </limit>
            <suspension>
              <cfm>0</cfm>
              <erp>0.2</erp>
            </suspension>
          </ode>
        </physics>
      </joint>
      <link name='gps'>
        <pose frame=''>0 0 1 0 -0 0</pose>
        <visual name='visual'>
          <geometry>
            <mesh>
              <uri>model://hokuyo/meshes/hokuyo.dae</uri>
            </mesh>
          </geometry>
        </visual>
        <collision name='gps_collision-base'>
          <pose frame=''>0 0 -0.0145 0 -0 0</pose>
          <geometry>
            <box>
              <size>0.05 0.05 0.041</size>
            </box>
          </geometry>
          <max_contacts>10</max_contacts>
          <surface>
            <contact>
              <ode/>
            </contact>
            <bounce/>
            <friction>
              <ode/>
            </friction>
          </surface>
        </collision>
        <collision name='gps_collision-top'>
          <pose frame=''>0 0 0.0205 0 -0 0</pose>
          <geometry>
            <cylinder>
              <radius>0.021</radius>
              <length>0.029</length>
            </cylinder>
          </geometry>
          <max_contacts>10</max_contacts>
          <surface>
            <contact>
              <ode/>
            </contact>
            <bounce/>
            <friction>
              <ode/>
            </friction>
          </surface>
        </collision>
        <sensor name='gps' type='gps'>
          <pose frame=''>0 0 0 0 -0 0</pose>
          <always_on>1</always_on>
          <update_rate>30</update_rate>
        </sensor>
        <self_collide>0</self_collide>
        <inertial>
          <inertia>
            <ixx>1</ixx>
            <ixy>0</ixy>
            <ixz>0</ixz>
            <iyy>1</iyy>
            <iyz>0</iyz>
            <izz>1</izz>
          </inertia>
          <mass>1</mass>
        </inertial>
        <kinematic>0</kinematic>
        <gravity>1</gravity>
      </link>
      <joint name='gps_joint' type='revolute'>
        <child>gps</child>
        <parent>chassis</parent>
        <axis>
          <xyz>0 0 1</xyz>
          <limit>
            <upper>0</upper>
            <lower>0</lower>
          </limit>
          <use_parent_model_frame>1</use_parent_model_frame>
          <dynamics>
            <spring_reference>0</spring_reference>
            <spring_stiffness>0</spring_stiffness>
          </dynamics>
        </axis>
      </joint>
      <plugin name='sdcCar' filename='build/libsdcCar.so'>
        <front_left>front_left_joint</front_left>
        <front_right>front_right_joint</front_right>
        <back_left>back_left_joint</back_left>
        <back_right>back_right_joint</back_right>
        <chassis>chassis</chassis>
        <camera>camera::link</camera>
        <frontLidar>front_lidar</frontLidar>
        <rightSideLidar>side_right_sensors</rightSideLidar>
        <leftSideLidar>side_left_sensors</leftSideLidar>
        <wheel_radius>0.21</wheel_radius>
        <front_power>10</front_power>
        <rear_power>10</rear_power>
        <tire_angle_range>0.5</tire_angle_range>
        <max_speed>10</max_speed>
        <aero_load>1.0</aero_load>
      </plugin>
      <plugin name='sdcGpsSensor' filename='build/libsdcGpsSensor.so'>
        <gps>gps</gps>
      </plugin>
      <pose frame=''>-12 -1.5 0 0 -0 0</pose>
    </model>
    <model name='ground_plane'>
      <static>1</static>
      <link name='link'>
        <pose frame=''>50 100 0 0 -0 0</pose>
        <collision name='collision'>
          <geometry>
            <plane>
              <normal>0 0 1</normal>
              <size>100 20</size>
            </plane>
          </geometry>
          <max_contacts>10</max_contacts>
          <surface>
            <contact>
              <ode/>
            </contact>
            <bounce/>
            <friction>
              <ode/>
            </friction>
          </surface>
        </collision>
        <visual name='visual'>
          <cast_shadows>0</cast_shadows>
          <geometry>
            <plane>
              <normal>0 0 1</normal>
              <size>100 20</size>
            </plane>
          </geometry>
          <material>
            <script>
              <uri>__default__</uri>
              <name>__default__</name>
            </script>
          </material>
        </visual>
        <self_collide>0</self_collide>
        <kinematic>0</kinematic>
        <gravity>1</gravity>
      </link>
    </model>
    <model name='road_2_0_1'>
      <pose frame=''>900 0 0 0 -0 0</pose>
      <static>1</static>
      <link name='link'>
        <collision name='collision'>
          <geometry>
            <box>
              <size>1000 6.54 0.0001</size>
            </box>
          </geometry>
          <max_contacts>100</max_contacts>
          <surface>
            <contact>
              <ode/>
            </contact>
            <bounce/>
            <friction>
              <ode/>
            </friction>
          </surface>
        </collision>
        <visual name='visual'>
          <cast_shadows>0</cast_shadows>
          <geometry>
            <box>
              <size>1000 6.54 0.0001</size>
            </box>
          </geometry>
          <material>
            <script>
              <uri>models/newstraight/materials/scripts</uri>
              <uri>models/newstraight/materials/textures</uri>
              <name>newstraight</name>
            </script>
          </material>
        </visual>
        <self_collide>0</self_collide>
        <kinematic>0</kinematic>
        <gravity>1</gravity>
      </link>
    </model>
    <physics name='default_physics' default='0' type='ode'>
      <max_step_size>0.001</max_step_size>
      <real_time_factor>1</real_time_factor>
      <real_time_update_rate>1000</real_time_update_rate>
      <gravity>0 0 -9.8</gravity>
      <magnetic_field>6e-06 2.3e-05 -4.2e-05</magnetic_field>
    </physics>
    <scene>
      <ambient>0.4 0.4 0.4 1</ambient>
      <background>0.7 0.7 0.7 1</background>
      <shadows>1</shadows>
    </scene>
    <audio>
      <device>default</device>
    </audio>
    <spherical_coordinates>
      <surface_model>EARTH_WGS84</surface_model>
      <latitude_deg>0</latitude_deg>
      <longitude_deg>0</longitude_deg>
      <elevation>0</elevation>
      <heading_deg>0</heading_deg>
    </spherical_coordinates>
    <model name='car_clone'>
      <link name='chassis'>
        <pose frame=''>0 0 0.35 0 -0 0</pose>
        <inertial>
          <mass>100</mass>
          <inertia>
            <ixx>1</ixx>
            <ixy>0</ixy>
            <ixz>0</ixz>
            <iyy>1</iyy>
            <iyz>0</iyz>
            <izz>1</izz>
          </inertia>
        </inertial>
        <collision name='chassis_collision'>
          <geometry>
            <box>
              <size>2 0.8 0.2</size>
            </box>
          </geometry>
          <max_contacts>10</max_contacts>
          <surface>
            <contact>
              <ode/>
            </contact>
            <bounce/>
            <friction>
              <ode/>
            </friction>
          </surface>
        </collision>
        <visual name='chassis_visual'>
          <pose frame=''>0.1 0 -0.2 0 -0 1.57079</pose>
          <geometry>
            <mesh>
              <uri>models/sdcCar/cooper-test.dae</uri>
            </mesh>
          </geometry>
        </visual>
        <self_collide>0</self_collide>
        <kinematic>0</kinematic>
        <gravity>1</gravity>
      </link>
      <link name='front_left_wheel'>
        <inertial>
          <mass>10</mass>
          <inertia>
            <ixx>1</ixx>
            <ixy>0</ixy>
            <ixz>0</ixz>
            <iyy>1</iyy>
            <iyz>0</iyz>
            <izz>1</izz>
          </inertia>
        </inertial>
        <pose frame=''>0.8 0.5 0.3 0 1.57079 1.57079</pose>
        <collision name='front_left_wheel_collision'>
          <geometry>
            <cylinder>
              <radius>0.21</radius>
              <length>0.1</length>
            </cylinder>
          </geometry>
          <max_contacts>10</max_contacts>
          <surface>
            <contact>
              <ode/>
            </contact>
            <bounce/>
            <friction>
              <ode/>
            </friction>
          </surface>
        </collision>
        <visual name='front_left_wheel_visual'>
          <geometry>
            <mesh>
              <uri>models/sdcCar/wheel.stl</uri>
            </mesh>
          </geometry>
          <material>
            <script>
              <uri>file://media/materials/scripts/gazebo.material</uri>
              <name>Gazebo/Black</name>
            </script>
          </material>
        </visual>
        <self_collide>0</self_collide>
        <kinematic>0</kinematic>
        <gravity>1</gravity>
      </link>
      <link name='front_right_wheel'>
        <pose frame=''>0.8 -0.5 0.3 0 1.57079 -1.57079</pose>
        <inertial>
          <mass>10</mass>
          <inertia>
            <ixx>1</ixx>
            <ixy>0</ixy>
            <ixz>0</ixz>
            <iyy>1</iyy>
            <iyz>0</iyz>
            <izz>1</izz>
          </inertia>
        </inertial>
        <collision name='front_right_wheel_collision'>
          <geometry>
            <cylinder>
              <radius>0.21</radius>
              <length>0.1</length>
            </cylinder>
          </geometry>
          <max_contacts>10</max_contacts>
          <surface>
            <contact>
              <ode/>
            </contact>
            <bounce/>
            <friction>
              <ode/>
            </friction>
          </surface>
        </collision>
        <visual name='front_right_wheel_visual'>
          <geometry>
            <mesh>
              <uri>models/sdcCar/wheel.stl</uri>
            </mesh>
          </geometry>
          <material>
            <script>
              <uri>file://media/materials/scripts/gazebo.material</uri>
              <name>Gazebo/Black</name>
            </script>
          </material>
        </visual>
        <self_collide>0</self_collide>
        <kinematic>0</kinematic>
        <gravity>1</gravity>
      </link>
      <link name='back_right_wheel'>
        <pose frame=''>-0.87 -0.5 0.3 0 1.57079 -1.57079</pose>
        <inertial>
          <mass>10</mass>
          <inertia>
            <ixx>1</ixx>
            <ixy>0</ixy>
            <ixz>0</ixz>
            <iyy>1</iyy>
            <iyz>0</iyz>
            <izz>1</izz>
          </inertia>
        </inertial>
        <collision name='back_right_wheel_collision'>
          <geometry>
            <cylinder>
              <radius>0.21</radius>
              <length>0.1</length>
            </cylinder>
          </geometry>
          <max_contacts>10</max_contacts>
          <surface>
            <contact>
              <ode/>
            </contact>
            <bounce/>
            <friction>
              <ode/>
            </friction>
          </surface>
        </collision>
        <visual name='back_right_wheel_visual'>
          <geometry>
            <mesh>
              <uri>models/sdcCar/wheel.stl</uri>
            </mesh>
          </geometry>
          <material>
            <script>
              <uri>file://media/materials/scripts/gazebo.material</uri>
              <name>Gazebo/Black</name>
            </script>
          </material>
        </visual>
        <self_collide>0</self_collide>
        <kinematic>0</kinematic>
        <gravity>1</gravity>
      </link>
      <link name='back_left_wheel'>
        <pose frame=''>-0.87 0.5 0.3 0 1.57079 1.57079</pose>
        <inertial>
          <mass>10</mass>
          <inertia>
            <ixx>1</ixx>
            <ixy>0</ixy>
            <ixz>0</ixz>
            <iyy>1</iyy>
            <iyz>0</iyz>
            <izz>1</izz>
          </inertia>
        </inertial>
        <collision name='back_left_wheel_collision'>
          <geometry>
            <cylinder>
              <radius>0.21</radius>
              <length>0.1</length>
            </cylinder>
          </geometry>
          <max_contacts>10</max_contacts>
          <surface>
            <contact>
              <ode/>
            </contact>
            <bounce/>
            <friction>
              <ode/>
            </friction>
          </surface>
        </collision>
        <visual name='back_left_wheel_visual'>
          <geometry>
            <mesh>
              <uri>models/sdcCar/wheel.stl</uri>
            </mesh>
          </geometry>
          <material>
            <script>
              <uri>file://media/materials/scripts/gazebo.material</uri>
              <name>Gazebo/Black</name>
            </script>
          </material>
        </visual>
        <self_collide>0</self_collide>
        <kinematic>0</kinematic>
        <gravity>1</gravity>
      </link>
      <joint name='front_left_joint' type='revolute2'>
        <parent>chassis</parent>
        <child>front_left_wheel</child>
        <axis>
          <xyz>0 0 1</xyz>
          <limit>
            <lower>0</lower>
            <upper>0</upper>
          </limit>
          <use_parent_model_frame>1</use_parent_model_frame>
          <dynamics>
            <spring_reference>0</spring_reference>
            <spring_stiffness>0</spring_stiffness>
          </dynamics>
        </axis>
        <axis2>
          <xyz>0 1 0</xyz>
          <use_parent_model_frame>1</use_parent_model_frame>
          <dynamics>
            <spring_reference>0</spring_reference>
            <spring_stiffness>0</spring_stiffness>
          </dynamics>
        </axis2>
        <physics>
          <ode>
            <limit>
              <cfm>0</cfm>
              <erp>0.9</erp>
            </limit>
            <suspension>
              <cfm>0.01</cfm>
              <erp>0.15</erp>
            </suspension>
          </ode>
        </physics>
      </joint>
      <joint name='front_right_joint' type='revolute2'>
        <parent>chassis</parent>
        <child>front_right_wheel</child>
        <axis>
          <xyz>0 0 1</xyz>
          <limit>
            <lower>0</lower>
            <upper>0</upper>
          </limit>
          <use_parent_model_frame>1</use_parent_model_frame>
          <dynamics>
            <spring_reference>0</spring_reference>
            <spring_stiffness>0</spring_stiffness>
          </dynamics>
        </axis>
        <axis2>
          <xyz>0 1 0</xyz>
          <use_parent_model_frame>1</use_parent_model_frame>
          <dynamics>
            <spring_reference>0</spring_reference>
            <spring_stiffness>0</spring_stiffness>
          </dynamics>
        </axis2>
        <physics>
          <ode>
            <limit>
              <cfm>0</cfm>
              <erp>0.9</erp>
            </limit>
            <suspension>
              <cfm>0.01</cfm>
              <erp>0.15</erp>
            </suspension>
          </ode>
        </physics>
      </joint>
      <joint name='back_right_joint' type='revolute2'>
        <parent>chassis</parent>
        <child>back_right_wheel</child>
        <axis>
          <xyz>0 0 1</xyz>
          <limit>
            <lower>0</lower>
            <upper>0</upper>
          </limit>
          <use_parent_model_frame>1</use_parent_model_frame>
          <dynamics>
            <spring_reference>0</spring_reference>
            <spring_stiffness>0</spring_stiffness>
          </dynamics>
        </axis>
        <axis2>
          <xyz>0 1 0</xyz>
          <use_parent_model_frame>1</use_parent_model_frame>
          <dynamics>
            <spring_reference>0</spring_reference>
            <spring_stiffness>0</spring_stiffness>
          </dynamics>
        </axis2>
        <physics>
          <ode>
            <limit>
              <cfm>0</cfm>
              <erp>0.9</erp>
            </limit>
            <suspension>
              <cfm>0.01</cfm>
              <erp>0.15</erp>
            </suspension>
          </ode>
        </physics>
      </joint>
      <joint name='back_left_joint' type='revolute2'>
        <parent>chassis</parent>
        <child>back_left_wheel</child>
        <axis>
          <xyz>0 0 1</xyz>
          <limit>
            <lower>0</lower>
            <upper>0</upper>
          </limit>
          <use_parent_model_frame>1</use_parent_model_frame>
          <dynamics>
            <spring_reference>0</spring_reference>
            <spring_stiffness>0</spring_stiffness>
          </dynamics>
        </axis>
        <axis2>
          <xyz>0 1 0</xyz>
          <use_parent_model_frame>1</use_parent_model_frame>
          <dynamics>
            <spring_reference>0</spring_reference>
            <spring_stiffness>0</spring_stiffness>
          </dynamics>
        </axis2>
        <physics>
          <ode>
            <limit>
              <cfm>0</cfm>
              <erp>0.9</erp>
            </limit>
            <suspension>
              <cfm>0.01</cfm>
              <erp>0.15</erp>
            </suspension>
          </ode>
        </physics>
      </joint>
      <link name='front_lidar'>
        <pose frame=''>1 0 0.4 0 -0 0</pose>
        <visual name='front_lidar_visual'>
          <geometry>
            <mesh>
              <uri>model://hokuyo/meshes/hokuyo.dae</uri>
            </mesh>
          </geometry>
        </visual>
        <collision name='front_lidar_collision-base'>
          <pose frame=''>0 0 -0.0145 0 -0 0</pose>
          <geometry>
            <box>
              <size>0.05 0.05 0.041</size>
            </box>
          </geometry>
          <max_contacts>10</max_contacts>
          <surface>
            <contact>
              <ode/>
            </contact>
            <bounce/>
            <friction>
              <ode/>
            </friction>
          </surface>
        </collision>
        <collision name='front_lidar_collision-top'>
          <pose frame=''>0 0 0.0205 0 -0 0</pose>
          <geometry>
            <cylinder>
              <radius>0.021</radius>
              <length>0.029</length>
            </cylinder>
          </geometry>
          <max_contacts>10</max_contacts>
          <surface>
            <contact>
              <ode/>
            </contact>
            <bounce/>
            <friction>
              <ode/>
            </friction>
          </surface>
        </collision>
        <sensor name='front_lidar' type='ray'>
          <pose frame=''>0.01 0 0.0175 0 -0 0</pose>
          <ray>
            <scan>
              <horizontal>
                <samples>640</samples>
                <resolution>1</resolution>
                <min_angle>-1.39626</min_angle>
                <max_angle>1.39626</max_angle>
              </horizontal>
            </scan>
            <range>
              <min>0.08</min>
              <max>20</max>
              <resolution>0.01</resolution>
            </range>
          </ray>
          <plugin name='sdcFrontLidarSensor' filename='build/libsdcFrontLidarSensor.so'/>
          <always_on>1</always_on>
          <update_rate>30</update_rate>
          <visualize>1</visualize>
        </sensor>
        <self_collide>0</self_collide>
        <inertial>
          <inertia>
            <ixx>1</ixx>
            <ixy>0</ixy>
            <ixz>0</ixz>
            <iyy>1</iyy>
            <iyz>0</iyz>
            <izz>1</izz>
          </inertia>
          <mass>1</mass>
        </inertial>
        <kinematic>0</kinematic>
        <gravity>1</gravity>
      </link>
      <joint name='front_lidar_joint' type='revolute'>
        <child>front_lidar</child>
        <parent>chassis</parent>
        <axis>
          <xyz>0 0 1</xyz>
          <limit>
            <upper>0</upper>
            <lower>0</lower>
          </limit>
          <use_parent_model_frame>1</use_parent_model_frame>
          <dynamics>
            <spring_reference>0</spring_reference>
            <spring_stiffness>0</spring_stiffness>
          </dynamics>
        </axis>
      </joint>
      <link name='back_lidar'>
        <pose frame=''>-1.2 0 0.4 0 -0 0</pose>
        <visual name='back_lidar_visual'>
          <geometry>
            <mesh>
              <uri>model://hokuyo/meshes/hokuyo.dae</uri>
            </mesh>
          </geometry>
        </visual>
        <collision name='back_lidar_collision-base'>
          <pose frame=''>0 0 -0.0145 0 -0 0</pose>
          <geometry>
            <box>
              <size>0.05 0.05 0.041</size>
            </box>
          </geometry>
          <max_contacts>10</max_contacts>
          <surface>
            <contact>
              <ode/>
            </contact>
            <bounce/>
            <friction>
              <ode/>
            </friction>
          </surface>
        </collision>
        <collision name='back_lidar_collision-top'>
          <pose frame=''>0 0 0.0205 0 -0 0</pose>
          <geometry>
            <cylinder>
              <radius>0.021</radius>
              <length>0.029</length>
            </cylinder>
          </geometry>
          <max_contacts>10</max_contacts>
          <surface>
            <contact>
              <ode/>
            </contact>
            <bounce/>
            <friction>
              <ode/>
            </friction>
          </surface>
        </collision>
        <sensor name='back_lidar' type='ray'>
          <pose frame=''>0.01 0 0.0175 3.14159 -0.004307 3.14159</pose>
          <ray>
            <scan>
              <horizontal>
                <samples>120</samples>
                <resolution>1</resolution>
                <min_angle>-1.5709</min_angle>
                <max_angle>1.5709</max_angle>
              </horizontal>
            </scan>
            <range>
              <min>0.08</min>
              <max>10</max>
              <resolution>0.01</resolution>
            </range>
          </ray>
          <plugin name='sdcBackLidarSensor' filename='build/libsdcBackLidarSensor.so'/>
          <always_on>1</always_on>
          <update_rate>30</update_rate>
          <visualize>0</visualize>
        </sensor>
        <self_collide>0</self_collide>
        <inertial>
          <inertia>
            <ixx>1</ixx>
            <ixy>0</ixy>
            <ixz>0</ixz>
            <iyy>1</iyy>
            <iyz>0</iyz>
            <izz>1</izz>
          </inertia>
          <mass>1</mass>
        </inertial>
        <kinematic>0</kinematic>
        <gravity>1</gravity>
      </link>
      <joint name='back_lidar_joint' type='revolute'>
        <child>back_lidar</child>
        <parent>chassis</parent>
        <axis>
          <xyz>0 0 1</xyz>
          <limit>
            <upper>0</upper>
            <lower>0</lower>
          </limit>
          <use_parent_model_frame>1</use_parent_model_frame>
          <dynamics>
            <spring_reference>0</spring_reference>
            <spring_stiffness>0</spring_stiffness>
          </dynamics>
        </axis>
      </joint>
      <link name='top_laser'>
        <pose frame=''>0 0 1.1 0 -0 0</pose>
        <visual name='top_laser_visual'>
          <geometry>
            <mesh>
              <uri>model://hokuyo/meshes/hokuyo.dae</uri>
            </mesh>
          </geometry>
        </visual>
        <collision name='top_laser_collision-base'>
          <pose frame=''>0 0 -0.0145 0 -0 0</pose>
          <geometry>
            <box>
              <size>0.05 0.05 0.041</size>
            </box>
          </geometry>
          <max_contacts>10</max_contacts>
          <surface>
            <contact>
              <ode/>
            </contact>
            <bounce/>
            <friction>
              <ode/>
            </friction>
          </surface>
        </collision>
        <collision name='top_laser_collision-top'>
          <pose frame=''>0 0 0.0205 0 -0 0</pose>
          <geometry>
            <cylinder>
              <radius>0.021</radius>
              <length>0.029</length>
            </cylinder>
          </geometry>
          <max_contacts>10</max_contacts>
          <surface>
            <contact>
              <ode/>
            </contact>
            <bounce/>
            <friction>
              <ode/>
            </friction>
          </surface>
        </collision>
        <sensor name='top_left_laser' type='ray'>
          <pose frame=''>0.01 0 0.0175 0 0.18 1.5708</pose>
          <ray>
            <scan>
              <horizontal>
                <samples>160</samples>
                <resolution>1</resolution>
                <min_angle>-0.7854</min_angle>
                <max_angle>0.7854</max_angle>
              </horizontal>
            </scan>
            <range>
              <min>0.08</min>
              <max>20</max>
              <resolution>0.01</resolution>
            </range>
          </ray>
          <plugin name='sdcTopLidarSensor' filename='build/libsdcTopLidarSensor.so'/>
          <always_on>1</always_on>
          <update_rate>30</update_rate>
          <visualize>0</visualize>
        </sensor>
        <sensor name='top_forward_laser' type='ray'>
          <pose frame=''>0.01 0 0.0175 0 0.18 0</pose>
          <ray>
            <scan>
              <horizontal>
                <samples>160</samples>
                <resolution>1</resolution>
                <min_angle>-0.7854</min_angle>
                <max_angle>0.7854</max_angle>
              </horizontal>
            </scan>
            <range>
              <min>0.08</min>
              <max>20</max>
              <resolution>0.01</resolution>
            </range>
          </ray>
          <plugin name='sdcTopLidarSensor' filename='build/libsdcTopLidarSensor.so'/>
          <always_on>1</always_on>
          <update_rate>30</update_rate>
          <visualize>0</visualize>
        </sensor>
        <sensor name='top_backward_laser' type='ray'>
          <pose frame=''>0.01 0 0.0175 -0 0.18 3.14159</pose>
          <ray>
            <scan>
              <horizontal>
                <samples>160</samples>
                <resolution>1</resolution>
                <min_angle>-0.7854</min_angle>
                <max_angle>0.7854</max_angle>
              </horizontal>
            </scan>
            <range>
              <min>0.08</min>
              <max>20</max>
              <resolution>0.01</resolution>
            </range>
          </ray>
          <plugin name='sdcTopLidarSensor' filename='build/libsdcTopLidarSensor.so'/>
          <always_on>1</always_on>
          <update_rate>30</update_rate>
          <visualize>0</visualize>
        </sensor>
        <sensor name='top_right_laser' type='ray'>
          <pose frame=''>0.01 0 0.0175 0 0.18 -1.5708</pose>
          <ray>
            <scan>
              <horizontal>
                <samples>160</samples>
                <resolution>1</resolution>
                <min_angle>-0.7854</min_angle>
                <max_angle>0.7854</max_angle>
              </horizontal>
            </scan>
            <range>
              <min>0.08</min>
              <max>20</max>
              <resolution>0.01</resolution>
            </range>
          </ray>
          <plugin name='sdcTopLidarSensor' filename='build/libsdcTopLidarSensor.so'/>
          <always_on>1</always_on>
          <update_rate>30</update_rate>
          <visualize>0</visualize>
        </sensor>
        <self_collide>0</self_collide>
        <inertial>
          <inertia>
            <ixx>1</ixx>
            <ixy>0</ixy>
            <ixz>0</ixz>
            <iyy>1</iyy>
            <iyz>0</iyz>
            <izz>1</izz>
          </inertia>
          <mass>1</mass>
        </inertial>
        <kinematic>0</kinematic>
        <gravity>1</gravity>
      </link>
      <joint name='top_laser_joint' type='revolute'>
        <child>top_laser</child>
        <parent>chassis</parent>
        <axis>
          <xyz>0 0 1</xyz>
          <limit>
            <upper>0</upper>
            <lower>0</lower>
          </limit>
          <use_parent_model_frame>1</use_parent_model_frame>
          <dynamics>
            <spring_reference>0</spring_reference>
            <spring_stiffness>0</spring_stiffness>
          </dynamics>
        </axis>
      </joint>
      <link name='side_right_sensors'>
        <pose frame=''>0 -0.55 0.4 0 -0 0</pose>
        <visual name='side_right_sensors_visual'>
          <geometry>
            <mesh>
              <uri>model://hokuyo/meshes/hokuyo.dae</uri>
            </mesh>
          </geometry>
        </visual>
        <collision name='side_right_sensors_collision-base'>
          <pose frame=''>0 0 -0.0145 0 -0 0</pose>
          <geometry>
            <box>
              <size>0.05 0.05 0.041</size>
            </box>
          </geometry>
          <max_contacts>10</max_contacts>
          <surface>
            <contact>
              <ode/>
            </contact>
            <bounce/>
            <friction>
              <ode/>
            </friction>
          </surface>
        </collision>
        <collision name='side_right_sensors_collision-top'>
          <pose frame=''>0 0 0.0205 0 -0 0</pose>
          <geometry>
            <cylinder>
              <radius>0.021</radius>
              <length>0.029</length>
            </cylinder>
          </geometry>
          <max_contacts>10</max_contacts>
          <surface>
            <contact>
              <ode/>
            </contact>
            <bounce/>
            <friction>
              <ode/>
            </friction>
          </surface>
        </collision>
        <sensor name='side_right_front_laser' type='ray'>
          <pose frame=''>0.4 -0.02 0 0 0 -1.5708</pose>
          <ray>
            <scan>
              <horizontal>
                <samples>160</samples>
                <resolution>1</resolution>
                <min_angle>-1.3</min_angle>
                <max_angle>1.3</max_angle>
              </horizontal>
            </scan>
            <range>
              <min>0.08</min>
              <max>11</max>
              <resolution>0.01</resolution>
            </range>
          </ray>
          <plugin name='sdcSideLidarSensor' filename='build/libsdcSideLidarSensor.so'/>
          <always_on>1</always_on>
          <update_rate>30</update_rate>
          <visualize>1</visualize>
        </sensor>
        <sensor name='side_right_back_laser' type='ray'>
          <pose frame=''>-0.6 -0.02 0 0 0 -1.5708</pose>
          <ray>
            <scan>
              <horizontal>
                <samples>160</samples>
                <resolution>1</resolution>
                <min_angle>-1.3</min_angle>
                <max_angle>1.3</max_angle>
              </horizontal>
            </scan>
            <range>
              <min>0.08</min>
              <max>1</max>
              <resolution>0.01</resolution>
            </range>
          </ray>
          <plugin name='sdcSideLidarSensor' filename='build/libsdcSideLidarSensor.so'/>
          <always_on>1</always_on>
          <update_rate>30</update_rate>
          <visualize>0</visualize>
        </sensor>
        <self_collide>0</self_collide>
        <inertial>
          <inertia>
            <ixx>1</ixx>
            <ixy>0</ixy>
            <ixz>0</ixz>
            <iyy>1</iyy>
            <iyz>0</iyz>
            <izz>1</izz>
          </inertia>
          <mass>1</mass>
        </inertial>
        <kinematic>0</kinematic>
        <gravity>1</gravity>
      </link>
      <joint name='side_right_sensor_joint' type='revolute'>
        <child>side_right_sensors</child>
        <parent>chassis</parent>
        <axis>
          <xyz>0 0 1</xyz>
          <limit>
            <upper>0</upper>
            <lower>0</lower>
          </limit>
          <use_parent_model_frame>1</use_parent_model_frame>
          <dynamics>
            <spring_reference>0</spring_reference>
            <spring_stiffness>0</spring_stiffness>
          </dynamics>
        </axis>
      </joint>
      <link name='side_left_sensors'>
        <pose frame=''>0 0.55 0.4 0 -0 0</pose>
        <visual name='side_left_sensors_visual'>
          <geometry>
            <mesh>
              <uri>model://hokuyo/meshes/hokuyo.dae</uri>
            </mesh>
          </geometry>
        </visual>
        <collision name='side_left_sensors_collision-base'>
          <pose frame=''>0 0 -0.0145 0 -0 0</pose>
          <geometry>
            <box>
              <size>0.05 0.05 0.041</size>
            </box>
          </geometry>
          <max_contacts>10</max_contacts>
          <surface>
            <contact>
              <ode/>
            </contact>
            <bounce/>
            <friction>
              <ode/>
            </friction>
          </surface>
        </collision>
        <collision name='side_left_sensors_collision-top'>
          <pose frame=''>0 0 0.0205 0 -0 0</pose>
          <geometry>
            <cylinder>
              <radius>0.021</radius>
              <length>0.029</length>
            </cylinder>
          </geometry>
          <max_contacts>10</max_contacts>
          <surface>
            <contact>
              <ode/>
            </contact>
            <bounce/>
            <friction>
              <ode/>
            </friction>
          </surface>
        </collision>
        <sensor name='side_left_front_laser' type='ray'>
          <pose frame=''>0.4 0.02 0 0 -0 1.5708</pose>
          <ray>
            <scan>
              <horizontal>
                <samples>160</samples>
                <resolution>1</resolution>
                <min_angle>-1.3</min_angle>
                <max_angle>1.3</max_angle>
              </horizontal>
            </scan>
            <range>
              <min>0.08</min>
              <max>11</max>
              <resolution>0.01</resolution>
            </range>
          </ray>
          <plugin name='sdcSideLidarSensor' filename='build/libsdcSideLidarSensor.so'/>
          <always_on>1</always_on>
          <update_rate>30</update_rate>
          <visualize>1</visualize>
        </sensor>
        <sensor name='side_left_back_laser' type='ray'>
          <pose frame=''>-0.6 0.02 0 0 -0 1.5708</pose>
          <ray>
            <scan>
              <horizontal>
                <samples>160</samples>
                <resolution>1</resolution>
                <min_angle>-1.3</min_angle>
                <max_angle>1.3</max_angle>
              </horizontal>
            </scan>
            <range>
              <min>0.08</min>
              <max>1</max>
              <resolution>0.01</resolution>
            </range>
          </ray>
          <plugin name='sdcSideLidarSensor' filename='build/libsdcSideLidarSensor.so'/>
          <always_on>1</always_on>
          <update_rate>30</update_rate>
          <visualize>0</visualize>
        </sensor>
        <self_collide>0</self_collide>
        <inertial>
          <inertia>
            <ixx>1</ixx>
            <ixy>0</ixy>
            <ixz>0</ixz>
            <iyy>1</iyy>
            <iyz>0</iyz>
            <izz>1</izz>
          </inertia>
          <mass>1</mass>
        </inertial>
        <kinematic>0</kinematic>
        <gravity>1</gravity>
      </link>
      <joint name='side_left_sensor_joint' type='revolute'>
        <child>side_left_sensors</child>
        <parent>chassis</parent>
        <axis>
          <xyz>0 0 1</xyz>
          <limit>
            <upper>0</upper>
            <lower>0</lower>
          </limit>
          <use_parent_model_frame>1</use_parent_model_frame>
          <dynamics>
            <spring_reference>0</spring_reference>
            <spring_stiffness>0</spring_stiffness>
          </dynamics>
        </axis>
      </joint>
      <link name='camera::link'>
        <pose frame=''>0.65 0 0.85 0 0.008 0</pose>
        <self_collide>0</self_collide>
        <kinematic>0</kinematic>
        <sensor name='camera' type='multicamera'>
          <always_on>1</always_on>
          <update_rate>24</update_rate>
          <visualize>0</visualize>
          <topic>comps_car_camera</topic>
          <camera name='left'>
            <pose frame=''>0 0 0 0 -0 0</pose>
            <horizontal_fov>1.047</horizontal_fov>
            <image>
              <width>640</width>
              <height>480</height>
            </image>
            <clip>
              <near>0.1</near>
              <far>150</far>
            </clip>
            <save enabled='0'>
              <path>/Users/selfcar/Desktop/Self-Driving-Comps/comps_camera_recordings/</path>
            </save>
          </camera>
          <plugin name='sdcCameraSensor' filename='build/libsdcCameraSensor.so'/>
        </sensor>
        <visual name='visual'>
          <geometry>
            <box>
              <size>0.1 0.1 0.1</size>
            </box>
          </geometry>
          <material>
            <shader type='pixel'/>
          </material>
          <pose frame=''>0 0 0 0 -0 0</pose>
          <cast_shadows>1</cast_shadows>
          <transparency>0</transparency>
        </visual>
        <inertial>
          <inertia>
            <ixx>1</ixx>
            <ixy>0</ixy>
            <ixz>0</ixz>
            <iyy>1</iyy>
            <iyz>0</iyz>
            <izz>1</izz>
          </inertia>
          <mass>1</mass>
        </inertial>
        <gravity>1</gravity>
      </link>
      <joint name='camera' type='revolute'>
        <parent>chassis</parent>
        <child>camera::link</child>
        <axis>
          <xyz>0 0 1</xyz>
          <use_parent_model_frame>0</use_parent_model_frame>
          <limit>
            <lower>0</lower>
            <upper>0</upper>
            <effort>-1</effort>
            <velocity>-1</velocity>
          </limit>
          <dynamics>
            <spring_reference>0</spring_reference>
            <spring_stiffness>0</spring_stiffness>
            <damping>0</damping>
            <friction>0</friction>
          </dynamics>
          <use_parent_model_frame>1</use_parent_model_frame>
        </axis>
        <physics>
          <ode>
            <limit>
              <cfm>0</cfm>
              <erp>0.2</erp>
            </limit>
            <suspension>
              <cfm>0</cfm>
              <erp>0.2</erp>
            </suspension>
          </ode>
        </physics>
      </joint>
      <link name='gps'>
        <pose frame=''>0 0 1 0 -0 0</pose>
        <visual name='visual'>
          <geometry>
            <mesh>
              <uri>model://hokuyo/meshes/hokuyo.dae</uri>
            </mesh>
          </geometry>
        </visual>
        <collision name='gps_collision-base'>
          <pose frame=''>0 0 -0.0145 0 -0 0</pose>
          <geometry>
            <box>
              <size>0.05 0.05 0.041</size>
            </box>
          </geometry>
          <max_contacts>10</max_contacts>
          <surface>
            <contact>
              <ode/>
            </contact>
            <bounce/>
            <friction>
              <ode/>
            </friction>
          </surface>
        </collision>
        <collision name='gps_collision-top'>
          <pose frame=''>0 0 0.0205 0 -0 0</pose>
          <geometry>
            <cylinder>
              <radius>0.021</radius>
              <length>0.029</length>
            </cylinder>
          </geometry>
          <max_contacts>10</max_contacts>
          <surface>
            <contact>
              <ode/>
            </contact>
            <bounce/>
            <friction>
              <ode/>
            </friction>
          </surface>
        </collision>
        <sensor name='gps' type='gps'>
          <pose frame=''>0 0 0 0 -0 0</pose>
          <always_on>1</always_on>
          <update_rate>30</update_rate>
        </sensor>
        <self_collide>0</self_collide>
        <inertial>
          <inertia>
            <ixx>1</ixx>
            <ixy>0</ixy>
            <ixz>0</ixz>
            <iyy>1</iyy>
            <iyz>0</iyz>
            <izz>1</izz>
          </inertia>
          <mass>1</mass>
        </inertial>
        <kinematic>0</kinematic>
        <gravity>1</gravity>
      </link>
      <joint name='gps_joint' type='revolute'>
        <child>gps</child>
        <parent>chassis</parent>
        <axis>
          <xyz>0 0 1</xyz>
          <limit>
            <upper>0</upper>
            <lower>0</lower>
          </limit>
          <use_parent_model_frame>1</use_parent_model_frame>
          <dynamics>
            <spring_reference>0</spring_reference>
            <spring_stiffness>0</spring_stiffness>
          </dynamics>
        </axis>
      </joint>
      <plugin name='sdcCar' filename='build/libsdcCar.so'>
        <front_left>front_left_joint</front_left>
        <front_right>front_right_joint</front_right>
        <back_left>back_left_joint</back_left>
        <back_right>back_right_joint</back_right>
        <chassis>chassis</chassis>
        <camera>camera::link</camera>
        <frontLidar>front_lidar</frontLidar>
        <rightSideLidar>side_right_sensors</rightSideLidar>
        <leftSideLidar>side_left_sensors</leftSideLidar>
        <wheel_radius>0.21</wheel_radius>
        <front_power>10</front_power>
        <rear_power>10</rear_power>
        <tire_angle_range>0.5</tire_angle_range>
        <max_speed>10</max_speed>
        <aero_load>1.0</aero_load>
      </plugin>
      <plugin name='sdcGpsSensor' filename='build/libsdcGpsSensor.so'>
        <gps>gps</gps>
      </plugin>
      <pose frame=''>4 -2 -1e-05 -3e-06 1.6e-05 -0.001156</pose>
    </model>
    <state world_name='default'>
      <sim_time>0 0</sim_time>
      <real_time>0 0</real_time>
      <wall_time>1486235819 844441000</wall_time>
      <iterations>0</iterations>
      <model name='car'>
        <pose frame=''>-10.133 -1.92002 -0.106536 1e-06 -3.3e-05 0.000213</pose>
        <link name='back_left_wheel'>
          <pose frame=''>-11.0031 -1.4202 0.209999 -1.4348 1.57075 0.1362</pose>
          <velocity>0.000852 -2.9e-05 0.009993 0.000136 0.004058 -3.4e-05</velocity>
          <acceleration>0.852471 -0.028607 9.99339 -3.00541 -0.916265 3.10778</acceleration>
          <wrench>8.52471 -0.286075 99.9339 0 -0 0</wrench>
        </link>
        <link name='back_lidar'>
          <pose frame=''>-11.333 -1.92027 0.293425 2e-06 -3.3e-05 0.000212</pose>
          <velocity>0.000605 -0.000176 -0.013994 6.6e-05 -0.003553 0.00012</velocity>
          <acceleration>0.604676 -0.176073 -13.9941 -3.07578 0.411386 -3.02125</acceleration>
          <wrench>0.604676 -0.176073 -13.9941 0 -0 0</wrench>
        </link>
        <link name='back_right_wheel'>
          <pose frame=''>-11.0029 -2.4202 0.21 1.46857 1.57074 -0.102011</pose>
          <velocity>0.000809 -1.2e-05 0.010007 5.9e-05 0.003854 -4.3e-05</velocity>
          <acceleration>0.80883 -0.012402 10.0068 -3.08253 -0.711932 3.09849</acceleration>
          <wrench>8.08831 -0.124023 100.068 0 -0 0</wrench>
        </link>
        <link name='camera::link'>
          <pose frame=''>-9.48301 -1.91988 0.743486 1e-06 0.007967 0.000213</pose>
          <velocity>-0.000988 -2.5e-05 -0.007443 6.9e-05 -0.003529 7.8e-05</velocity>
          <acceleration>-0.988398 -0.024996 -7.44277 -3.07248 0.387013 -3.06326</acceleration>
          <wrench>-0.988398 -0.024996 -7.44277 0 -0 0</wrench>
        </link>
        <link name='chassis'>
          <pose frame=''>-10.133 -1.92002 0.243464 1e-06 -3.3e-05 0.000213</pose>
          <velocity>0.000781 -3.7e-05 -0.009741 6.9e-05 -0.003557 6.6e-05</velocity>
          <acceleration>0.781065 -0.036959 -9.74067 -3.07271 0.415055 -3.07605</acceleration>
          <wrench>78.1065 -3.69594 -974.067 0 -0 0</wrench>
        </link>
        <link name='front_left_wheel'>
          <pose frame=''>-9.3331 -1.41985 0.209999 -1.42248 1.57075 0.148519</pose>
          <velocity>0.000802 -1.2e-05 0.009994 5.7e-05 0.003822 5.6e-05</velocity>
          <acceleration>0.802034 -0.012064 9.994 -3.08414 -0.680139 -3.08579</acceleration>
          <wrench>8.02034 -0.120638 99.94 0 -0 0</wrench>
        </link>
        <link name='front_lidar'>
          <pose frame=''>-9.133 -1.91981 0.293497 2e-06 -3.3e-05 0.000212</pose>
          <velocity>0.000603 8.4e-05 -0.006183 6.3e-05 -0.003558 0.000133</velocity>
          <acceleration>0.603235 0.084135 -6.18292 -3.07815 0.41682 -3.00908</acceleration>
          <wrench>0.603235 0.084135 -6.18292 0 -0 0</wrench>
        </link>
        <link name='front_right_wheel'>
          <pose frame=''>-9.33289 -2.41985 0.21 1.49995 1.57074 -0.070632</pose>
          <velocity>0.000851 -2.1e-05 0.010007 9.9e-05 0.00405 3e-05</velocity>
          <acceleration>0.8507 -0.020855 10.0066 -3.0423 -0.907994 -3.11133</acceleration>
          <wrench>8.507 -0.208546 100.066 0 -0 0</wrench>
        </link>
        <link name='gps'>
          <pose frame=''>-10.133 -1.92002 0.893464 1e-06 -3.3e-05 0.000213</pose>
          <velocity>-0.001527 -8.4e-05 -0.009741 7e-05 -0.003543 7.3e-05</velocity>
          <acceleration>-1.52712 -0.083899 -9.74069 -3.07158 0.40146 -3.06899</acceleration>
          <wrench>-1.52712 -0.083899 -9.74069 0 -0 0</wrench>
        </link>
        <link name='side_left_sensors'>
          <pose frame=''>-10.1331 -1.37002 0.293465 1e-06 -3.3e-05 0.000213</pose>
          <velocity>0.000561 -4.2e-05 -0.009703 6.9e-05 -0.003524 8.5e-05</velocity>
          <acceleration>0.560508 -0.041968 -9.70306 -3.07299 0.382766 -3.05619</acceleration>
          <wrench>0.560508 -0.041968 -9.70306 0 -0 0</wrench>
        </link>
        <link name='side_right_sensors'>
          <pose frame=''>-10.1329 -2.47002 0.293463 1e-06 -3.3e-05 0.000213</pose>
          <velocity>0.000654 -4.2e-05 -0.009778 6.7e-05 -0.003524 9.4e-05</velocity>
          <acceleration>0.653574 -0.04194 -9.7778 -3.07412 0.382833 -3.048</acceleration>
          <wrench>0.653574 -0.04194 -9.7778 0 -0 0</wrench>
        </link>
        <link name='top_laser'>
          <pose frame=''>-10.133 -1.92002 0.993464 2e-06 -3.3e-05 0.000212</pose>
          <velocity>-0.001864 -8.9e-05 -0.009741 6.7e-05 -0.003533 0.0001</velocity>
          <acceleration>-1.8638 -0.08949 -9.74076 -3.07457 0.39153 -3.04128</acceleration>
          <wrench>-1.8638 -0.08949 -9.74076 0 -0 0</wrench>
        </link>
      </model>
      <model name='car_clone'>
        <pose frame=''>10.0127 -1.68943 -0.106853 -2e-06 0.000972 -1.5e-05</pose>
        <link name='back_left_wheel'>
          <pose frame=''>9.14297 -1.18942 0.21 1.569 1.56979 3.13978</pose>
          <velocity>0.000866 -2.8e-05 0.009994 0.000135 0.004122 -3.4e-05</velocity>
          <acceleration>0.865992 -0.028392 9.99351 -3.00643 -0.980648 3.10765</acceleration>
          <wrench>8.65992 -0.283923 99.9351 0 -0 0</wrench>
        </link>
        <link name='back_lidar'>
          <pose frame=''>8.81304 -1.68941 0.294314 -2e-06 0.000973 -1.7e-05</pose>
          <velocity>0.000591 -0.000175 -0.013987 6.4e-05 -0.003547 0.000119</velocity>
          <acceleration>0.590853 -0.174553 -13.9873 -3.07768 0.405215 -3.02276</acceleration>
          <wrench>0.590853 -0.174553 -13.9873 0 -0 0</wrench>
        </link>
        <link name='back_right_wheel'>
          <pose frame=''>9.14295 -2.18942 0.209999 -1.56232 1.56979 -3.13313</pose>
          <velocity>0.000823 -1.2e-05 0.010007 5.9e-05 0.003921 -4.3e-05</velocity>
          <acceleration>0.822911 -0.012324 10.0067 -3.0829 -0.778959 3.09899</acceleration>
          <wrench>8.22911 -0.123241 100.067 0 -0 0</wrench>
        </link>
        <link name='camera::link'>
          <pose frame=''>10.6635 -1.68944 0.742515 -2e-06 0.008973 -1.6e-05</pose>
          <velocity>-0.000993 -2.5e-05 -0.007446 6.7e-05 -0.003522 7.7e-05</velocity>
          <acceleration>-0.992735 -0.024564 -7.44573 -3.07448 0.380841 -3.06412</acceleration>
          <wrench>-0.992735 -0.024564 -7.44573 0 -0 0</wrench>
        </link>
        <link name='chassis'>
          <pose frame=''>10.013 -1.68943 0.243147 -2e-06 0.000972 -1.5e-05</pose>
          <velocity>0.000771 -3.7e-05 -0.009741 6.7e-05 -0.003551 6.5e-05</velocity>
          <acceleration>0.771305 -0.037112 -9.74143 -3.07465 0.408948 -3.07673</acceleration>
          <wrench>77.1305 -3.71121 -974.143 0 -0 0</wrench>
        </link>
        <link name='front_left_wheel'>
          <pose frame=''>10.813 -1.18944 0.21 1.56594 1.56978 3.13671</pose>
          <velocity>0.000804 -1.2e-05 0.009994 5.7e-05 0.003831 5.5e-05</velocity>
          <acceleration>0.804024 -0.012065 9.9941 -3.08414 -0.689586 -3.08642</acceleration>
          <wrench>8.04024 -0.120652 99.941 0 -0 0</wrench>
        </link>
        <link name='front_lidar'>
          <pose frame=''>11.013 -1.68945 0.292175 -2e-06 0.000972 -1.8e-05</pose>
          <velocity>0.000597 8.3e-05 -0.00619 6.1e-05 -0.003552 0.000131</velocity>
          <acceleration>0.597436 0.08252 -6.18968 -3.08012 0.410648 -3.01084</acceleration>
          <wrench>0.597436 0.08252 -6.18968 0 -0 0</wrench>
        </link>
        <link name='front_right_wheel'>
          <pose frame=''>10.813 -2.18944 0.209999 -1.56326 1.56978 -3.13406</pose>
          <velocity>0.000852 -2.1e-05 0.010006 9.9e-05 0.004055 3e-05</velocity>
          <acceleration>0.851926 -0.020724 10.0064 -3.04293 -0.913842 -3.11165</acceleration>
          <wrench>8.51926 -0.20724 100.064 0 -0 0</wrench>
        </link>
        <link name='gps'>
          <pose frame=''>10.0136 -1.68943 0.893147 -2e-06 0.000973 -1.6e-05</pose>
          <velocity>-0.001533 -8.3e-05 -0.009739 6.8e-05 -0.003537 7.2e-05</velocity>
          <acceleration>-1.53291 -0.082691 -9.73909 -3.07361 0.395328 -3.06976</acceleration>
          <wrench>-1.53291 -0.082691 -9.73909 0 -0 0</wrench>
        </link>
        <link name='side_left_sensors'>
          <pose frame=''>10.013 -1.13943 0.293146 -2e-06 0.000973 -1.6e-05</pose>
          <velocity>0.000552 -4.2e-05 -0.009704 6.7e-05 -0.003518 8.4e-05</velocity>
          <acceleration>0.551548 -0.041999 -9.70429 -3.07495 0.376571 -3.05715</acceleration>
          <wrench>0.551548 -0.041999 -9.70429 0 -0 0</wrench>
        </link>
        <link name='side_right_sensors'>
          <pose frame=''>10.013 -2.23943 0.293148 -2e-06 0.000973 -1.6e-05</pose>
          <velocity>0.000644 -4.2e-05 -0.009778 6.6e-05 -0.003518 9.3e-05</velocity>
          <acceleration>0.643554 -0.041994 -9.77776 -3.07603 0.376628 -3.04909</acceleration>
          <wrench>0.643554 -0.041994 -9.77776 0 -0 0</wrench>
        </link>
        <link name='top_laser'>
          <pose frame=''>10.0137 -1.68943 0.993147 -2e-06 0.000973 -1.7e-05</pose>
          <velocity>-0.001869 -8.8e-05 -0.009739 6.5e-05 -0.003527 9.9e-05</velocity>
          <acceleration>-1.86892 -0.08815 -9.73882 -3.07645 0.385334 -3.04247</acceleration>
          <wrench>-1.86892 -0.08815 -9.73882 0 -0 0</wrench>
        </link>
      </model>
      <model name='car_clone_clone'>
        <pose frame=''>17.5139 -2 -0.106853 -1e-06 0.000974 -1.6e-05</pose>
        <link name='back_left_wheel'>
          <pose frame=''>16.6442 -1.49999 0.21 1.5694 1.56978 3.14017</pose>
          <velocity>0.000952 -2.7e-05 0.009994 0.000128 0.00453 -4e-05</velocity>
          <acceleration>0.951593 -0.026939 9.99407 -3.01335 -1.38799 3.10128</acceleration>
          <wrench>9.51594 -0.269385 99.9407 0 -0 0</wrench>
        </link>
        <link name='back_lidar'>
          <pose frame=''>16.3142 -1.99998 0.294316 -2e-06 0.000974 -1.8e-05</pose>
          <velocity>0.000541 -0.000176 -0.014078 5.6e-05 -0.003621 0.000119</velocity>
          <acceleration>0.540812 -0.175766 -14.0776 -3.0858 0.479736 -3.02294</acceleration>
          <wrench>0.540812 -0.175766 -14.0776 0 -0 0</wrench>
        </link>
        <link name='back_right_wheel'>
          <pose frame=''>16.6442 -2.49999 0.209999 -1.56199 1.56979 -3.13279</pose>
          <velocity>0.000899 -1e-05 0.010006 4.9e-05 0.004285 -4.4e-05</velocity>
          <acceleration>0.899469 -0.010349 10.006 -3.09231 -1.14359 3.0973</acceleration>
          <wrench>8.99469 -0.103487 100.06 0 -0 0</wrench>
        </link>
        <link name='camera::link'>
          <pose frame=''>18.1647 -2.00001 0.742514 -2e-06 0.008974 -1.7e-05</pose>
          <velocity>-0.001076 -1.7e-05 -0.007398 5.9e-05 -0.003597 8.3e-05</velocity>
          <acceleration>-1.07553 -0.017269 -7.39811 -3.08234 0.455027 -3.05886</acceleration>
          <wrench>-1.07553 -0.017269 -7.39811 0 -0 0</wrench>
        </link>
        <link name='chassis'>
          <pose frame=''>17.5142 -2 0.243147 -1e-06 0.000974 -1.6e-05</pose>
          <velocity>0.000725 -3.8e-05 -0.009742 6e-05 -0.003624 7.2e-05</velocity>
          <acceleration>0.725145 -0.037543 -9.74167 -3.08162 0.481939 -3.06966</acceleration>
          <wrench>72.5145 -3.75426 -974.167 0 -0 0</wrench>
        </link>
        <link name='front_left_wheel'>
          <pose frame=''>18.3142 -1.50001 0.21 1.5656 1.56978 3.13637</pose>
          <velocity>0.000888 -1.1e-05 0.009995 5e-05 0.00423 6.2e-05</velocity>
          <acceleration>0.887673 -0.010551 9.99468 -3.09135 -1.0882 -3.08001</acceleration>
          <wrench>8.87673 -0.105507 99.9468 0 -0 0</wrench>
        </link>
        <link name='front_lidar'>
          <pose frame=''>18.5142 -2.00002 0.292173 -2e-06 0.000974 -1.9e-05</pose>
          <velocity>0.000548 8.1e-05 -0.006116 5.3e-05 -0.003626 0.000128</velocity>
          <acceleration>0.547614 0.08108 -6.11599 -3.08817 0.484077 -3.01372</acceleration>
          <wrench>0.547614 0.08108 -6.11599 0 -0 0</wrench>
        </link>
        <link name='front_right_wheel'>
          <pose frame=''>18.3142 -2.50001 0.209999 -1.5634 1.56979 -3.13421</pose>
          <velocity>0.000947 -2e-05 0.010006 9.4e-05 0.00451 3.4e-05</velocity>
          <acceleration>0.947438 -0.019809 10.0059 -3.04728 -1.36847 -3.10742</acceleration>
          <wrench>9.47438 -0.198093 100.059 0 -0 0</wrench>
        </link>
        <link name='gps'>
          <pose frame=''>17.5148 -2 0.893147 -2e-06 0.000974 -1.6e-05</pose>
          <velocity>-0.001626 -7.8e-05 -0.009739 6e-05 -0.00361 7.8e-05</velocity>
          <acceleration>-1.62641 -0.078257 -9.73929 -3.08138 0.468468 -3.06352</acceleration>
          <wrench>-1.62641 -0.078257 -9.73929 0 -0 0</wrench>
        </link>
        <link name='side_left_sensors'>
          <pose frame=''>17.5143 -1.45 0.293146 -2e-06 0.000974 -1.7e-05</pose>
          <velocity>0.000499 -4.2e-05 -0.009709 5.9e-05 -0.003593 8.9e-05</velocity>
          <acceleration>0.498965 -0.042023 -9.7089 -3.08299 0.451407 -3.05293</acceleration>
          <wrench>0.498965 -0.042023 -9.7089 0 -0 0</wrench>
        </link>
        <link name='side_right_sensors'>
          <pose frame=''>17.5142 -2.55 0.293148 -2e-06 0.000974 -1.7e-05</pose>
          <velocity>0.000596 -4.2e-05 -0.009774 5.7e-05 -0.003594 9.6e-05</velocity>
          <acceleration>0.595732 -0.042009 -9.77355 -3.08412 0.451978 -3.04596</acceleration>
          <wrench>0.595732 -0.042009 -9.77355 0 -0 0</wrench>
        </link>
        <link name='top_laser'>
          <pose frame=''>17.5149 -2 0.993147 -2e-06 0.000974 -1.7e-05</pose>
          <velocity>-0.001972 -8.2e-05 -0.009739 5.7e-05 -0.003602 0.000101</velocity>
          <acceleration>-1.97177 -0.082492 -9.73901 -3.08453 0.460897 -3.04017</acceleration>
          <wrench>-1.97177 -0.082492 -9.73901 0 -0 0</wrench>
        </link>
      </model>
      <model name='ground_plane'>
        <pose frame=''>0 0 0 0 -0 0</pose>
        <link name='link'>
          <pose frame=''>50 100 0 0 -0 0</pose>
          <velocity>0 0 0 0 -0 0</velocity>
          <acceleration>0 0 0 0 -0 0</acceleration>
          <wrench>0 0 0 0 -0 0</wrench>
        </link>
      </model>
      <model name='road_2_0_1'>
        <pose frame=''>0.160612 0.083908 0 0 -0 0</pose>
        <link name='link'>
          <pose frame=''>0.160612 0.083908 0 0 -0 0</pose>
          <velocity>0 0 0 0 -0 0</velocity>
          <acceleration>0 0 0 0 -0 0</acceleration>
          <wrench>0 0 0 0 -0 0</wrench>
        </link>
      </model>
    </state>
    <model name='car_clone_clone'>
      <link name='chassis'>
        <pose frame=''>0 0 0.35 0 -0 0</pose>
        <inertial>
          <mass>100</mass>
          <inertia>
            <ixx>1</ixx>
            <ixy>0</ixy>
            <ixz>0</ixz>
            <iyy>1</iyy>
            <iyz>0</iyz>
            <izz>1</izz>
          </inertia>
        </inertial>
        <collision name='chassis_collision'>
          <geometry>
            <box>
              <size>2 0.8 0.2</size>
            </box>
          </geometry>
          <max_contacts>10</max_contacts>
          <surface>
            <contact>
              <ode/>
            </contact>
            <bounce/>
            <friction>
              <ode/>
            </friction>
          </surface>
        </collision>
        <visual name='chassis_visual'>
          <pose frame=''>0.1 0 -0.2 0 -0 1.57079</pose>
          <geometry>
            <mesh>
              <uri>models/sdcCar/cooper-test.dae</uri>
            </mesh>
          </geometry>
        </visual>
        <self_collide>0</self_collide>
        <kinematic>0</kinematic>
        <gravity>1</gravity>
      </link>
      <link name='front_left_wheel'>
        <inertial>
          <mass>10</mass>
          <inertia>
            <ixx>1</ixx>
            <ixy>0</ixy>
            <ixz>0</ixz>
            <iyy>1</iyy>
            <iyz>0</iyz>
            <izz>1</izz>
          </inertia>
        </inertial>
        <pose frame=''>0.8 0.5 0.3 0 1.57079 1.57079</pose>
        <collision name='front_left_wheel_collision'>
          <geometry>
            <cylinder>
              <radius>0.21</radius>
              <length>0.1</length>
            </cylinder>
          </geometry>
          <max_contacts>10</max_contacts>
          <surface>
            <contact>
              <ode/>
            </contact>
            <bounce/>
            <friction>
              <ode/>
            </friction>
          </surface>
        </collision>
        <visual name='front_left_wheel_visual'>
          <geometry>
            <mesh>
              <uri>models/sdcCar/wheel.stl</uri>
            </mesh>
          </geometry>
          <material>
            <script>
              <uri>file://media/materials/scripts/gazebo.material</uri>
              <name>Gazebo/Black</name>
            </script>
          </material>
        </visual>
        <self_collide>0</self_collide>
        <kinematic>0</kinematic>
        <gravity>1</gravity>
      </link>
      <link name='front_right_wheel'>
        <pose frame=''>0.8 -0.5 0.3 0 1.57079 -1.57079</pose>
        <inertial>
          <mass>10</mass>
          <inertia>
            <ixx>1</ixx>
            <ixy>0</ixy>
            <ixz>0</ixz>
            <iyy>1</iyy>
            <iyz>0</iyz>
            <izz>1</izz>
          </inertia>
        </inertial>
        <collision name='front_right_wheel_collision'>
          <geometry>
            <cylinder>
              <radius>0.21</radius>
              <length>0.1</length>
            </cylinder>
          </geometry>
          <max_contacts>10</max_contacts>
          <surface>
            <contact>
              <ode/>
            </contact>
            <bounce/>
            <friction>
              <ode/>
            </friction>
          </surface>
        </collision>
        <visual name='front_right_wheel_visual'>
          <geometry>
            <mesh>
              <uri>models/sdcCar/wheel.stl</uri>
            </mesh>
          </geometry>
          <material>
            <script>
              <uri>file://media/materials/scripts/gazebo.material</uri>
              <name>Gazebo/Black</name>
            </script>
          </material>
        </visual>
        <self_collide>0</self_collide>
        <kinematic>0</kinematic>
        <gravity>1</gravity>
      </link>
      <link name='back_right_wheel'>
        <pose frame=''>-0.87 -0.5 0.3 0 1.57079 -1.57079</pose>
        <inertial>
          <mass>10</mass>
          <inertia>
            <ixx>1</ixx>
            <ixy>0</ixy>
            <ixz>0</ixz>
            <iyy>1</iyy>
            <iyz>0</iyz>
            <izz>1</izz>
          </inertia>
        </inertial>
        <collision name='back_right_wheel_collision'>
          <geometry>
            <cylinder>
              <radius>0.21</radius>
              <length>0.1</length>
            </cylinder>
          </geometry>
          <max_contacts>10</max_contacts>
          <surface>
            <contact>
              <ode/>
            </contact>
            <bounce/>
            <friction>
              <ode/>
            </friction>
          </surface>
        </collision>
        <visual name='back_right_wheel_visual'>
          <geometry>
            <mesh>
              <uri>models/sdcCar/wheel.stl</uri>
            </mesh>
          </geometry>
          <material>
            <script>
              <uri>file://media/materials/scripts/gazebo.material</uri>
              <name>Gazebo/Black</name>
            </script>
          </material>
        </visual>
        <self_collide>0</self_collide>
        <kinematic>0</kinematic>
        <gravity>1</gravity>
      </link>
      <link name='back_left_wheel'>
        <pose frame=''>-0.87 0.5 0.3 0 1.57079 1.57079</pose>
        <inertial>
          <mass>10</mass>
          <inertia>
            <ixx>1</ixx>
            <ixy>0</ixy>
            <ixz>0</ixz>
            <iyy>1</iyy>
            <iyz>0</iyz>
            <izz>1</izz>
          </inertia>
        </inertial>
        <collision name='back_left_wheel_collision'>
          <geometry>
            <cylinder>
              <radius>0.21</radius>
              <length>0.1</length>
            </cylinder>
          </geometry>
          <max_contacts>10</max_contacts>
          <surface>
            <contact>
              <ode/>
            </contact>
            <bounce/>
            <friction>
              <ode/>
            </friction>
          </surface>
        </collision>
        <visual name='back_left_wheel_visual'>
          <geometry>
            <mesh>
              <uri>models/sdcCar/wheel.stl</uri>
            </mesh>
          </geometry>
          <material>
            <script>
              <uri>file://media/materials/scripts/gazebo.material</uri>
              <name>Gazebo/Black</name>
            </script>
          </material>
        </visual>
        <self_collide>0</self_collide>
        <kinematic>0</kinematic>
        <gravity>1</gravity>
      </link>
      <joint name='front_left_joint' type='revolute2'>
        <parent>chassis</parent>
        <child>front_left_wheel</child>
        <axis>
          <xyz>0 0 1</xyz>
          <limit>
            <lower>0</lower>
            <upper>0</upper>
          </limit>
          <use_parent_model_frame>1</use_parent_model_frame>
          <dynamics>
            <spring_reference>0</spring_reference>
            <spring_stiffness>0</spring_stiffness>
          </dynamics>
        </axis>
        <axis2>
          <xyz>0 1 0</xyz>
          <use_parent_model_frame>1</use_parent_model_frame>
          <dynamics>
            <spring_reference>0</spring_reference>
            <spring_stiffness>0</spring_stiffness>
          </dynamics>
        </axis2>
        <physics>
          <ode>
            <limit>
              <cfm>0</cfm>
              <erp>0.9</erp>
            </limit>
            <suspension>
              <cfm>0.01</cfm>
              <erp>0.15</erp>
            </suspension>
          </ode>
        </physics>
      </joint>
      <joint name='front_right_joint' type='revolute2'>
        <parent>chassis</parent>
        <child>front_right_wheel</child>
        <axis>
          <xyz>0 0 1</xyz>
          <limit>
            <lower>0</lower>
            <upper>0</upper>
          </limit>
          <use_parent_model_frame>1</use_parent_model_frame>
          <dynamics>
            <spring_reference>0</spring_reference>
            <spring_stiffness>0</spring_stiffness>
          </dynamics>
        </axis>
        <axis2>
          <xyz>0 1 0</xyz>
          <use_parent_model_frame>1</use_parent_model_frame>
          <dynamics>
            <spring_reference>0</spring_reference>
            <spring_stiffness>0</spring_stiffness>
          </dynamics>
        </axis2>
        <physics>
          <ode>
            <limit>
              <cfm>0</cfm>
              <erp>0.9</erp>
            </limit>
            <suspension>
              <cfm>0.01</cfm>
              <erp>0.15</erp>
            </suspension>
          </ode>
        </physics>
      </joint>
      <joint name='back_right_joint' type='revolute2'>
        <parent>chassis</parent>
        <child>back_right_wheel</child>
        <axis>
          <xyz>0 0 1</xyz>
          <limit>
            <lower>0</lower>
            <upper>0</upper>
          </limit>
          <use_parent_model_frame>1</use_parent_model_frame>
          <dynamics>
            <spring_reference>0</spring_reference>
            <spring_stiffness>0</spring_stiffness>
          </dynamics>
        </axis>
        <axis2>
          <xyz>0 1 0</xyz>
          <use_parent_model_frame>1</use_parent_model_frame>
          <dynamics>
            <spring_reference>0</spring_reference>
            <spring_stiffness>0</spring_stiffness>
          </dynamics>
        </axis2>
        <physics>
          <ode>
            <limit>
              <cfm>0</cfm>
              <erp>0.9</erp>
            </limit>
            <suspension>
              <cfm>0.01</cfm>
              <erp>0.15</erp>
            </suspension>
          </ode>
        </physics>
      </joint>
      <joint name='back_left_joint' type='revolute2'>
        <parent>chassis</parent>
        <child>back_left_wheel</child>
        <axis>
          <xyz>0 0 1</xyz>
          <limit>
            <lower>0</lower>
            <upper>0</upper>
          </limit>
          <use_parent_model_frame>1</use_parent_model_frame>
          <dynamics>
            <spring_reference>0</spring_reference>
            <spring_stiffness>0</spring_stiffness>
          </dynamics>
        </axis>
        <axis2>
          <xyz>0 1 0</xyz>
          <use_parent_model_frame>1</use_parent_model_frame>
          <dynamics>
            <spring_reference>0</spring_reference>
            <spring_stiffness>0</spring_stiffness>
          </dynamics>
        </axis2>
        <physics>
          <ode>
            <limit>
              <cfm>0</cfm>
              <erp>0.9</erp>
            </limit>
            <suspension>
              <cfm>0.01</cfm>
              <erp>0.15</erp>
            </suspension>
          </ode>
        </physics>
      </joint>
      <link name='front_lidar'>
        <pose frame=''>1 0 0.4 0 -0 0</pose>
        <visual name='front_lidar_visual'>
          <geometry>
            <mesh>
              <uri>model://hokuyo/meshes/hokuyo.dae</uri>
            </mesh>
          </geometry>
        </visual>
        <collision name='front_lidar_collision-base'>
          <pose frame=''>0 0 -0.0145 0 -0 0</pose>
          <geometry>
            <box>
              <size>0.05 0.05 0.041</size>
            </box>
          </geometry>
          <max_contacts>10</max_contacts>
          <surface>
            <contact>
              <ode/>
            </contact>
            <bounce/>
            <friction>
              <ode/>
            </friction>
          </surface>
        </collision>
        <collision name='front_lidar_collision-top'>
          <pose frame=''>0 0 0.0205 0 -0 0</pose>
          <geometry>
            <cylinder>
              <radius>0.021</radius>
              <length>0.029</length>
            </cylinder>
          </geometry>
          <max_contacts>10</max_contacts>
          <surface>
            <contact>
              <ode/>
            </contact>
            <bounce/>
            <friction>
              <ode/>
            </friction>
          </surface>
        </collision>
        <sensor name='front_lidar' type='ray'>
          <pose frame=''>0.01 0 0.0175 0 -0 0</pose>
          <ray>
            <scan>
              <horizontal>
                <samples>640</samples>
                <resolution>1</resolution>
                <min_angle>-1.39626</min_angle>
                <max_angle>1.39626</max_angle>
              </horizontal>
            </scan>
            <range>
              <min>0.08</min>
              <max>20</max>
              <resolution>0.01</resolution>
            </range>
          </ray>
          <plugin name='sdcFrontLidarSensor' filename='build/libsdcFrontLidarSensor.so'/>
          <always_on>1</always_on>
          <update_rate>30</update_rate>
          <visualize>1</visualize>
        </sensor>
        <self_collide>0</self_collide>
        <inertial>
          <inertia>
            <ixx>1</ixx>
            <ixy>0</ixy>
            <ixz>0</ixz>
            <iyy>1</iyy>
            <iyz>0</iyz>
            <izz>1</izz>
          </inertia>
          <mass>1</mass>
        </inertial>
        <kinematic>0</kinematic>
        <gravity>1</gravity>
      </link>
      <joint name='front_lidar_joint' type='revolute'>
        <child>front_lidar</child>
        <parent>chassis</parent>
        <axis>
          <xyz>0 0 1</xyz>
          <limit>
            <upper>0</upper>
            <lower>0</lower>
          </limit>
          <use_parent_model_frame>1</use_parent_model_frame>
          <dynamics>
            <spring_reference>0</spring_reference>
            <spring_stiffness>0</spring_stiffness>
          </dynamics>
        </axis>
      </joint>
      <link name='back_lidar'>
        <pose frame=''>-1.2 0 0.4 0 -0 0</pose>
        <visual name='back_lidar_visual'>
          <geometry>
            <mesh>
              <uri>model://hokuyo/meshes/hokuyo.dae</uri>
            </mesh>
          </geometry>
        </visual>
        <collision name='back_lidar_collision-base'>
          <pose frame=''>0 0 -0.0145 0 -0 0</pose>
          <geometry>
            <box>
              <size>0.05 0.05 0.041</size>
            </box>
          </geometry>
          <max_contacts>10</max_contacts>
          <surface>
            <contact>
              <ode/>
            </contact>
            <bounce/>
            <friction>
              <ode/>
            </friction>
          </surface>
        </collision>
        <collision name='back_lidar_collision-top'>
          <pose frame=''>0 0 0.0205 0 -0 0</pose>
          <geometry>
            <cylinder>
              <radius>0.021</radius>
              <length>0.029</length>
            </cylinder>
          </geometry>
          <max_contacts>10</max_contacts>
          <surface>
            <contact>
              <ode/>
            </contact>
            <bounce/>
            <friction>
              <ode/>
            </friction>
          </surface>
        </collision>
        <sensor name='back_lidar' type='ray'>
          <pose frame=''>0.01 0 0.0175 3.14159 -0.004307 3.14159</pose>
          <ray>
            <scan>
              <horizontal>
                <samples>120</samples>
                <resolution>1</resolution>
                <min_angle>-1.5709</min_angle>
                <max_angle>1.5709</max_angle>
              </horizontal>
            </scan>
            <range>
              <min>0.08</min>
              <max>10</max>
              <resolution>0.01</resolution>
            </range>
          </ray>
          <plugin name='sdcBackLidarSensor' filename='build/libsdcBackLidarSensor.so'/>
          <always_on>1</always_on>
          <update_rate>30</update_rate>
          <visualize>0</visualize>
        </sensor>
        <self_collide>0</self_collide>
        <inertial>
          <inertia>
            <ixx>1</ixx>
            <ixy>0</ixy>
            <ixz>0</ixz>
            <iyy>1</iyy>
            <iyz>0</iyz>
            <izz>1</izz>
          </inertia>
          <mass>1</mass>
        </inertial>
        <kinematic>0</kinematic>
        <gravity>1</gravity>
      </link>
      <joint name='back_lidar_joint' type='revolute'>
        <child>back_lidar</child>
        <parent>chassis</parent>
        <axis>
          <xyz>0 0 1</xyz>
          <limit>
            <upper>0</upper>
            <lower>0</lower>
          </limit>
          <use_parent_model_frame>1</use_parent_model_frame>
          <dynamics>
            <spring_reference>0</spring_reference>
            <spring_stiffness>0</spring_stiffness>
          </dynamics>
        </axis>
      </joint>
      <link name='top_laser'>
        <pose frame=''>0 0 1.1 0 -0 0</pose>
        <visual name='top_laser_visual'>
          <geometry>
            <mesh>
              <uri>model://hokuyo/meshes/hokuyo.dae</uri>
            </mesh>
          </geometry>
        </visual>
        <collision name='top_laser_collision-base'>
          <pose frame=''>0 0 -0.0145 0 -0 0</pose>
          <geometry>
            <box>
              <size>0.05 0.05 0.041</size>
            </box>
          </geometry>
          <max_contacts>10</max_contacts>
          <surface>
            <contact>
              <ode/>
            </contact>
            <bounce/>
            <friction>
              <ode/>
            </friction>
          </surface>
        </collision>
        <collision name='top_laser_collision-top'>
          <pose frame=''>0 0 0.0205 0 -0 0</pose>
          <geometry>
            <cylinder>
              <radius>0.021</radius>
              <length>0.029</length>
            </cylinder>
          </geometry>
          <max_contacts>10</max_contacts>
          <surface>
            <contact>
              <ode/>
            </contact>
            <bounce/>
            <friction>
              <ode/>
            </friction>
          </surface>
        </collision>
        <sensor name='top_left_laser' type='ray'>
          <pose frame=''>0.01 0 0.0175 0 0.18 1.5708</pose>
          <ray>
            <scan>
              <horizontal>
                <samples>160</samples>
                <resolution>1</resolution>
                <min_angle>-0.7854</min_angle>
                <max_angle>0.7854</max_angle>
              </horizontal>
            </scan>
            <range>
              <min>0.08</min>
              <max>20</max>
              <resolution>0.01</resolution>
            </range>
          </ray>
          <plugin name='sdcTopLidarSensor' filename='build/libsdcTopLidarSensor.so'/>
          <always_on>1</always_on>
          <update_rate>30</update_rate>
          <visualize>0</visualize>
        </sensor>
        <sensor name='top_forward_laser' type='ray'>
          <pose frame=''>0.01 0 0.0175 0 0.18 0</pose>
          <ray>
            <scan>
              <horizontal>
                <samples>160</samples>
                <resolution>1</resolution>
                <min_angle>-0.7854</min_angle>
                <max_angle>0.7854</max_angle>
              </horizontal>
            </scan>
            <range>
              <min>0.08</min>
              <max>20</max>
              <resolution>0.01</resolution>
            </range>
          </ray>
          <plugin name='sdcTopLidarSensor' filename='build/libsdcTopLidarSensor.so'/>
          <always_on>1</always_on>
          <update_rate>30</update_rate>
          <visualize>0</visualize>
        </sensor>
        <sensor name='top_backward_laser' type='ray'>
          <pose frame=''>0.01 0 0.0175 -0 0.18 3.14159</pose>
          <ray>
            <scan>
              <horizontal>
                <samples>160</samples>
                <resolution>1</resolution>
                <min_angle>-0.7854</min_angle>
                <max_angle>0.7854</max_angle>
              </horizontal>
            </scan>
            <range>
              <min>0.08</min>
              <max>20</max>
              <resolution>0.01</resolution>
            </range>
          </ray>
          <plugin name='sdcTopLidarSensor' filename='build/libsdcTopLidarSensor.so'/>
          <always_on>1</always_on>
          <update_rate>30</update_rate>
          <visualize>0</visualize>
        </sensor>
        <sensor name='top_right_laser' type='ray'>
          <pose frame=''>0.01 0 0.0175 0 0.18 -1.5708</pose>
          <ray>
            <scan>
              <horizontal>
                <samples>160</samples>
                <resolution>1</resolution>
                <min_angle>-0.7854</min_angle>
                <max_angle>0.7854</max_angle>
              </horizontal>
            </scan>
            <range>
              <min>0.08</min>
              <max>20</max>
              <resolution>0.01</resolution>
            </range>
          </ray>
          <plugin name='sdcTopLidarSensor' filename='build/libsdcTopLidarSensor.so'/>
          <always_on>1</always_on>
          <update_rate>30</update_rate>
          <visualize>0</visualize>
        </sensor>
        <self_collide>0</self_collide>
        <inertial>
          <inertia>
            <ixx>1</ixx>
            <ixy>0</ixy>
            <ixz>0</ixz>
            <iyy>1</iyy>
            <iyz>0</iyz>
            <izz>1</izz>
          </inertia>
          <mass>1</mass>
        </inertial>
        <kinematic>0</kinematic>
        <gravity>1</gravity>
      </link>
      <joint name='top_laser_joint' type='revolute'>
        <child>top_laser</child>
        <parent>chassis</parent>
        <axis>
          <xyz>0 0 1</xyz>
          <limit>
            <upper>0</upper>
            <lower>0</lower>
          </limit>
          <use_parent_model_frame>1</use_parent_model_frame>
          <dynamics>
            <spring_reference>0</spring_reference>
            <spring_stiffness>0</spring_stiffness>
          </dynamics>
        </axis>
      </joint>
      <link name='side_right_sensors'>
        <pose frame=''>0 -0.55 0.4 0 -0 0</pose>
        <visual name='side_right_sensors_visual'>
          <geometry>
            <mesh>
              <uri>model://hokuyo/meshes/hokuyo.dae</uri>
            </mesh>
          </geometry>
        </visual>
        <collision name='side_right_sensors_collision-base'>
          <pose frame=''>0 0 -0.0145 0 -0 0</pose>
          <geometry>
            <box>
              <size>0.05 0.05 0.041</size>
            </box>
          </geometry>
          <max_contacts>10</max_contacts>
          <surface>
            <contact>
              <ode/>
            </contact>
            <bounce/>
            <friction>
              <ode/>
            </friction>
          </surface>
        </collision>
        <collision name='side_right_sensors_collision-top'>
          <pose frame=''>0 0 0.0205 0 -0 0</pose>
          <geometry>
            <cylinder>
              <radius>0.021</radius>
              <length>0.029</length>
            </cylinder>
          </geometry>
          <max_contacts>10</max_contacts>
          <surface>
            <contact>
              <ode/>
            </contact>
            <bounce/>
            <friction>
              <ode/>
            </friction>
          </surface>
        </collision>
        <sensor name='side_right_front_laser' type='ray'>
          <pose frame=''>0.4 -0.02 0 0 0 -1.5708</pose>
          <ray>
            <scan>
              <horizontal>
                <samples>160</samples>
                <resolution>1</resolution>
                <min_angle>-1.3</min_angle>
                <max_angle>1.3</max_angle>
              </horizontal>
            </scan>
            <range>
              <min>0.08</min>
              <max>11</max>
              <resolution>0.01</resolution>
            </range>
          </ray>
          <plugin name='sdcSideLidarSensor' filename='build/libsdcSideLidarSensor.so'/>
          <always_on>1</always_on>
          <update_rate>30</update_rate>
          <visualize>1</visualize>
        </sensor>
        <sensor name='side_right_back_laser' type='ray'>
          <pose frame=''>-0.6 -0.02 0 0 0 -1.5708</pose>
          <ray>
            <scan>
              <horizontal>
                <samples>160</samples>
                <resolution>1</resolution>
                <min_angle>-1.3</min_angle>
                <max_angle>1.3</max_angle>
              </horizontal>
            </scan>
            <range>
              <min>0.08</min>
              <max>1</max>
              <resolution>0.01</resolution>
            </range>
          </ray>
          <plugin name='sdcSideLidarSensor' filename='build/libsdcSideLidarSensor.so'/>
          <always_on>1</always_on>
          <update_rate>30</update_rate>
          <visualize>0</visualize>
        </sensor>
        <self_collide>0</self_collide>
        <inertial>
          <inertia>
            <ixx>1</ixx>
            <ixy>0</ixy>
            <ixz>0</ixz>
            <iyy>1</iyy>
            <iyz>0</iyz>
            <izz>1</izz>
          </inertia>
          <mass>1</mass>
        </inertial>
        <kinematic>0</kinematic>
        <gravity>1</gravity>
      </link>
      <joint name='side_right_sensor_joint' type='revolute'>
        <child>side_right_sensors</child>
        <parent>chassis</parent>
        <axis>
          <xyz>0 0 1</xyz>
          <limit>
            <upper>0</upper>
            <lower>0</lower>
          </limit>
          <use_parent_model_frame>1</use_parent_model_frame>
          <dynamics>
            <spring_reference>0</spring_reference>
            <spring_stiffness>0</spring_stiffness>
          </dynamics>
        </axis>
      </joint>
      <link name='side_left_sensors'>
        <pose frame=''>0 0.55 0.4 0 -0 0</pose>
        <visual name='side_left_sensors_visual'>
          <geometry>
            <mesh>
              <uri>model://hokuyo/meshes/hokuyo.dae</uri>
            </mesh>
          </geometry>
        </visual>
        <collision name='side_left_sensors_collision-base'>
          <pose frame=''>0 0 -0.0145 0 -0 0</pose>
          <geometry>
            <box>
              <size>0.05 0.05 0.041</size>
            </box>
          </geometry>
          <max_contacts>10</max_contacts>
          <surface>
            <contact>
              <ode/>
            </contact>
            <bounce/>
            <friction>
              <ode/>
            </friction>
          </surface>
        </collision>
        <collision name='side_left_sensors_collision-top'>
          <pose frame=''>0 0 0.0205 0 -0 0</pose>
          <geometry>
            <cylinder>
              <radius>0.021</radius>
              <length>0.029</length>
            </cylinder>
          </geometry>
          <max_contacts>10</max_contacts>
          <surface>
            <contact>
              <ode/>
            </contact>
            <bounce/>
            <friction>
              <ode/>
            </friction>
          </surface>
        </collision>
        <sensor name='side_left_front_laser' type='ray'>
          <pose frame=''>0.4 0.02 0 0 -0 1.5708</pose>
          <ray>
            <scan>
              <horizontal>
                <samples>160</samples>
                <resolution>1</resolution>
                <min_angle>-1.3</min_angle>
                <max_angle>1.3</max_angle>
              </horizontal>
            </scan>
            <range>
              <min>0.08</min>
              <max>11</max>
              <resolution>0.01</resolution>
            </range>
          </ray>
          <plugin name='sdcSideLidarSensor' filename='build/libsdcSideLidarSensor.so'/>
          <always_on>1</always_on>
          <update_rate>30</update_rate>
          <visualize>1</visualize>
        </sensor>
        <sensor name='side_left_back_laser' type='ray'>
          <pose frame=''>-0.6 0.02 0 0 -0 1.5708</pose>
          <ray>
            <scan>
              <horizontal>
                <samples>160</samples>
                <resolution>1</resolution>
                <min_angle>-1.3</min_angle>
                <max_angle>1.3</max_angle>
              </horizontal>
            </scan>
            <range>
              <min>0.08</min>
              <max>1</max>
              <resolution>0.01</resolution>
            </range>
          </ray>
          <plugin name='sdcSideLidarSensor' filename='build/libsdcSideLidarSensor.so'/>
          <always_on>1</always_on>
          <update_rate>30</update_rate>
          <visualize>0</visualize>
        </sensor>
        <self_collide>0</self_collide>
        <inertial>
          <inertia>
            <ixx>1</ixx>
            <ixy>0</ixy>
            <ixz>0</ixz>
            <iyy>1</iyy>
            <iyz>0</iyz>
            <izz>1</izz>
          </inertia>
          <mass>1</mass>
        </inertial>
        <kinematic>0</kinematic>
        <gravity>1</gravity>
      </link>
      <joint name='side_left_sensor_joint' type='revolute'>
        <child>side_left_sensors</child>
        <parent>chassis</parent>
        <axis>
          <xyz>0 0 1</xyz>
          <limit>
            <upper>0</upper>
            <lower>0</lower>
          </limit>
          <use_parent_model_frame>1</use_parent_model_frame>
          <dynamics>
            <spring_reference>0</spring_reference>
            <spring_stiffness>0</spring_stiffness>
          </dynamics>
        </axis>
      </joint>
      <link name='camera::link'>
        <pose frame=''>0.65 0 0.85 0 0.008 0</pose>
        <self_collide>0</self_collide>
        <kinematic>0</kinematic>
        <sensor name='camera' type='multicamera'>
          <always_on>1</always_on>
          <update_rate>24</update_rate>
          <visualize>0</visualize>
          <topic>comps_car_camera</topic>
          <camera name='left'>
            <pose frame=''>0 0 0 0 -0 0</pose>
            <horizontal_fov>1.047</horizontal_fov>
            <image>
              <width>640</width>
              <height>480</height>
            </image>
            <clip>
              <near>0.1</near>
              <far>150</far>
            </clip>
            <save enabled='0'>
              <path>/Users/selfcar/Desktop/Self-Driving-Comps/comps_camera_recordings/</path>
            </save>
          </camera>
          <plugin name='sdcCameraSensor' filename='build/libsdcCameraSensor.so'/>
        </sensor>
        <visual name='visual'>
          <geometry>
            <box>
              <size>0.1 0.1 0.1</size>
            </box>
          </geometry>
          <material>
            <shader type='pixel'/>
          </material>
          <pose frame=''>0 0 0 0 -0 0</pose>
          <cast_shadows>1</cast_shadows>
          <transparency>0</transparency>
        </visual>
        <inertial>
          <inertia>
            <ixx>1</ixx>
            <ixy>0</ixy>
            <ixz>0</ixz>
            <iyy>1</iyy>
            <iyz>0</iyz>
            <izz>1</izz>
          </inertia>
          <mass>1</mass>
        </inertial>
        <gravity>1</gravity>
      </link>
      <joint name='camera' type='revolute'>
        <parent>chassis</parent>
        <child>camera::link</child>
        <axis>
          <xyz>0 0 1</xyz>
          <use_parent_model_frame>0</use_parent_model_frame>
          <limit>
            <lower>0</lower>
            <upper>0</upper>
            <effort>-1</effort>
            <velocity>-1</velocity>
          </limit>
          <dynamics>
            <spring_reference>0</spring_reference>
            <spring_stiffness>0</spring_stiffness>
            <damping>0</damping>
            <friction>0</friction>
          </dynamics>
          <use_parent_model_frame>1</use_parent_model_frame>
        </axis>
        <physics>
          <ode>
            <limit>
              <cfm>0</cfm>
              <erp>0.2</erp>
            </limit>
            <suspension>
              <cfm>0</cfm>
              <erp>0.2</erp>
            </suspension>
          </ode>
        </physics>
      </joint>
      <link name='gps'>
        <pose frame=''>0 0 1 0 -0 0</pose>
        <visual name='visual'>
          <geometry>
            <mesh>
              <uri>model://hokuyo/meshes/hokuyo.dae</uri>
            </mesh>
          </geometry>
        </visual>
        <collision name='gps_collision-base'>
          <pose frame=''>0 0 -0.0145 0 -0 0</pose>
          <geometry>
            <box>
              <size>0.05 0.05 0.041</size>
            </box>
          </geometry>
          <max_contacts>10</max_contacts>
          <surface>
            <contact>
              <ode/>
            </contact>
            <bounce/>
            <friction>
              <ode/>
            </friction>
          </surface>
        </collision>
        <collision name='gps_collision-top'>
          <pose frame=''>0 0 0.0205 0 -0 0</pose>
          <geometry>
            <cylinder>
              <radius>0.021</radius>
              <length>0.029</length>
            </cylinder>
          </geometry>
          <max_contacts>10</max_contacts>
          <surface>
            <contact>
              <ode/>
            </contact>
            <bounce/>
            <friction>
              <ode/>
            </friction>
          </surface>
        </collision>
        <sensor name='gps' type='gps'>
          <pose frame=''>0 0 0 0 -0 0</pose>
          <always_on>1</always_on>
          <update_rate>30</update_rate>
        </sensor>
        <self_collide>0</self_collide>
        <inertial>
          <inertia>
            <ixx>1</ixx>
            <ixy>0</ixy>
            <ixz>0</ixz>
            <iyy>1</iyy>
            <iyz>0</iyz>
            <izz>1</izz>
          </inertia>
          <mass>1</mass>
        </inertial>
        <kinematic>0</kinematic>
        <gravity>1</gravity>
      </link>
      <joint name='gps_joint' type='revolute'>
        <child>gps</child>
        <parent>chassis</parent>
        <axis>
          <xyz>0 0 1</xyz>
          <limit>
            <upper>0</upper>
            <lower>0</lower>
          </limit>
          <use_parent_model_frame>1</use_parent_model_frame>
          <dynamics>
            <spring_reference>0</spring_reference>
            <spring_stiffness>0</spring_stiffness>
          </dynamics>
        </axis>
      </joint>
      <plugin name='sdcCar' filename='build/libsdcCar.so'>
        <front_left>front_left_joint</front_left>
        <front_right>front_right_joint</front_right>
        <back_left>back_left_joint</back_left>
        <back_right>back_right_joint</back_right>
        <chassis>chassis</chassis>
        <camera>camera::link</camera>
        <frontLidar>front_lidar</frontLidar>
        <rightSideLidar>side_right_sensors</rightSideLidar>
        <leftSideLidar>side_left_sensors</leftSideLidar>
        <wheel_radius>0.21</wheel_radius>
        <front_power>10</front_power>
        <rear_power>10</rear_power>
        <tire_angle_range>0.5</tire_angle_range>
        <max_speed>10</max_speed>
        <aero_load>1.0</aero_load>
      </plugin>
      <plugin name='sdcGpsSensor' filename='build/libsdcGpsSensor.so'>
        <gps>gps</gps>
      </plugin>
      <pose frame=''>17.5139 -2 -0.106906 0 0.000973 -1.4e-05</pose>
    </model>
  </world>
</sdf>
